Workbook

Sheet Cover
B3: FINANCIAL FEASIBILITY & PROJECTION MODEL
B5: Small-Scale Food & Agro-Processing Unit — Gujarat
B7: 5-Year Monthly Model — fully formula-linked, ready for data entry
B10: BLANK, FULLY-LINKED TEMPLATE — ENTER YOUR DATA IN THE YELLOW CELLS
B13: Applicant / Enterprise | C13: 〈Enterprise name〉 (edit on Assumptions)
B14: Proposed location | C14: 〈Taluka / District〉, Gujarat
B15: Enterprise class (MSME) | C15: Small Enterprise (P&M ≤ ₹25 cr; turnover ≤ ₹100 cr)
B16: Constitution | C16: Private Limited Company (assumed)
B17: Projection horizon | C17: 60 months (5 financial years), monthly granularity
B18: Currency / units | C18: All financial lines in ₹ lakh unless stated (1 lakh = ₹100,000)
B19: Base / model date | C19: FY-1 = first year of commercial operation
B22: WORKBOOK CONTENTS
B24: 01 | C24: Assumptions | D24: Every driver – blue = editable input, with live source links
B25: 02 | C25: Capex & Financing | D25: Project cost, means of finance, subsidy build-up
B26: 03 | C26: Loan Schedule | D26: Monthly term-loan amortisation (moratorium + repayment)
B27: 04 | C27: Depreciation | D27: Block-wise SLM depreciation schedule
B28: 05 | C28: Payroll | D28: Monthly headcount & wage bill (feeds employment impact)
B29: 06 | C29: Monthly Model | D29: THE ENGINE – 60-month P&L from production to net cash
B30: 07 | C30: Annual P&L | D30: Year 1-5 profit & loss summary
B31: 08 | C31: Cash Flow | D31: Annual cash-flow statement
B32: 09 | C32: Balance Sheet | D32: Annual balance sheet (self-balancing)
B33: 10 | C33: Returns & Ratios | D33: IRR, NPV, DSCR, break-even, margins
B34: 11 | C34: Socio-Economic Impact | D34: Jobs, wages, farmer linkage, taxes, local multiplier
B35: 12 | C35: Sustainability (ESG) | D35: Energy, water, waste, solar, emissions
... B38: 15 | C38: Sources | D38: Consolidated, clickable source bibliography
B40: Disclaimer: This is a projection model built on stated assumptions and publicly sourced parameters (see hyperlinks). It is not audited advice. Figures must be validated by the promoter, a chartered accountant and the appraising bank before submission. Tax, subsidy and scheme parameters change — verify each source link at time of use.

Sheet Assumptions
B1: ASSUMPTIONS — single source of truth for the model
B2: Blue = editable input • Yellow = key driver • Black = derived • Green links (col E) open the live source. Change any blue cell and the whole model updates.
B4: Parameter | C4: Value | D4: Unit | E4: Source / basis (click)
B5: A. Macro-economic & tax parameters
B6: Effective corporate tax rate (s.115BAA, incl. surcharge+cess) | D6: % | E6: s.115BAA 22% (eff. 25.17%); s.115BAB 15% (eff. 17.16%, sunset 31-Mar-2024) – ClearTax
B7: └ Alternative if s.115BAB eligible (new mfg, if applicable) | D7: % | E7: Corporate tax – Income Tax Dept (domestic company rates, AY 2025-26)
B8: Annual escalation – selling price / realisation | D8: % p.a. | E8: Analyst estimate aligned to RBI CPI target band (4% ±2%)
B9: Annual escalation – raw material & consumables | D9: % p.a. | E9: Analyst estimate aligned to RBI CPI target band (4% ±2%)
B10: Annual escalation – wages & salaries | D10: % p.a. | E10: Analyst estimate aligned to RBI CPI target band (4% ±2%)
B11: Annual escalation – other operating expenses | D11: % p.a. | E11: Analyst estimate aligned to RBI CPI target band (4% ±2%)
B12: Working days per month | D12: days | E12: Management / DPR estimate (to be validated by promoter & appraising bank)
B13: B. Project cost (capex, ₹ lakh)
B14: Land & site development | D14: ₹ lakh | E14: Management / DPR estimate (to be validated by promoter & appraising bank)
B15: Factory building & civil works | D15: ₹ lakh | E15: Management / DPR estimate (to be validated by promoter & appraising bank)
B16: Plant & machinery (processing + packaging line) | D16: ₹ lakh | E16: Management / DPR estimate (to be validated by promoter & appraising bank)
B17: Utilities – power, water, cold storage, DG, solar | D17: ₹ lakh | E17: Management / DPR estimate (to be validated by promoter & appraising bank)
B18: Misc. fixed assets (furniture, IT, lab, ETP) | D18: ₹ lakh | E18: Management / DPR estimate (to be validated by promoter & appraising bank)
B19: Preliminary & pre-operative expenses | D19: ₹ lakh | E19: Management / DPR estimate (to be validated by promoter & appraising bank)
B20: Contingency (~2% of capital cost) | D20: ₹ lakh | E20: Management / DPR estimate (to be validated by promoter & appraising bank)
B21: Margin money for working capital | D21: ₹ lakh | E21: Management / DPR estimate (to be validated by promoter & appraising bank)
B22: C. Means of finance
B23: Promoter contribution (equity) | D23: % of project | E23: CGTMSE collateral-free credit guarantee up to ₹5 cr (raised to ₹10 cr, Budget 2025) – MoMSME/SIDBI
B24: Term-loan interest rate (p.a.) | D24: % p.a. | E24: MSME term-loan / working-capital rates & RBI repo (~6.5% early-2026; term loans ~9-11%) – 2026 survey
B25: Term-loan tenure (incl. moratorium) | D25: months | E25: MSME term-loan / working-capital rates & RBI repo (~6.5% early-2026; term loans ~9-11%) – 2026 survey
B26: Moratorium on principal (interest serviced) | D26: months | E26: MSME term-loan / working-capital rates & RBI repo (~6.5% early-2026; term loans ~9-11%) – 2026 survey
B27: Working-capital finance rate (p.a.) | D27: % p.a. | E27: MSME term-loan / working-capital rates & RBI repo (~6.5% early-2026; term loans ~9-11%) – 2026 survey
B28: Working capital funded by bank | D28: % of WC gap | E28: CGTMSE collateral-free credit guarantee up to ₹5 cr (raised to ₹10 cr, Budget 2025) – MoMSME/SIDBI
B29: D. Production & capacity
B30: Installed capacity at 100% (finished product) | D30: tonnes/mo | E30: Management / DPR estimate (to be validated by promoter & appraising bank)
B31: Capacity utilisation – Year 1 | D31: % | E31: Management / DPR estimate (to be validated by promoter & appraising bank)
B32: Capacity utilisation – Year 2 | D32: % | E32: Management / DPR estimate (to be validated by promoter & appraising bank)
B33: Capacity utilisation – Year 3 | D33: % | E33: Management / DPR estimate (to be validated by promoter & appraising bank)
B34: Capacity utilisation – Year 4 | D34: % | E34: Management / DPR estimate (to be validated by promoter & appraising bank)
B35: Capacity utilisation – Year 5 | D35: % | E35: Management / DPR estimate (to be validated by promoter & appraising bank)
B36: E. Pricing & unit economics (Year 1 base, ₹ per tonne)
B37: Average net realisation (ex-GST) | D37: ₹/tonne | E37: Management / DPR estimate (to be validated by promoter & appraising bank)
B38: Raw material (farm produce incl. wastage) | D38: ₹/tonne | E38: Management / DPR estimate (to be validated by promoter & appraising bank)
B39: Packaging & consumables | D39: ₹/tonne | E39: Management / DPR estimate (to be validated by promoter & appraising bank)
B40: Direct utilities per tonne (power/steam/water) | D40: ₹/tonne | E40: Management / DPR estimate (to be validated by promoter & appraising bank)
B41: Other direct / QC / logistics inward | D41: ₹/tonne | E41: Management / DPR estimate (to be validated by promoter & appraising bank)
...

Sheet Capex & Financing
B1: PROJECT COST & MEANS OF FINANCE (₹ lakh)
B3: A. Project cost
B4: Land & site development | C4: =IFERROR(Assumptions!$C$14,0) -> 0 | D4: ₹ lakh
B5: Factory building & civil | C5: =IFERROR(Assumptions!$C$15,0) -> 0 | D5: ₹ lakh
B6: Plant & machinery | C6: =IFERROR(Assumptions!$C$16,0) -> 0 | D6: ₹ lakh
B7: Utilities (power/water/cold-chain/solar) | C7: =IFERROR(Assumptions!$C$17,0) -> 0 | D7: ₹ lakh
B8: Misc. fixed assets (furniture, IT, lab, ETP) | C8: =IFERROR(Assumptions!$C$18,0) -> 0 | D8: ₹ lakh
B9: Preliminary & pre-operative | C9: =IFERROR(Assumptions!$C$19,0) -> 0 | D9: ₹ lakh
B10: Contingency | C10: =IFERROR(Assumptions!$C$20,0) -> 0 | D10: ₹ lakh
B11: Margin money for working capital | C11: =IFERROR(Assumptions!$C$21,0) -> 0 | D11: ₹ lakh
B12: Total project cost | C12: =IFERROR(Assumptions!$C$75,0) -> 0 | D12: ₹ lakh
B14: B. Means of finance
B15: Promoter equity | C15: =IFERROR(Assumptions!$C$77,0) -> 0 | D15: ₹ lakh | E15: Own contribution
B16: Term loan | C16: =IFERROR(Assumptions!$C$78,0) -> 0 | D16: ₹ lakh | E16: CGTMSE-eligible bank term loan
B17: Total means of finance | C17: =IFERROR(C15+C16,0) -> 0 | D17: ₹ lakh
B18: Debt : Equity ratio | C18: =IFERROR(C16/C15,"")
B19: Promoter contribution (%) | C19: =IFERROR(C15/C12,"")
B21: C. Government support build-up (indicative)
B22: State capital investment subsidy | C22: =IFERROR(Assumptions!$C$79,0) -> 0 | D22: ₹ lakh | E22: Aatmanirbhar Gujarat (post-COD claim)
B23: Interest subsidy (5-yr, term loan) | C23: =IFERROR(SUM('Loan Schedule'!C12:BJ12),0) -> 0 | D23: ₹ lakh | E23: Reduces effective interest cost
B24: PMFME subsidy (only if micro unit) | C24: =IFERROR(MIN(Assumptions!$C$75*Assumptions!$C$69,Assumptions!$C$70),0) -> 0 | D24: ₹ lakh | E24: Conditional – P&M ≤ ₹2.5 cr
B25: Total indicative support | C25: =IFERROR(Assumptions!$C$79+C23,0) -> 0 | D25: ₹ lakh
B27: Note: subsidies are reimbursed after commencement of commercial operation and are shown as inflows in the Cash Flow / Balance Sheet, not netted against project cost here. Enabler schemes (CGTMSE guarantee, concessional tax) reduce risk and outflows but are not cash grants.

Sheet Loan Schedule
A1: TERM-LOAN AMORTISATION (₹ lakh, monthly)
A2: Equal-principal repayment after moratorium; interest on reducing balance. Interest-subsidy row feeds the P&L.
A3: Month # | C3: 1 | D3: 2 | E3: 3 | F3: 4 | G3: 5 | H3: 6 | I3: 7 | J3: 8 | K3: 9 | L3: 10 | M3: 11 | N3: 12 | O3: 13 | P3: 14 | Q3: 15 | R3: 16 | S3: 17 | T3: 18 | U3: 19 | V3: 20 | W3: 21 | X3: 22 | Y3: 23 | Z3: 24 | AA3: 25 | AB3: 26 | AC3: 27 | AD3: 28 | AE3: 29 | AF3: 30 | AG3: 31 | AH3: 32 | AI3: 33 | AJ3: 34 | AK3: 35 | AL3: 36 | AM3: 37 | AN3: 38 | AO3: 39 | AP3: 40 | AQ3: 41 | AR3: 42 | AS3: 43 | AT3: 44 | AU3: 45 | AV3: 46 | AW3: 47 | AX3: 48 | AY3: 49 | AZ3: 50 | BA3: 51 | BB3: 52 | BC3: 53 | BD3: 54 | BE3: 55 | BF3: 56 | BG3: 57 | BH3: 58 | BI3: 59 | BJ3: 60
A4: Financial Year | C4: Y1 | D4: Y1 | E4: Y1 | F4: Y1 | G4: Y1 | H4: Y1 | I4: Y1 | J4: Y1 | K4: Y1 | L4: Y1 | M4: Y1 | N4: Y1 | O4: Y2 | P4: Y2 | Q4: Y2 | R4: Y2 | S4: Y2 | T4: Y2 | U4: Y2 | V4: Y2 | W4: Y2 | X4: Y2 | Y4: Y2 | Z4: Y2 | AA4: Y3 | AB4: Y3 | AC4: Y3 | AD4: Y3 | AE4: Y3 | AF4: Y3 | AG4: Y3 | AH4: Y3 | AI4: Y3 | AJ4: Y3 | AK4: Y3 | AL4: Y3 | AM4: Y4 | AN4: Y4 | AO4: Y4 | AP4: Y4 | AQ4: Y4 | AR4: Y4 | AS4: Y4 | AT4: Y4 | AU4: Y4 | AV4: Y4 | AW4: Y4 | AX4: Y4 | AY4: Y5 | AZ4: Y5 | BA4: Y5 | BB4: Y5 | BC4: Y5 | BD4: Y5 | BE4: Y5 | BF4: Y5 | BG4: Y5 | BH4: Y5 | BI4: Y5 | BJ4: Y5
A6: Opening balance | B6: ₹ lakh | C6: =IFERROR(Assumptions!$C$78,0) -> 0 | D6: =IFERROR(C10,0) -> 0 | E6: =IFERROR(D10,0) -> 0 | F6: =IFERROR(E10,0) -> 0 | G6: =IFERROR(F10,0) -> 0 | H6: =IFERROR(G10,0) -> 0 | I6: =IFERROR(H10,0) -> 0 | J6: =IFERROR(I10,0) -> 0 | K6: =IFERROR(J10,0) -> 0 | ... BJ6: =IFERROR(BI10,0) -> 0
A7: Interest for month | B7: ₹ lakh | C7: =IFERROR(C6*Assumptions!$C$24/12,0) -> 0 | D7: =IFERROR(D6*Assumptions!$C$24/12,0) -> 0 | E7: =IFERROR(E6*Assumptions!$C$24/12,0) -> 0 | F7: =IFERROR(F6*Assumptions!$C$24/12,0) -> 0 | G7: =IFERROR(G6*Assumptions!$C$24/12,0) -> 0 | H7: =IFERROR(H6*Assumptions!$C$24/12,0) -> 0 | I7: =IFERROR(I6*Assumptions!$C$24/12,0) -> 0 | J7: =IFERROR(J6*Assumptions!$C$24/12,0) -> 0 | ... BJ7: =IFERROR(BJ6*Assumptions!$C$24/12,0) -> 0
A8: Principal repayment | B8: ₹ lakh | C8: =IFERROR(IF(1<=Assumptions!$C$26,0,Assumptions!$C$78/(Assumptions!$C$25-Assumptions!$C$26)),0) -> 0 | D8: =IFERROR(IF(2<=Assumptions!$C$26,0,Assumptions!$C$78/(Assumptions!$C$25-Assumptions!$C$26)),0) -> 0 | E8: =IFERROR(IF(3<=Assumptions!$C$26,0,Assumptions!$C$78/(Assumptions!$C$25-Assumptions!$C$26)),0) -> 0 | F8: =IFERROR(IF(4<=Assumptions!$C$26,0,Assumptions!$C$78/(Assumptions!$C$25-Assumptions!$C$26)),0) -> 0 | G8: =IFERROR(IF(5<=Assumptions!$C$26,0,Assumptions!$C$78/(Assumptions!$C$25-Assumptions!$C$26)),0) -> 0 | H8: =IFERROR(IF(6<=Assumptions!$C$26,0,Assumptions!$C$78/(Assumptions!$C$25-Assumptions!$C$26)),0) -> 0 | I8: =IFERROR(IF(7<=Assumptions!$C$26,0,Assumptions!$C$78/(Assumptions!$C$25-Assumptions!$C$26)),0) -> 0 | J8: =IFERROR(IF(8<=Assumptions!$C$26,0,Assumptions!$C$78/(Assumptions!$C$25-Assumptions!$C$26)),0) -> 0 | K8: =IFERROR(IF(9<=Assumptions!$C$26,0,Assumptions!$C$78/(Assumptions!$C$25-Assumptions!$C$26)),0) -> 0 | L8: =IFERROR(IF(10<=Assumptions!$C$26,0,Assumptions!$C$78/(Assumptions!$C$25-Assumptions!$C$26)),0) -> 0 | M8: =IFERROR(IF(11<=Assumptions!$C$26,0,Assumptions!$C$78/(Assumptions!$C$25-Assumptions!$C$26)),0) -> 0 | N8: =IFERROR(IF(12<=Assumptions!$C$26,0,Assumptions!$C$78/(Assumptions!$C$25-Assumptions!$C$26)),0) -> 0 | O8: =IFERROR(IF(13<=Assumptions!$C$26,0,Assumptions!$C$78/(Assumptions!$C$25-Assumptions!$C$26)),0) -> 0 | P8: =IFERROR(IF(14<=Assumptions!$C$26,0,Assumptions!$C$78/(Assumptions!$C$25-Assumptions!$C$26)),0) -> 0 | Q8: =IFERROR(IF(15<=Assumptions!$C$26,0,Assumptions!$C$78/(Assumptions!$C$25-Assumptions!$C$26)),0) -> 0 | R8: =IFERROR(IF(16<=Assumptions!$C$26,0,Assumptions!$C$78/(Assumptions!$C$25-Assumptions!$C$26)),0) -> 0 | S8: =IFERROR(IF(17<=Assumptions!$C$26,0,Assumptions!$C$78/(Assumptions!$C$25-Assumptions!$C$26)),0) -> 0 | T8: =IFERROR(IF(18<=Assumptions!$C$26,0,Assumptions!$C$78/(Assumptions!$C$25-Assumptions!$C$26)),0) -> 0 | U8: =IFERROR(IF(19<=Assumptions!$C$26,0,Assumptions!$C$78/(Assumptions!$C$25-Assumptions!$C$26)),0) -> 0 | V8: =IFERROR(IF(20<=Assumptions!$C$26,0,Assumptions!$C$78/(Assumptions!$C$25-Assumptions!$C$26)),0) -> 0 | W8: =IFERROR(IF(21<=Assumptions!$C$26,0,Assumptions!$C$78/(Assumptions!$C$25-Assumptions!$C$26)),0) -> 0 | X8: =IFERROR(IF(22<=Assumptions!$C$26,0,Assumptions!$C$78/(Assumptions!$C$25-Assumptions!$C$26)),0) -> 0 | Y8: =IFERROR(IF(23<=Assumptions!$C$26,0,Assumptions!$C$78/(Assumptions!$C$25-Assumptions!$C$26)),0) -> 0 | Z8: =IFERROR(IF(24<=Assumptions!$C$26,0,Assumptions!$C$78/(Assumptions!$C$25-Assumptions!$C$26)),0) -> 0 | AA8: =IFERROR(IF(25<=Assumptions!$C$26,0,Assumptions!$C$78/(Assumptions!$C$25-Assumptions!$C$26)),0) -> 0 | AB8: =IFERROR(IF(26<=Assumptions!$C$26,0,Assumptions!$C$78/(Assumptions!$C$25-Assumptions!$C$26)),0) -> 0 | AC8: =IFERROR(IF(27<=Assumptions!$C$26,0,Assumptions!$C$78/(Assumptions!$C$25-Assumptions!$C$26)),0) -> 0 | AD8: =IFERROR(IF(28<=Assumptions!$C$26,0,Assumptions!$C$78/(Assumptions!$C$25-Assumptions!$C$26)),0) -> 0 | AE8: =IFERROR(IF(29<=Assumptions!$C$26,0,Assumptions!$C$78/(Assumptions!$C$25-Assumptions!$C$26)),0) -> 0 | AF8: =IFERROR(IF(30<=Assumptions!$C$26,0,Assumptions!$C$78/(Assumptions!$C$25-Assumptions!$C$26)),0) -> 0 | AG8: =IFERROR(IF(31<=Assumptions!$C$26,0,Assumptions!$C$78/(Assumptions!$C$25-Assumptions!$C$26)),0) -> 0 | AH8: =IFERROR(IF(32<=Assumptions!$C$26,0,Assumptions!$C$78/(Assumptions!$C$25-Assumptions!$C$26)),0) -> 0 | AI8: =IFERROR(IF(33<=Assumptions!$C$26,0,Assumptions!$C$78/(Assumptions!$C$25-Assumptions!$C$26)),0) -> 0 | AJ8: =IFERROR(IF(34<=Assumptions!$C$26,0,Assumptions!$C$78/(Assumptions!$C$25-Assumptions!$C$26)),0) -> 0 | AK8: =IFERROR(IF(35<=Assumptions!$C$26,0,Assumptions!$C$78/(Assumptions!$C$25-Assumptions!$C$26)),0) -> 0 | AL8: =IFERROR(IF(36<=Assumptions!$C$26,0,Assumptions!$C$78/(Assumptions!$C$25-Assumptions!$C$26)),0) -> 0 | AM8: =IFERROR(IF(37<=Assumptions!$C$26,0,Assumptions!$C$78/(Assumptions!$C$25-Assumptions!$C$26)),0) -> 0 | AN8: =IFERROR(IF(38<=Assumptions!$C$26,0,Assumptions!$C$78/(Assumptions!$C$25-Assumptions!$C$26)),0) -> 0 | AO8: =IFERROR(IF(39<=Assumptions!$C$26,0,Assumptions!$C$78/(Assumptions!$C$25-Assumptions!$C$26)),0) -> 0 | AP8: =IFERROR(IF(40<=Assumptions!$C$26,0,Assumptions!$C$78/(Assumptions!$C$25-Assumptions!$C$26)),0) -> 0 | AQ8: =IFERROR(IF(41<=Assumptions!$C$26,0,Assumptions!$C$78/(Assumptions!$C$25-Assumptions!$C$26)),0) -> 0 | AR8: =IFERROR(IF(42<=Assumptions!$C$26,0,Assumptions!$C$78/(Assumptions!$C$25-Assumptions!$C$26)),0) -> 0 | AS8: =IFERROR(IF(43<=Assumptions!$C$26,0,Assumptions!$C$78/(Assumptions!$C$25-Assumptions!$C$26)),0) -> 0 | AT8: =IFERROR(IF(44<=Assumptions!$C$26,0,Assumptions!$C$78/(Assumptions!$C$25-Assumptions!$C$26)),0) -> 0 | AU8: =IFERROR(IF(45<=Assumptions!$C$26,0,Assumptions!$C$78/(Assumptions!$C$25-Assumptions!$C$26)),0) -> 0 | AV8: =IFERROR(IF(46<=Assumptions!$C$26,0,Assumptions!$C$78/(Assumptions!$C$25-Assumptions!$C$26)),0) -> 0 | AW8: =IFERROR(IF(47<=Assumptions!$C$26,0,Assumptions!$C$78/(Assumptions!$C$25-Assumptions!$C$26)),0) -> 0 | AX8: =IFERROR(IF(48<=Assumptions!$C$26,0,Assumptions!$C$78/(Assumptions!$C$25-Assumptions!$C$26)),0) -> 0 | AY8: =IFERROR(IF(49<=Assumptions!$C$26,0,Assumptions!$C$78/(Assumptions!$C$25-Assumptions!$C$26)),0) -> 0 | AZ8: =IFERROR(IF(50<=Assumptions!$C$26,0,Assumptions!$C$78/(Assumptions!$C$25-Assumptions!$C$26)),0) -> 0 | BA8: =IFERROR(IF(51<=Assumptions!$C$26,0,Assumptions!$C$78/(Assumptions!$C$25-Assumptions!$C$26)),0) -> 0 | BB8: =IFERROR(IF(52<=Assumptions!$C$26,0,Assumptions!$C$78/(Assumptions!$C$25-Assumptions!$C$26)),0) -> 0 | BC8: =IFERROR(IF(53<=Assumptions!$C$26,0,Assumptions!$C$78/(Assumptions!$C$25-Assumptions!$C$26)),0) -> 0 | BD8: =IFERROR(IF(54<=Assumptions!$C$26,0,Assumptions!$C$78/(Assumptions!$C$25-Assumptions!$C$26)),0) -> 0 | BE8: =IFERROR(IF(55<=Assumptions!$C$26,0,Assumptions!$C$78/(Assumptions!$C$25-Assumptions!$C$26)),0) -> 0 | BF8: =IFERROR(IF(56<=Assumptions!$C$26,0,Assumptions!$C$78/(Assumptions!$C$25-Assumptions!$C$26)),0) -> 0 | BG8: =IFERROR(IF(57<=Assumptions!$C$26,0,Assumptions!$C$78/(Assumptions!$C$25-Assumptions!$C$26)),0) -> 0 | BH8: =IFERROR(IF(58<=Assumptions!$C$26,0,Assumptions!$C$78/(Assumptions!$C$25-Assumptions!$C$26)),0) -> 0 | BI8: =IFERROR(IF(59<=Assumptions!$C$26,0,Assumptions!$C$78/(Assumptions!$C$25-Assumptions!$C$26)),0) -> 0 | BJ8: =IFERROR(IF(60<=Assumptions!$C$26,0,Assumptions!$C$78/(Assumptions!$C$25-Assumptions!$C$26)),0) -> 0
A9: Total debt service (interest+principal) | B9: ₹ lakh | C9: =IFERROR(C7+C8,0) -> 0 | D9: =IFERROR(D7+D8,0) -> 0 | E9: =IFERROR(E7+E8,0) -> 0 | F9: =IFERROR(F7+F8,0) -> 0 | G9: =IFERROR(G7+G8,0) -> 0 | H9: =IFERROR(H7+H8,0) -> 0 | I9: =IFERROR(I7+I8,0) -> 0 | J9: =IFERROR(J7+J8,0) -> 0 | ... BJ9: =IFERROR(BJ7+BJ8,0) -> 0
A10: Closing balance | B10: ₹ lakh | C10: =IFERROR(C6-C8,0) -> 0 | D10: =IFERROR(D6-D8,0) -> 0 | E10: =IFERROR(E6-E8,0) -> 0 | F10: =IFERROR(F6-F8,0) -> 0 | G10: =IFERROR(G6-G8,0) -> 0 | H10: =IFERROR(H6-H8,0) -> 0 | I10: =IFERROR(I6-I8,0) -> 0 | J10: =IFERROR(J6-J8,0) -> 0 | ... BJ10: =IFERROR(BJ6-BJ8,0) -> 0
A12: Less: interest subsidy (Aatmanirbhar Gujarat) | B12: ₹ lakh | C12: =IFERROR(MIN(C6*Assumptions!$C$67/12,Assumptions!$C$68/12),0) -> 0 | D12: =IFERROR(MIN(D6*Assumptions!$C$67/12,Assumptions!$C$68/12),0) -> 0 | E12: =IFERROR(MIN(E6*Assumptions!$C$67/12,Assumptions!$C$68/12),0) -> 0 | F12: =IFERROR(MIN(F6*Assumptions!$C$67/12,Assumptions!$C$68/12),0) -> 0 | G12: =IFERROR(MIN(G6*Assumptions!$C$67/12,Assumptions!$C$68/12),0) -> 0 | H12: =IFERROR(MIN(H6*Assumptions!$C$67/12,Assumptions!$C$68/12),0) -> 0 | I12: =IFERROR(MIN(I6*Assumptions!$C$67/12,Assumptions!$C$68/12),0) -> 0 | J12: =IFERROR(MIN(J6*Assumptions!$C$67/12,Assumptions!$C$68/12),0) -> 0 | ... BJ12: =IFERROR(MIN(BJ6*Assumptions!$C$67/12,Assumptions!$C$68/12),0) -> 0
A13: Net interest cost to enterprise | B13: ₹ lakh | C13: =IFERROR(C7-C12,0) -> 0 | D13: =IFERROR(D7-D12,0) -> 0 | E13: =IFERROR(E7-E12,0) -> 0 | F13: =IFERROR(F7-F12,0) -> 0 | G13: =IFERROR(G7-G12,0) -> 0 | H13: =IFERROR(H7-H12,0) -> 0 | I13: =IFERROR(I7-I12,0) -> 0 | J13: =IFERROR(J7-J12,0) -> 0 | ... BJ13: =IFERROR(BJ7-BJ12,0) -> 0

Sheet Depreciation
A1: DEPRECIATION SCHEDULE (₹ lakh, monthly, SLM)
A2: Straight-line book depreciation by asset block; constant per month over the horizon.
A3: Month # | C3: 1 | D3: 2 | E3: 3 | F3: 4 | G3: 5 | H3: 6 | I3: 7 | J3: 8 | K3: 9 | L3: 10 | M3: 11 | N3: 12 | O3: 13 | P3: 14 | Q3: 15 | R3: 16 | S3: 17 | T3: 18 | U3: 19 | V3: 20 | W3: 21 | X3: 22 | Y3: 23 | Z3: 24 | AA3: 25 | AB3: 26 | AC3: 27 | AD3: 28 | AE3: 29 | AF3: 30 | AG3: 31 | AH3: 32 | AI3: 33 | AJ3: 34 | AK3: 35 | AL3: 36 | AM3: 37 | AN3: 38 | AO3: 39 | AP3: 40 | AQ3: 41 | AR3: 42 | AS3: 43 | AT3: 44 | AU3: 45 | AV3: 46 | AW3: 47 | AX3: 48 | AY3: 49 | AZ3: 50 | BA3: 51 | BB3: 52 | BC3: 53 | BD3: 54 | BE3: 55 | BF3: 56 | BG3: 57 | BH3: 58 | BI3: 59 | BJ3: 60
A4: Financial Year | C4: Y1 | D4: Y1 | E4: Y1 | F4: Y1 | G4: Y1 | H4: Y1 | I4: Y1 | J4: Y1 | K4: Y1 | L4: Y1 | M4: Y1 | N4: Y1 | O4: Y2 | P4: Y2 | Q4: Y2 | R4: Y2 | S4: Y2 | T4: Y2 | U4: Y2 | V4: Y2 | W4: Y2 | X4: Y2 | Y4: Y2 | Z4: Y2 | AA4: Y3 | AB4: Y3 | AC4: Y3 | AD4: Y3 | AE4: Y3 | AF4: Y3 | AG4: Y3 | AH4: Y3 | AI4: Y3 | AJ4: Y3 | AK4: Y3 | AL4: Y3 | AM4: Y4 | AN4: Y4 | AO4: Y4 | AP4: Y4 | AQ4: Y4 | AR4: Y4 | AS4: Y4 | AT4: Y4 | AU4: Y4 | AV4: Y4 | AW4: Y4 | AX4: Y4 | AY4: Y5 | AZ4: Y5 | BA4: Y5 | BB4: Y5 | BC4: Y5 | BD4: Y5 | BE4: Y5 | BF4: Y5 | BG4: Y5 | BH4: Y5 | BI4: Y5 | BJ4: Y5
A6: Building & civil | B6: ₹ lakh | C6: =IFERROR(Assumptions!$C$15*Assumptions!$C$61/12,0) -> 0 | D6: =IFERROR(Assumptions!$C$15*Assumptions!$C$61/12,0) -> 0 | E6: =IFERROR(Assumptions!$C$15*Assumptions!$C$61/12,0) -> 0 | F6: =IFERROR(Assumptions!$C$15*Assumptions!$C$61/12,0) -> 0 | G6: =IFERROR(Assumptions!$C$15*Assumptions!$C$61/12,0) -> 0 | H6: =IFERROR(Assumptions!$C$15*Assumptions!$C$61/12,0) -> 0 | I6: =IFERROR(Assumptions!$C$15*Assumptions!$C$61/12,0) -> 0 | J6: =IFERROR(Assumptions!$C$15*Assumptions!$C$61/12,0) -> 0 | ... BJ6: =IFERROR(Assumptions!$C$15*Assumptions!$C$61/12,0) -> 0
A7: Plant & machinery | B7: ₹ lakh | C7: =IFERROR(Assumptions!$C$16*Assumptions!$C$62/12,0) -> 0 | D7: =IFERROR(Assumptions!$C$16*Assumptions!$C$62/12,0) -> 0 | E7: =IFERROR(Assumptions!$C$16*Assumptions!$C$62/12,0) -> 0 | F7: =IFERROR(Assumptions!$C$16*Assumptions!$C$62/12,0) -> 0 | G7: =IFERROR(Assumptions!$C$16*Assumptions!$C$62/12,0) -> 0 | H7: =IFERROR(Assumptions!$C$16*Assumptions!$C$62/12,0) -> 0 | I7: =IFERROR(Assumptions!$C$16*Assumptions!$C$62/12,0) -> 0 | J7: =IFERROR(Assumptions!$C$16*Assumptions!$C$62/12,0) -> 0 | ... BJ7: =IFERROR(Assumptions!$C$16*Assumptions!$C$62/12,0) -> 0
A8: Utilities & misc assets | B8: ₹ lakh | C8: =IFERROR((Assumptions!$C$17+Assumptions!$C$18)*Assumptions!$C$63/12,0) -> 0 | D8: =IFERROR((Assumptions!$C$17+Assumptions!$C$18)*Assumptions!$C$63/12,0) -> 0 | E8: =IFERROR((Assumptions!$C$17+Assumptions!$C$18)*Assumptions!$C$63/12,0) -> 0 | F8: =IFERROR((Assumptions!$C$17+Assumptions!$C$18)*Assumptions!$C$63/12,0) -> 0 | G8: =IFERROR((Assumptions!$C$17+Assumptions!$C$18)*Assumptions!$C$63/12,0) -> 0 | H8: =IFERROR((Assumptions!$C$17+Assumptions!$C$18)*Assumptions!$C$63/12,0) -> 0 | I8: =IFERROR((Assumptions!$C$17+Assumptions!$C$18)*Assumptions!$C$63/12,0) -> 0 | J8: =IFERROR((Assumptions!$C$17+Assumptions!$C$18)*Assumptions!$C$63/12,0) -> 0 | ... BJ8: =IFERROR((Assumptions!$C$17+Assumptions!$C$18)*Assumptions!$C$63/12,0) -> 0
A9: Total depreciation | B9: ₹ lakh | C9: =IFERROR(SUM(C6:C8),0) -> 0 | D9: =IFERROR(SUM(D6:D8),0) -> 0 | E9: =IFERROR(SUM(E6:E8),0) -> 0 | F9: =IFERROR(SUM(F6:F8),0) -> 0 | G9: =IFERROR(SUM(G6:G8),0) -> 0 | H9: =IFERROR(SUM(H6:H8),0) -> 0 | I9: =IFERROR(SUM(I6:I8),0) -> 0 | J9: =IFERROR(SUM(J6:J8),0) -> 0 | ... BJ9: =IFERROR(SUM(BJ6:BJ8),0) -> 0

Sheet Payroll
A1: MANPOWER & PAYROLL (monthly)
A2: Headcount steps up by year; average wage escalates. Feeds both the P&L and the Socio-Economic Impact sheet.
A3: Month # | C3: 1 | D3: 2 | E3: 3 | F3: 4 | G3: 5 | H3: 6 | I3: 7 | J3: 8 | K3: 9 | L3: 10 | M3: 11 | N3: 12 | O3: 13 | P3: 14 | Q3: 15 | R3: 16 | S3: 17 | T3: 18 | U3: 19 | V3: 20 | W3: 21 | X3: 22 | Y3: 23 | Z3: 24 | AA3: 25 | AB3: 26 | AC3: 27 | AD3: 28 | AE3: 29 | AF3: 30 | AG3: 31 | AH3: 32 | AI3: 33 | AJ3: 34 | AK3: 35 | AL3: 36 | AM3: 37 | AN3: 38 | AO3: 39 | AP3: 40 | AQ3: 41 | AR3: 42 | AS3: 43 | AT3: 44 | AU3: 45 | AV3: 46 | AW3: 47 | AX3: 48 | AY3: 49 | AZ3: 50 | BA3: 51 | BB3: 52 | BC3: 53 | BD3: 54 | BE3: 55 | BF3: 56 | BG3: 57 | BH3: 58 | BI3: 59 | BJ3: 60
A4: Financial Year | C4: Y1 | D4: Y1 | E4: Y1 | F4: Y1 | G4: Y1 | H4: Y1 | I4: Y1 | J4: Y1 | K4: Y1 | L4: Y1 | M4: Y1 | N4: Y1 | O4: Y2 | P4: Y2 | Q4: Y2 | R4: Y2 | S4: Y2 | T4: Y2 | U4: Y2 | V4: Y2 | W4: Y2 | X4: Y2 | Y4: Y2 | Z4: Y2 | AA4: Y3 | AB4: Y3 | AC4: Y3 | AD4: Y3 | AE4: Y3 | AF4: Y3 | AG4: Y3 | AH4: Y3 | AI4: Y3 | AJ4: Y3 | AK4: Y3 | AL4: Y3 | AM4: Y4 | AN4: Y4 | AO4: Y4 | AP4: Y4 | AQ4: Y4 | AR4: Y4 | AS4: Y4 | AT4: Y4 | AU4: Y4 | AV4: Y4 | AW4: Y4 | AX4: Y4 | AY4: Y5 | AZ4: Y5 | BA4: Y5 | BB4: Y5 | BC4: Y5 | BD4: Y5 | BE4: Y5 | BF4: Y5 | BG4: Y5 | BH4: Y5 | BI4: Y5 | BJ4: Y5
A6: Total headcount | B6: persons | C6: =IFERROR(Assumptions!$C$49,0) -> 0 | D6: =IFERROR(Assumptions!$C$49,0) -> 0 | E6: =IFERROR(Assumptions!$C$49,0) -> 0 | F6: =IFERROR(Assumptions!$C$49,0) -> 0 | G6: =IFERROR(Assumptions!$C$49,0) -> 0 | H6: =IFERROR(Assumptions!$C$49,0) -> 0 | I6: =IFERROR(Assumptions!$C$49,0) -> 0 | J6: =IFERROR(Assumptions!$C$49,0) -> 0 | ... N6: =IFERROR(Assumptions!$C$49,0) -> 0 | O6: =IFERROR(Assumptions!$C$50,0) -> 0 | P6: =IFERROR(Assumptions!$C$50,0) -> 0 | Q6: =IFERROR(Assumptions!$C$50,0) -> 0 | R6: =IFERROR(Assumptions!$C$50,0) -> 0 | S6: =IFERROR(Assumptions!$C$50,0) -> 0 | T6: =IFERROR(Assumptions!$C$50,0) -> 0 | U6: =IFERROR(Assumptions!$C$50,0) -> 0 | V6: =IFERROR(Assumptions!$C$50,0) -> 0 | ... Z6: =IFERROR(Assumptions!$C$50,0) -> 0 | AA6: =IFERROR(Assumptions!$C$51,0) -> 0 | AB6: =IFERROR(Assumptions!$C$51,0) -> 0 | AC6: =IFERROR(Assumptions!$C$51,0) -> 0 | AD6: =IFERROR(Assumptions!$C$51,0) -> 0 | AE6: =IFERROR(Assumptions!$C$51,0) -> 0 | AF6: =IFERROR(Assumptions!$C$51,0) -> 0 | AG6: =IFERROR(Assumptions!$C$51,0) -> 0 | AH6: =IFERROR(Assumptions!$C$51,0) -> 0 | ... AL6: =IFERROR(Assumptions!$C$51,0) -> 0 | AM6: =IFERROR(Assumptions!$C$52,0) -> 0 | AN6: =IFERROR(Assumptions!$C$52,0) -> 0 | AO6: =IFERROR(Assumptions!$C$52,0) -> 0 | AP6: =IFERROR(Assumptions!$C$52,0) -> 0 | AQ6: =IFERROR(Assumptions!$C$52,0) -> 0 | AR6: =IFERROR(Assumptions!$C$52,0) -> 0 | AS6: =IFERROR(Assumptions!$C$52,0) -> 0 | AT6: =IFERROR(Assumptions!$C$52,0) -> 0 | ... AX6: =IFERROR(Assumptions!$C$52,0) -> 0 | AY6: =IFERROR(Assumptions!$C$53,0) -> 0 | AZ6: =IFERROR(Assumptions!$C$53,0) -> 0 | BA6: =IFERROR(Assumptions!$C$53,0) -> 0 | BB6: =IFERROR(Assumptions!$C$53,0) -> 0 | BC6: =IFERROR(Assumptions!$C$53,0) -> 0 | BD6: =IFERROR(Assumptions!$C$53,0) -> 0 | BE6: =IFERROR(Assumptions!$C$53,0) -> 0 | BF6: =IFERROR(Assumptions!$C$53,0) -> 0 | ... BJ6: =IFERROR(Assumptions!$C$53,0) -> 0
A7: of which women | B7: persons | C7: =IFERROR(C6*Assumptions!$C$55,0) -> 0 | D7: =IFERROR(D6*Assumptions!$C$55,0) -> 0 | E7: =IFERROR(E6*Assumptions!$C$55,0) -> 0 | F7: =IFERROR(F6*Assumptions!$C$55,0) -> 0 | G7: =IFERROR(G6*Assumptions!$C$55,0) -> 0 | H7: =IFERROR(H6*Assumptions!$C$55,0) -> 0 | I7: =IFERROR(I6*Assumptions!$C$55,0) -> 0 | J7: =IFERROR(J6*Assumptions!$C$55,0) -> 0 | ... BJ7: =IFERROR(BJ6*Assumptions!$C$55,0) -> 0
A8: Average monthly wage | B8: ₹ | C8: =IFERROR(Assumptions!$C$54*(1+Assumptions!$C$10)^(1-1),0) -> 0 | D8: =IFERROR(Assumptions!$C$54*(1+Assumptions!$C$10)^(1-1),0) -> 0 | E8: =IFERROR(Assumptions!$C$54*(1+Assumptions!$C$10)^(1-1),0) -> 0 | F8: =IFERROR(Assumptions!$C$54*(1+Assumptions!$C$10)^(1-1),0) -> 0 | G8: =IFERROR(Assumptions!$C$54*(1+Assumptions!$C$10)^(1-1),0) -> 0 | H8: =IFERROR(Assumptions!$C$54*(1+Assumptions!$C$10)^(1-1),0) -> 0 | I8: =IFERROR(Assumptions!$C$54*(1+Assumptions!$C$10)^(1-1),0) -> 0 | J8: =IFERROR(Assumptions!$C$54*(1+Assumptions!$C$10)^(1-1),0) -> 0 | ... N8: =IFERROR(Assumptions!$C$54*(1+Assumptions!$C$10)^(1-1),0) -> 0 | O8: =IFERROR(Assumptions!$C$54*(1+Assumptions!$C$10)^(2-1),0) -> 0 | P8: =IFERROR(Assumptions!$C$54*(1+Assumptions!$C$10)^(2-1),0) -> 0 | Q8: =IFERROR(Assumptions!$C$54*(1+Assumptions!$C$10)^(2-1),0) -> 0 | R8: =IFERROR(Assumptions!$C$54*(1+Assumptions!$C$10)^(2-1),0) -> 0 | S8: =IFERROR(Assumptions!$C$54*(1+Assumptions!$C$10)^(2-1),0) -> 0 | T8: =IFERROR(Assumptions!$C$54*(1+Assumptions!$C$10)^(2-1),0) -> 0 | U8: =IFERROR(Assumptions!$C$54*(1+Assumptions!$C$10)^(2-1),0) -> 0 | V8: =IFERROR(Assumptions!$C$54*(1+Assumptions!$C$10)^(2-1),0) -> 0 | ... Z8: =IFERROR(Assumptions!$C$54*(1+Assumptions!$C$10)^(2-1),0) -> 0 | AA8: =IFERROR(Assumptions!$C$54*(1+Assumptions!$C$10)^(3-1),0) -> 0 | AB8: =IFERROR(Assumptions!$C$54*(1+Assumptions!$C$10)^(3-1),0) -> 0 | AC8: =IFERROR(Assumptions!$C$54*(1+Assumptions!$C$10)^(3-1),0) -> 0 | AD8: =IFERROR(Assumptions!$C$54*(1+Assumptions!$C$10)^(3-1),0) -> 0 | AE8: =IFERROR(Assumptions!$C$54*(1+Assumptions!$C$10)^(3-1),0) -> 0 | AF8: =IFERROR(Assumptions!$C$54*(1+Assumptions!$C$10)^(3-1),0) -> 0 | AG8: =IFERROR(Assumptions!$C$54*(1+Assumptions!$C$10)^(3-1),0) -> 0 | AH8: =IFERROR(Assumptions!$C$54*(1+Assumptions!$C$10)^(3-1),0) -> 0 | ... AL8: =IFERROR(Assumptions!$C$54*(1+Assumptions!$C$10)^(3-1),0) -> 0 | AM8: =IFERROR(Assumptions!$C$54*(1+Assumptions!$C$10)^(4-1),0) -> 0 | AN8: =IFERROR(Assumptions!$C$54*(1+Assumptions!$C$10)^(4-1),0) -> 0 | AO8: =IFERROR(Assumptions!$C$54*(1+Assumptions!$C$10)^(4-1),0) -> 0 | AP8: =IFERROR(Assumptions!$C$54*(1+Assumptions!$C$10)^(4-1),0) -> 0 | AQ8: =IFERROR(Assumptions!$C$54*(1+Assumptions!$C$10)^(4-1),0) -> 0 | AR8: =IFERROR(Assumptions!$C$54*(1+Assumptions!$C$10)^(4-1),0) -> 0 | AS8: =IFERROR(Assumptions!$C$54*(1+Assumptions!$C$10)^(4-1),0) -> 0 | AT8: =IFERROR(Assumptions!$C$54*(1+Assumptions!$C$10)^(4-1),0) -> 0 | ... AX8: =IFERROR(Assumptions!$C$54*(1+Assumptions!$C$10)^(4-1),0) -> 0 | AY8: =IFERROR(Assumptions!$C$54*(1+Assumptions!$C$10)^(5-1),0) -> 0 | AZ8: =IFERROR(Assumptions!$C$54*(1+Assumptions!$C$10)^(5-1),0) -> 0 | BA8: =IFERROR(Assumptions!$C$54*(1+Assumptions!$C$10)^(5-1),0) -> 0 | BB8: =IFERROR(Assumptions!$C$54*(1+Assumptions!$C$10)^(5-1),0) -> 0 | BC8: =IFERROR(Assumptions!$C$54*(1+Assumptions!$C$10)^(5-1),0) -> 0 | BD8: =IFERROR(Assumptions!$C$54*(1+Assumptions!$C$10)^(5-1),0) -> 0 | BE8: =IFERROR(Assumptions!$C$54*(1+Assumptions!$C$10)^(5-1),0) -> 0 | BF8: =IFERROR(Assumptions!$C$54*(1+Assumptions!$C$10)^(5-1),0) -> 0 | ... BJ8: =IFERROR(Assumptions!$C$54*(1+Assumptions!$C$10)^(5-1),0) -> 0
A9: Monthly wage & salary bill | B9: ₹ lakh | C9: =IFERROR(C6*C8/100000,0) -> 0 | D9: =IFERROR(D6*D8/100000,0) -> 0 | E9: =IFERROR(E6*E8/100000,0) -> 0 | F9: =IFERROR(F6*F8/100000,0) -> 0 | G9: =IFERROR(G6*G8/100000,0) -> 0 | H9: =IFERROR(H6*H8/100000,0) -> 0 | I9: =IFERROR(I6*I8/100000,0) -> 0 | J9: =IFERROR(J6*J8/100000,0) -> 0 | ... BJ9: =IFERROR(BJ6*BJ8/100000,0) -> 0

Sheet Monthly Model
A1: MONTHLY MODEL — integrated P&L, working capital & cash flow (₹ lakh)
A2: Fully formula-driven from Assumptions. Escalation, ramp-up, financing, tax loss carry-forward all automated.
A3: Month # | C3: 1 | D3: 2 | E3: 3 | F3: 4 | G3: 5 | H3: 6 | I3: 7 | J3: 8 | K3: 9 | L3: 10 | M3: 11 | N3: 12 | O3: 13 | P3: 14 | Q3: 15 | R3: 16 | S3: 17 | T3: 18 | U3: 19 | V3: 20 | W3: 21 | X3: 22 | Y3: 23 | Z3: 24 | AA3: 25 | AB3: 26 | AC3: 27 | AD3: 28 | AE3: 29 | AF3: 30 | AG3: 31 | AH3: 32 | AI3: 33 | AJ3: 34 | AK3: 35 | AL3: 36 | AM3: 37 | AN3: 38 | AO3: 39 | AP3: 40 | AQ3: 41 | AR3: 42 | AS3: 43 | AT3: 44 | AU3: 45 | AV3: 46 | AW3: 47 | AX3: 48 | AY3: 49 | AZ3: 50 | BA3: 51 | BB3: 52 | BC3: 53 | BD3: 54 | BE3: 55 | BF3: 56 | BG3: 57 | BH3: 58 | BI3: 59 | BJ3: 60
A4: Financial Year | C4: Y1 | D4: Y1 | E4: Y1 | F4: Y1 | G4: Y1 | H4: Y1 | I4: Y1 | J4: Y1 | K4: Y1 | L4: Y1 | M4: Y1 | N4: Y1 | O4: Y2 | P4: Y2 | Q4: Y2 | R4: Y2 | S4: Y2 | T4: Y2 | U4: Y2 | V4: Y2 | W4: Y2 | X4: Y2 | Y4: Y2 | Z4: Y2 | AA4: Y3 | AB4: Y3 | AC4: Y3 | AD4: Y3 | AE4: Y3 | AF4: Y3 | AG4: Y3 | AH4: Y3 | AI4: Y3 | AJ4: Y3 | AK4: Y3 | AL4: Y3 | AM4: Y4 | AN4: Y4 | AO4: Y4 | AP4: Y4 | AQ4: Y4 | AR4: Y4 | AS4: Y4 | AT4: Y4 | AU4: Y4 | AV4: Y4 | AW4: Y4 | AX4: Y4 | AY4: Y5 | AZ4: Y5 | BA4: Y5 | BB4: Y5 | BC4: Y5 | BD4: Y5 | BE4: Y5 | BF4: Y5 | BG4: Y5 | BH4: Y5 | BI4: Y5 | BJ4: Y5
A6: PRODUCTION
A7: Installed capacity (100%) | B7: tonnes | C7: =IFERROR(Assumptions!$C$30,0) -> 0 | D7: =IFERROR(Assumptions!$C$30,0) -> 0 | E7: =IFERROR(Assumptions!$C$30,0) -> 0 | F7: =IFERROR(Assumptions!$C$30,0) -> 0 | G7: =IFERROR(Assumptions!$C$30,0) -> 0 | H7: =IFERROR(Assumptions!$C$30,0) -> 0 | I7: =IFERROR(Assumptions!$C$30,0) -> 0 | J7: =IFERROR(Assumptions!$C$30,0) -> 0 | ... BJ7: =IFERROR(Assumptions!$C$30,0) -> 0
A8: Capacity utilisation | B8: % | C8: =IFERROR(Assumptions!$C$31,0) -> 0 | D8: =IFERROR(Assumptions!$C$31,0) -> 0 | E8: =IFERROR(Assumptions!$C$31,0) -> 0 | F8: =IFERROR(Assumptions!$C$31,0) -> 0 | G8: =IFERROR(Assumptions!$C$31,0) -> 0 | H8: =IFERROR(Assumptions!$C$31,0) -> 0 | I8: =IFERROR(Assumptions!$C$31,0) -> 0 | J8: =IFERROR(Assumptions!$C$31,0) -> 0 | ... N8: =IFERROR(Assumptions!$C$31,0) -> 0 | O8: =IFERROR(Assumptions!$C$32,0) -> 0 | P8: =IFERROR(Assumptions!$C$32,0) -> 0 | Q8: =IFERROR(Assumptions!$C$32,0) -> 0 | R8: =IFERROR(Assumptions!$C$32,0) -> 0 | S8: =IFERROR(Assumptions!$C$32,0) -> 0 | T8: =IFERROR(Assumptions!$C$32,0) -> 0 | U8: =IFERROR(Assumptions!$C$32,0) -> 0 | V8: =IFERROR(Assumptions!$C$32,0) -> 0 | ... Z8: =IFERROR(Assumptions!$C$32,0) -> 0 | AA8: =IFERROR(Assumptions!$C$33,0) -> 0 | AB8: =IFERROR(Assumptions!$C$33,0) -> 0 | AC8: =IFERROR(Assumptions!$C$33,0) -> 0 | AD8: =IFERROR(Assumptions!$C$33,0) -> 0 | AE8: =IFERROR(Assumptions!$C$33,0) -> 0 | AF8: =IFERROR(Assumptions!$C$33,0) -> 0 | AG8: =IFERROR(Assumptions!$C$33,0) -> 0 | AH8: =IFERROR(Assumptions!$C$33,0) -> 0 | ... AL8: =IFERROR(Assumptions!$C$33,0) -> 0 | AM8: =IFERROR(Assumptions!$C$34,0) -> 0 | AN8: =IFERROR(Assumptions!$C$34,0) -> 0 | AO8: =IFERROR(Assumptions!$C$34,0) -> 0 | AP8: =IFERROR(Assumptions!$C$34,0) -> 0 | AQ8: =IFERROR(Assumptions!$C$34,0) -> 0 | AR8: =IFERROR(Assumptions!$C$34,0) -> 0 | AS8: =IFERROR(Assumptions!$C$34,0) -> 0 | AT8: =IFERROR(Assumptions!$C$34,0) -> 0 | ... AX8: =IFERROR(Assumptions!$C$34,0) -> 0 | AY8: =IFERROR(Assumptions!$C$35,0) -> 0 | AZ8: =IFERROR(Assumptions!$C$35,0) -> 0 | BA8: =IFERROR(Assumptions!$C$35,0) -> 0 | BB8: =IFERROR(Assumptions!$C$35,0) -> 0 | BC8: =IFERROR(Assumptions!$C$35,0) -> 0 | BD8: =IFERROR(Assumptions!$C$35,0) -> 0 | BE8: =IFERROR(Assumptions!$C$35,0) -> 0 | BF8: =IFERROR(Assumptions!$C$35,0) -> 0 | ... BJ8: =IFERROR(Assumptions!$C$35,0) -> 0
A9: Production | B9: tonnes | C9: =IFERROR(C7*C8,0) -> 0 | D9: =IFERROR(D7*D8,0) -> 0 | E9: =IFERROR(E7*E8,0) -> 0 | F9: =IFERROR(F7*F8,0) -> 0 | G9: =IFERROR(G7*G8,0) -> 0 | H9: =IFERROR(H7*H8,0) -> 0 | I9: =IFERROR(I7*I8,0) -> 0 | J9: =IFERROR(J7*J8,0) -> 0 | ... BJ9: =IFERROR(BJ7*BJ8,0) -> 0
A10: Sales volume | B10: tonnes | C10: =IFERROR(C9,0) -> 0 | D10: =IFERROR(D9,0) -> 0 | E10: =IFERROR(E9,0) -> 0 | F10: =IFERROR(F9,0) -> 0 | G10: =IFERROR(G9,0) -> 0 | H10: =IFERROR(H9,0) -> 0 | I10: =IFERROR(I9,0) -> 0 | J10: =IFERROR(J9,0) -> 0 | ... BJ10: =IFERROR(BJ9,0) -> 0
A11: REVENUE
A12: Net realisation | B12: ₹/tonne | C12: =IFERROR(Assumptions!$C$37*(1+Assumptions!$C$8)^(1-1),0) -> 0 | D12: =IFERROR(Assumptions!$C$37*(1+Assumptions!$C$8)^(1-1),0) -> 0 | E12: =IFERROR(Assumptions!$C$37*(1+Assumptions!$C$8)^(1-1),0) -> 0 | F12: =IFERROR(Assumptions!$C$37*(1+Assumptions!$C$8)^(1-1),0) -> 0 | G12: =IFERROR(Assumptions!$C$37*(1+Assumptions!$C$8)^(1-1),0) -> 0 | H12: =IFERROR(Assumptions!$C$37*(1+Assumptions!$C$8)^(1-1),0) -> 0 | I12: =IFERROR(Assumptions!$C$37*(1+Assumptions!$C$8)^(1-1),0) -> 0 | J12: =IFERROR(Assumptions!$C$37*(1+Assumptions!$C$8)^(1-1),0) -> 0 | ... N12: =IFERROR(Assumptions!$C$37*(1+Assumptions!$C$8)^(1-1),0) -> 0 | O12: =IFERROR(Assumptions!$C$37*(1+Assumptions!$C$8)^(2-1),0) -> 0 | P12: =IFERROR(Assumptions!$C$37*(1+Assumptions!$C$8)^(2-1),0) -> 0 | Q12: =IFERROR(Assumptions!$C$37*(1+Assumptions!$C$8)^(2-1),0) -> 0 | R12: =IFERROR(Assumptions!$C$37*(1+Assumptions!$C$8)^(2-1),0) -> 0 | S12: =IFERROR(Assumptions!$C$37*(1+Assumptions!$C$8)^(2-1),0) -> 0 | T12: =IFERROR(Assumptions!$C$37*(1+Assumptions!$C$8)^(2-1),0) -> 0 | U12: =IFERROR(Assumptions!$C$37*(1+Assumptions!$C$8)^(2-1),0) -> 0 | V12: =IFERROR(Assumptions!$C$37*(1+Assumptions!$C$8)^(2-1),0) -> 0 | ... Z12: =IFERROR(Assumptions!$C$37*(1+Assumptions!$C$8)^(2-1),0) -> 0 | AA12: =IFERROR(Assumptions!$C$37*(1+Assumptions!$C$8)^(3-1),0) -> 0 | AB12: =IFERROR(Assumptions!$C$37*(1+Assumptions!$C$8)^(3-1),0) -> 0 | AC12: =IFERROR(Assumptions!$C$37*(1+Assumptions!$C$8)^(3-1),0) -> 0 | AD12: =IFERROR(Assumptions!$C$37*(1+Assumptions!$C$8)^(3-1),0) -> 0 | AE12: =IFERROR(Assumptions!$C$37*(1+Assumptions!$C$8)^(3-1),0) -> 0 | AF12: =IFERROR(Assumptions!$C$37*(1+Assumptions!$C$8)^(3-1),0) -> 0 | AG12: =IFERROR(Assumptions!$C$37*(1+Assumptions!$C$8)^(3-1),0) -> 0 | AH12: =IFERROR(Assumptions!$C$37*(1+Assumptions!$C$8)^(3-1),0) -> 0 | ... AL12: =IFERROR(Assumptions!$C$37*(1+Assumptions!$C$8)^(3-1),0) -> 0 | AM12: =IFERROR(Assumptions!$C$37*(1+Assumptions!$C$8)^(4-1),0) -> 0 | AN12: =IFERROR(Assumptions!$C$37*(1+Assumptions!$C$8)^(4-1),0) -> 0 | AO12: =IFERROR(Assumptions!$C$37*(1+Assumptions!$C$8)^(4-1),0) -> 0 | AP12: =IFERROR(Assumptions!$C$37*(1+Assumptions!$C$8)^(4-1),0) -> 0 | AQ12: =IFERROR(Assumptions!$C$37*(1+Assumptions!$C$8)^(4-1),0) -> 0 | AR12: =IFERROR(Assumptions!$C$37*(1+Assumptions!$C$8)^(4-1),0) -> 0 | AS12: =IFERROR(Assumptions!$C$37*(1+Assumptions!$C$8)^(4-1),0) -> 0 | AT12: =IFERROR(Assumptions!$C$37*(1+Assumptions!$C$8)^(4-1),0) -> 0 | ... AX12: =IFERROR(Assumptions!$C$37*(1+Assumptions!$C$8)^(4-1),0) -> 0 | AY12: =IFERROR(Assumptions!$C$37*(1+Assumptions!$C$8)^(5-1),0) -> 0 | AZ12: =IFERROR(Assumptions!$C$37*(1+Assumptions!$C$8)^(5-1),0) -> 0 | BA12: =IFERROR(Assumptions!$C$37*(1+Assumptions!$C$8)^(5-1),0) -> 0 | BB12: =IFERROR(Assumptions!$C$37*(1+Assumptions!$C$8)^(5-1),0) -> 0 | BC12: =IFERROR(Assumptions!$C$37*(1+Assumptions!$C$8)^(5-1),0) -> 0 | BD12: =IFERROR(Assumptions!$C$37*(1+Assumptions!$C$8)^(5-1),0) -> 0 | BE12: =IFERROR(Assumptions!$C$37*(1+Assumptions!$C$8)^(5-1),0) -> 0 | BF12: =IFERROR(Assumptions!$C$37*(1+Assumptions!$C$8)^(5-1),0) -> 0 | ... BJ12: =IFERROR(Assumptions!$C$37*(1+Assumptions!$C$8)^(5-1),0) -> 0
A13: Gross revenue (net of GST) | B13: ₹ lakh | C13: =IFERROR(C10*C12/100000,0) -> 0 | D13: =IFERROR(D10*D12/100000,0) -> 0 | E13: =IFERROR(E10*E12/100000,0) -> 0 | F13: =IFERROR(F10*F12/100000,0) -> 0 | G13: =IFERROR(G10*G12/100000,0) -> 0 | H13: =IFERROR(H10*H12/100000,0) -> 0 | I13: =IFERROR(I10*I12/100000,0) -> 0 | J13: =IFERROR(J10*J12/100000,0) -> 0 | ... BJ13: =IFERROR(BJ10*BJ12/100000,0) -> 0
A14: DIRECT COST OF GOODS SOLD
A15: Raw material | B15: ₹ lakh | C15: =IFERROR(C10*Assumptions!$C$38*(1+Assumptions!$C$9)^(1-1)/100000,0) -> 0 | D15: =IFERROR(D10*Assumptions!$C$38*(1+Assumptions!$C$9)^(1-1)/100000,0) -> 0 | E15: =IFERROR(E10*Assumptions!$C$38*(1+Assumptions!$C$9)^(1-1)/100000,0) -> 0 | F15: =IFERROR(F10*Assumptions!$C$38*(1+Assumptions!$C$9)^(1-1)/100000,0) -> 0 | G15: =IFERROR(G10*Assumptions!$C$38*(1+Assumptions!$C$9)^(1-1)/100000,0) -> 0 | H15: =IFERROR(H10*Assumptions!$C$38*(1+Assumptions!$C$9)^(1-1)/100000,0) -> 0 | I15: =IFERROR(I10*Assumptions!$C$38*(1+Assumptions!$C$9)^(1-1)/100000,0) -> 0 | J15: =IFERROR(J10*Assumptions!$C$38*(1+Assumptions!$C$9)^(1-1)/100000,0) -> 0 | ... N15: =IFERROR(N10*Assumptions!$C$38*(1+Assumptions!$C$9)^(1-1)/100000,0) -> 0 | O15: =IFERROR(O10*Assumptions!$C$38*(1+Assumptions!$C$9)^(2-1)/100000,0) -> 0 | P15: =IFERROR(P10*Assumptions!$C$38*(1+Assumptions!$C$9)^(2-1)/100000,0) -> 0 | Q15: =IFERROR(Q10*Assumptions!$C$38*(1+Assumptions!$C$9)^(2-1)/100000,0) -> 0 | R15: =IFERROR(R10*Assumptions!$C$38*(1+Assumptions!$C$9)^(2-1)/100000,0) -> 0 | S15: =IFERROR(S10*Assumptions!$C$38*(1+Assumptions!$C$9)^(2-1)/100000,0) -> 0 | T15: =IFERROR(T10*Assumptions!$C$38*(1+Assumptions!$C$9)^(2-1)/100000,0) -> 0 | U15: =IFERROR(U10*Assumptions!$C$38*(1+Assumptions!$C$9)^(2-1)/100000,0) -> 0 | V15: =IFERROR(V10*Assumptions!$C$38*(1+Assumptions!$C$9)^(2-1)/100000,0) -> 0 | ... Z15: =IFERROR(Z10*Assumptions!$C$38*(1+Assumptions!$C$9)^(2-1)/100000,0) -> 0 | AA15: =IFERROR(AA10*Assumptions!$C$38*(1+Assumptions!$C$9)^(3-1)/100000,0) -> 0 | AB15: =IFERROR(AB10*Assumptions!$C$38*(1+Assumptions!$C$9)^(3-1)/100000,0) -> 0 | AC15: =IFERROR(AC10*Assumptions!$C$38*(1+Assumptions!$C$9)^(3-1)/100000,0) -> 0 | AD15: =IFERROR(AD10*Assumptions!$C$38*(1+Assumptions!$C$9)^(3-1)/100000,0) -> 0 | AE15: =IFERROR(AE10*Assumptions!$C$38*(1+Assumptions!$C$9)^(3-1)/100000,0) -> 0 | AF15: =IFERROR(AF10*Assumptions!$C$38*(1+Assumptions!$C$9)^(3-1)/100000,0) -> 0 | AG15: =IFERROR(AG10*Assumptions!$C$38*(1+Assumptions!$C$9)^(3-1)/100000,0) -> 0 | AH15: =IFERROR(AH10*Assumptions!$C$38*(1+Assumptions!$C$9)^(3-1)/100000,0) -> 0 | ... AL15: =IFERROR(AL10*Assumptions!$C$38*(1+Assumptions!$C$9)^(3-1)/100000,0) -> 0 | AM15: =IFERROR(AM10*Assumptions!$C$38*(1+Assumptions!$C$9)^(4-1)/100000,0) -> 0 | AN15: =IFERROR(AN10*Assumptions!$C$38*(1+Assumptions!$C$9)^(4-1)/100000,0) -> 0 | AO15: =IFERROR(AO10*Assumptions!$C$38*(1+Assumptions!$C$9)^(4-1)/100000,0) -> 0 | AP15: =IFERROR(AP10*Assumptions!$C$38*(1+Assumptions!$C$9)^(4-1)/100000,0) -> 0 | AQ15: =IFERROR(AQ10*Assumptions!$C$38*(1+Assumptions!$C$9)^(4-1)/100000,0) -> 0 | AR15: =IFERROR(AR10*Assumptions!$C$38*(1+Assumptions!$C$9)^(4-1)/100000,0) -> 0 | AS15: =IFERROR(AS10*Assumptions!$C$38*(1+Assumptions!$C$9)^(4-1)/100000,0) -> 0 | AT15: =IFERROR(AT10*Assumptions!$C$38*(1+Assumptions!$C$9)^(4-1)/100000,0) -> 0 | ... AX15: =IFERROR(AX10*Assumptions!$C$38*(1+Assumptions!$C$9)^(4-1)/100000,0) -> 0 | AY15: =IFERROR(AY10*Assumptions!$C$38*(1+Assumptions!$C$9)^(5-1)/100000,0) -> 0 | AZ15: =IFERROR(AZ10*Assumptions!$C$38*(1+Assumptions!$C$9)^(5-1)/100000,0) -> 0 | BA15: =IFERROR(BA10*Assumptions!$C$38*(1+Assumptions!$C$9)^(5-1)/100000,0) -> 0 | BB15: =IFERROR(BB10*Assumptions!$C$38*(1+Assumptions!$C$9)^(5-1)/100000,0) -> 0 | BC15: =IFERROR(BC10*Assumptions!$C$38*(1+Assumptions!$C$9)^(5-1)/100000,0) -> 0 | BD15: =IFERROR(BD10*Assumptions!$C$38*(1+Assumptions!$C$9)^(5-1)/100000,0) -> 0 | BE15: =IFERROR(BE10*Assumptions!$C$38*(1+Assumptions!$C$9)^(5-1)/100000,0) -> 0 | BF15: =IFERROR(BF10*Assumptions!$C$38*(1+Assumptions!$C$9)^(5-1)/100000,0) -> 0 | ... BJ15: =IFERROR(BJ10*Assumptions!$C$38*(1+Assumptions!$C$9)^(5-1)/100000,0) -> 0
A16: Packaging & consumables | B16: ₹ lakh | C16: =IFERROR(C10*Assumptions!$C$39*(1+Assumptions!$C$9)^(1-1)/100000,0) -> 0 | D16: =IFERROR(D10*Assumptions!$C$39*(1+Assumptions!$C$9)^(1-1)/100000,0) -> 0 | E16: =IFERROR(E10*Assumptions!$C$39*(1+Assumptions!$C$9)^(1-1)/100000,0) -> 0 | F16: =IFERROR(F10*Assumptions!$C$39*(1+Assumptions!$C$9)^(1-1)/100000,0) -> 0 | G16: =IFERROR(G10*Assumptions!$C$39*(1+Assumptions!$C$9)^(1-1)/100000,0) -> 0 | H16: =IFERROR(H10*Assumptions!$C$39*(1+Assumptions!$C$9)^(1-1)/100000,0) -> 0 | I16: =IFERROR(I10*Assumptions!$C$39*(1+Assumptions!$C$9)^(1-1)/100000,0) -> 0 | J16: =IFERROR(J10*Assumptions!$C$39*(1+Assumptions!$C$9)^(1-1)/100000,0) -> 0 | ... N16: =IFERROR(N10*Assumptions!$C$39*(1+Assumptions!$C$9)^(1-1)/100000,0) -> 0 | O16: =IFERROR(O10*Assumptions!$C$39*(1+Assumptions!$C$9)^(2-1)/100000,0) -> 0 | P16: =IFERROR(P10*Assumptions!$C$39*(1+Assumptions!$C$9)^(2-1)/100000,0) -> 0 | Q16: =IFERROR(Q10*Assumptions!$C$39*(1+Assumptions!$C$9)^(2-1)/100000,0) -> 0 | R16: =IFERROR(R10*Assumptions!$C$39*(1+Assumptions!$C$9)^(2-1)/100000,0) -> 0 | S16: =IFERROR(S10*Assumptions!$C$39*(1+Assumptions!$C$9)^(2-1)/100000,0) -> 0 | T16: =IFERROR(T10*Assumptions!$C$39*(1+Assumptions!$C$9)^(2-1)/100000,0) -> 0 | U16: =IFERROR(U10*Assumptions!$C$39*(1+Assumptions!$C$9)^(2-1)/100000,0) -> 0 | V16: =IFERROR(V10*Assumptions!$C$39*(1+Assumptions!$C$9)^(2-1)/100000,0) -> 0 | ... Z16: =IFERROR(Z10*Assumptions!$C$39*(1+Assumptions!$C$9)^(2-1)/100000,0) -> 0 | AA16: =IFERROR(AA10*Assumptions!$C$39*(1+Assumptions!$C$9)^(3-1)/100000,0) -> 0 | AB16: =IFERROR(AB10*Assumptions!$C$39*(1+Assumptions!$C$9)^(3-1)/100000,0) -> 0 | AC16: =IFERROR(AC10*Assumptions!$C$39*(1+Assumptions!$C$9)^(3-1)/100000,0) -> 0 | AD16: =IFERROR(AD10*Assumptions!$C$39*(1+Assumptions!$C$9)^(3-1)/100000,0) -> 0 | AE16: =IFERROR(AE10*Assumptions!$C$39*(1+Assumptions!$C$9)^(3-1)/100000,0) -> 0 | AF16: =IFERROR(AF10*Assumptions!$C$39*(1+Assumptions!$C$9)^(3-1)/100000,0) -> 0 | AG16: =IFERROR(AG10*Assumptions!$C$39*(1+Assumptions!$C$9)^(3-1)/100000,0) -> 0 | AH16: =IFERROR(AH10*Assumptions!$C$39*(1+Assumptions!$C$9)^(3-1)/100000,0) -> 0 | ... AL16: =IFERROR(AL10*Assumptions!$C$39*(1+Assumptions!$C$9)^(3-1)/100000,0) -> 0 | AM16: =IFERROR(AM10*Assumptions!$C$39*(1+Assumptions!$C$9)^(4-1)/100000,0) -> 0 | AN16: =IFERROR(AN10*Assumptions!$C$39*(1+Assumptions!$C$9)^(4-1)/100000,0) -> 0 | AO16: =IFERROR(AO10*Assumptions!$C$39*(1+Assumptions!$C$9)^(4-1)/100000,0) -> 0 | AP16: =IFERROR(AP10*Assumptions!$C$39*(1+Assumptions!$C$9)^(4-1)/100000,0) -> 0 | AQ16: =IFERROR(AQ10*Assumptions!$C$39*(1+Assumptions!$C$9)^(4-1)/100000,0) -> 0 | AR16: =IFERROR(AR10*Assumptions!$C$39*(1+Assumptions!$C$9)^(4-1)/100000,0) -> 0 | AS16: =IFERROR(AS10*Assumptions!$C$39*(1+Assumptions!$C$9)^(4-1)/100000,0) -> 0 | AT16: =IFERROR(AT10*Assumptions!$C$39*(1+Assumptions!$C$9)^(4-1)/100000,0) -> 0 | ... AX16: =IFERROR(AX10*Assumptions!$C$39*(1+Assumptions!$C$9)^(4-1)/100000,0) -> 0 | AY16: =IFERROR(AY10*Assumptions!$C$39*(1+Assumptions!$C$9)^(5-1)/100000,0) -> 0 | AZ16: =IFERROR(AZ10*Assumptions!$C$39*(1+Assumptions!$C$9)^(5-1)/100000,0) -> 0 | BA16: =IFERROR(BA10*Assumptions!$C$39*(1+Assumptions!$C$9)^(5-1)/100000,0) -> 0 | BB16: =IFERROR(BB10*Assumptions!$C$39*(1+Assumptions!$C$9)^(5-1)/100000,0) -> 0 | BC16: =IFERROR(BC10*Assumptions!$C$39*(1+Assumptions!$C$9)^(5-1)/100000,0) -> 0 | BD16: =IFERROR(BD10*Assumptions!$C$39*(1+Assumptions!$C$9)^(5-1)/100000,0) -> 0 | BE16: =IFERROR(BE10*Assumptions!$C$39*(1+Assumptions!$C$9)^(5-1)/100000,0) -> 0 | BF16: =IFERROR(BF10*Assumptions!$C$39*(1+Assumptions!$C$9)^(5-1)/100000,0) -> 0 | ... BJ16: =IFERROR(BJ10*Assumptions!$C$39*(1+Assumptions!$C$9)^(5-1)/100000,0) -> 0
A17: Direct utilities | B17: ₹ lakh | C17: =IFERROR(C10*Assumptions!$C$40*(1+Assumptions!$C$11)^(1-1)/100000,0) -> 0 | D17: =IFERROR(D10*Assumptions!$C$40*(1+Assumptions!$C$11)^(1-1)/100000,0) -> 0 | E17: =IFERROR(E10*Assumptions!$C$40*(1+Assumptions!$C$11)^(1-1)/100000,0) -> 0 | F17: =IFERROR(F10*Assumptions!$C$40*(1+Assumptions!$C$11)^(1-1)/100000,0) -> 0 | G17: =IFERROR(G10*Assumptions!$C$40*(1+Assumptions!$C$11)^(1-1)/100000,0) -> 0 | H17: =IFERROR(H10*Assumptions!$C$40*(1+Assumptions!$C$11)^(1-1)/100000,0) -> 0 | I17: =IFERROR(I10*Assumptions!$C$40*(1+Assumptions!$C$11)^(1-1)/100000,0) -> 0 | J17: =IFERROR(J10*Assumptions!$C$40*(1+Assumptions!$C$11)^(1-1)/100000,0) -> 0 | ... N17: =IFERROR(N10*Assumptions!$C$40*(1+Assumptions!$C$11)^(1-1)/100000,0) -> 0 | O17: =IFERROR(O10*Assumptions!$C$40*(1+Assumptions!$C$11)^(2-1)/100000,0) -> 0 | P17: =IFERROR(P10*Assumptions!$C$40*(1+Assumptions!$C$11)^(2-1)/100000,0) -> 0 | Q17: =IFERROR(Q10*Assumptions!$C$40*(1+Assumptions!$C$11)^(2-1)/100000,0) -> 0 | R17: =IFERROR(R10*Assumptions!$C$40*(1+Assumptions!$C$11)^(2-1)/100000,0) -> 0 | S17: =IFERROR(S10*Assumptions!$C$40*(1+Assumptions!$C$11)^(2-1)/100000,0) -> 0 | T17: =IFERROR(T10*Assumptions!$C$40*(1+Assumptions!$C$11)^(2-1)/100000,0) -> 0 | U17: =IFERROR(U10*Assumptions!$C$40*(1+Assumptions!$C$11)^(2-1)/100000,0) -> 0 | V17: =IFERROR(V10*Assumptions!$C$40*(1+Assumptions!$C$11)^(2-1)/100000,0) -> 0 | ... Z17: =IFERROR(Z10*Assumptions!$C$40*(1+Assumptions!$C$11)^(2-1)/100000,0) -> 0 | AA17: =IFERROR(AA10*Assumptions!$C$40*(1+Assumptions!$C$11)^(3-1)/100000,0) -> 0 | AB17: =IFERROR(AB10*Assumptions!$C$40*(1+Assumptions!$C$11)^(3-1)/100000,0) -> 0 | AC17: =IFERROR(AC10*Assumptions!$C$40*(1+Assumptions!$C$11)^(3-1)/100000,0) -> 0 | AD17: =IFERROR(AD10*Assumptions!$C$40*(1+Assumptions!$C$11)^(3-1)/100000,0) -> 0 | AE17: =IFERROR(AE10*Assumptions!$C$40*(1+Assumptions!$C$11)^(3-1)/100000,0) -> 0 | AF17: =IFERROR(AF10*Assumptions!$C$40*(1+Assumptions!$C$11)^(3-1)/100000,0) -> 0 | AG17: =IFERROR(AG10*Assumptions!$C$40*(1+Assumptions!$C$11)^(3-1)/100000,0) -> 0 | AH17: =IFERROR(AH10*Assumptions!$C$40*(1+Assumptions!$C$11)^(3-1)/100000,0) -> 0 | ... AL17: =IFERROR(AL10*Assumptions!$C$40*(1+Assumptions!$C$11)^(3-1)/100000,0) -> 0 | AM17: =IFERROR(AM10*Assumptions!$C$40*(1+Assumptions!$C$11)^(4-1)/100000,0) -> 0 | AN17: =IFERROR(AN10*Assumptions!$C$40*(1+Assumptions!$C$11)^(4-1)/100000,0) -> 0 | AO17: =IFERROR(AO10*Assumptions!$C$40*(1+Assumptions!$C$11)^(4-1)/100000,0) -> 0 | AP17: =IFERROR(AP10*Assumptions!$C$40*(1+Assumptions!$C$11)^(4-1)/100000,0) -> 0 | AQ17: =IFERROR(AQ10*Assumptions!$C$40*(1+Assumptions!$C$11)^(4-1)/100000,0) -> 0 | AR17: =IFERROR(AR10*Assumptions!$C$40*(1+Assumptions!$C$11)^(4-1)/100000,0) -> 0 | AS17: =IFERROR(AS10*Assumptions!$C$40*(1+Assumptions!$C$11)^(4-1)/100000,0) -> 0 | AT17: =IFERROR(AT10*Assumptions!$C$40*(1+Assumptions!$C$11)^(4-1)/100000,0) -> 0 | ... AX17: =IFERROR(AX10*Assumptions!$C$40*(1+Assumptions!$C$11)^(4-1)/100000,0) -> 0 | AY17: =IFERROR(AY10*Assumptions!$C$40*(1+Assumptions!$C$11)^(5-1)/100000,0) -> 0 | AZ17: =IFERROR(AZ10*Assumptions!$C$40*(1+Assumptions!$C$11)^(5-1)/100000,0) -> 0 | BA17: =IFERROR(BA10*Assumptions!$C$40*(1+Assumptions!$C$11)^(5-1)/100000,0) -> 0 | BB17: =IFERROR(BB10*Assumptions!$C$40*(1+Assumptions!$C$11)^(5-1)/100000,0) -> 0 | BC17: =IFERROR(BC10*Assumptions!$C$40*(1+Assumptions!$C$11)^(5-1)/100000,0) -> 0 | BD17: =IFERROR(BD10*Assumptions!$C$40*(1+Assumptions!$C$11)^(5-1)/100000,0) -> 0 | BE17: =IFERROR(BE10*Assumptions!$C$40*(1+Assumptions!$C$11)^(5-1)/100000,0) -> 0 | BF17: =IFERROR(BF10*Assumptions!$C$40*(1+Assumptions!$C$11)^(5-1)/100000,0) -> 0 | ... BJ17: =IFERROR(BJ10*Assumptions!$C$40*(1+Assumptions!$C$11)^(5-1)/100000,0) -> 0
A18: Other direct cost | B18: ₹ lakh | C18: =IFERROR(C10*Assumptions!$C$41*(1+Assumptions!$C$11)^(1-1)/100000,0) -> 0 | D18: =IFERROR(D10*Assumptions!$C$41*(1+Assumptions!$C$11)^(1-1)/100000,0) -> 0 | E18: =IFERROR(E10*Assumptions!$C$41*(1+Assumptions!$C$11)^(1-1)/100000,0) -> 0 | F18: =IFERROR(F10*Assumptions!$C$41*(1+Assumptions!$C$11)^(1-1)/100000,0) -> 0 | G18: =IFERROR(G10*Assumptions!$C$41*(1+Assumptions!$C$11)^(1-1)/100000,0) -> 0 | H18: =IFERROR(H10*Assumptions!$C$41*(1+Assumptions!$C$11)^(1-1)/100000,0) -> 0 | I18: =IFERROR(I10*Assumptions!$C$41*(1+Assumptions!$C$11)^(1-1)/100000,0) -> 0 | J18: =IFERROR(J10*Assumptions!$C$41*(1+Assumptions!$C$11)^(1-1)/100000,0) -> 0 | ... N18: =IFERROR(N10*Assumptions!$C$41*(1+Assumptions!$C$11)^(1-1)/100000,0) -> 0 | O18: =IFERROR(O10*Assumptions!$C$41*(1+Assumptions!$C$11)^(2-1)/100000,0) -> 0 | P18: =IFERROR(P10*Assumptions!$C$41*(1+Assumptions!$C$11)^(2-1)/100000,0) -> 0 | Q18: =IFERROR(Q10*Assumptions!$C$41*(1+Assumptions!$C$11)^(2-1)/100000,0) -> 0 | R18: =IFERROR(R10*Assumptions!$C$41*(1+Assumptions!$C$11)^(2-1)/100000,0) -> 0 | S18: =IFERROR(S10*Assumptions!$C$41*(1+Assumptions!$C$11)^(2-1)/100000,0) -> 0 | T18: =IFERROR(T10*Assumptions!$C$41*(1+Assumptions!$C$11)^(2-1)/100000,0) -> 0 | U18: =IFERROR(U10*Assumptions!$C$41*(1+Assumptions!$C$11)^(2-1)/100000,0) -> 0 | V18: =IFERROR(V10*Assumptions!$C$41*(1+Assumptions!$C$11)^(2-1)/100000,0) -> 0 | ... Z18: =IFERROR(Z10*Assumptions!$C$41*(1+Assumptions!$C$11)^(2-1)/100000,0) -> 0 | AA18: =IFERROR(AA10*Assumptions!$C$41*(1+Assumptions!$C$11)^(3-1)/100000,0) -> 0 | AB18: =IFERROR(AB10*Assumptions!$C$41*(1+Assumptions!$C$11)^(3-1)/100000,0) -> 0 | AC18: =IFERROR(AC10*Assumptions!$C$41*(1+Assumptions!$C$11)^(3-1)/100000,0) -> 0 | AD18: =IFERROR(AD10*Assumptions!$C$41*(1+Assumptions!$C$11)^(3-1)/100000,0) -> 0 | AE18: =IFERROR(AE10*Assumptions!$C$41*(1+Assumptions!$C$11)^(3-1)/100000,0) -> 0 | AF18: =IFERROR(AF10*Assumptions!$C$41*(1+Assumptions!$C$11)^(3-1)/100000,0) -> 0 | AG18: =IFERROR(AG10*Assumptions!$C$41*(1+Assumptions!$C$11)^(3-1)/100000,0) -> 0 | AH18: =IFERROR(AH10*Assumptions!$C$41*(1+Assumptions!$C$11)^(3-1)/100000,0) -> 0 | ... AL18: =IFERROR(AL10*Assumptions!$C$41*(1+Assumptions!$C$11)^(3-1)/100000,0) -> 0 | AM18: =IFERROR(AM10*Assumptions!$C$41*(1+Assumptions!$C$11)^(4-1)/100000,0) -> 0 | AN18: =IFERROR(AN10*Assumptions!$C$41*(1+Assumptions!$C$11)^(4-1)/100000,0) -> 0 | AO18: =IFERROR(AO10*Assumptions!$C$41*(1+Assumptions!$C$11)^(4-1)/100000,0) -> 0 | AP18: =IFERROR(AP10*Assumptions!$C$41*(1+Assumptions!$C$11)^(4-1)/100000,0) -> 0 | AQ18: =IFERROR(AQ10*Assumptions!$C$41*(1+Assumptions!$C$11)^(4-1)/100000,0) -> 0 | AR18: =IFERROR(AR10*Assumptions!$C$41*(1+Assumptions!$C$11)^(4-1)/100000,0) -> 0 | AS18: =IFERROR(AS10*Assumptions!$C$41*(1+Assumptions!$C$11)^(4-1)/100000,0) -> 0 | AT18: =IFERROR(AT10*Assumptions!$C$41*(1+Assumptions!$C$11)^(4-1)/100000,0) -> 0 | ... AX18: =IFERROR(AX10*Assumptions!$C$41*(1+Assumptions!$C$11)^(4-1)/100000,0) -> 0 | AY18: =IFERROR(AY10*Assumptions!$C$41*(1+Assumptions!$C$11)^(5-1)/100000,0) -> 0 | AZ18: =IFERROR(AZ10*Assumptions!$C$41*(1+Assumptions!$C$11)^(5-1)/100000,0) -> 0 | BA18: =IFERROR(BA10*Assumptions!$C$41*(1+Assumptions!$C$11)^(5-1)/100000,0) -> 0 | BB18: =IFERROR(BB10*Assumptions!$C$41*(1+Assumptions!$C$11)^(5-1)/100000,0) -> 0 | BC18: =IFERROR(BC10*Assumptions!$C$41*(1+Assumptions!$C$11)^(5-1)/100000,0) -> 0 | BD18: =IFERROR(BD10*Assumptions!$C$41*(1+Assumptions!$C$11)^(5-1)/100000,0) -> 0 | BE18: =IFERROR(BE10*Assumptions!$C$41*(1+Assumptions!$C$11)^(5-1)/100000,0) -> 0 | BF18: =IFERROR(BF10*Assumptions!$C$41*(1+Assumptions!$C$11)^(5-1)/100000,0) -> 0 | ... BJ18: =IFERROR(BJ10*Assumptions!$C$41*(1+Assumptions!$C$11)^(5-1)/100000,0) -> 0
A19: Total COGS | B19: ₹ lakh | C19: =IFERROR(SUM(C15:C18),0) -> 0 | D19: =IFERROR(SUM(D15:D18),0) -> 0 | E19: =IFERROR(SUM(E15:E18),0) -> 0 | F19: =IFERROR(SUM(F15:F18),0) -> 0 | G19: =IFERROR(SUM(G15:G18),0) -> 0 | H19: =IFERROR(SUM(H15:H18),0) -> 0 | I19: =IFERROR(SUM(I15:I18),0) -> 0 | J19: =IFERROR(SUM(J15:J18),0) -> 0 | ... BJ19: =IFERROR(SUM(BJ15:BJ18),0) -> 0
A20: Gross profit | B20: ₹ lakh | C20: =IFERROR(C13-C19,0) -> 0 | D20: =IFERROR(D13-D19,0) -> 0 | E20: =IFERROR(E13-E19,0) -> 0 | F20: =IFERROR(F13-F19,0) -> 0 | G20: =IFERROR(G13-G19,0) -> 0 | H20: =IFERROR(H13-H19,0) -> 0 | I20: =IFERROR(I13-I19,0) -> 0 | J20: =IFERROR(J13-J19,0) -> 0 | ... BJ20: =IFERROR(BJ13-BJ19,0) -> 0
A21: OPERATING EXPENSES
A22: Salaries & wages | B22: ₹ lakh | C22: =IFERROR(Payroll!C9,0) -> 0 | D22: =IFERROR(Payroll!D9,0) -> 0 | E22: =IFERROR(Payroll!E9,0) -> 0 | F22: =IFERROR(Payroll!F9,0) -> 0 | G22: =IFERROR(Payroll!G9,0) -> 0 | H22: =IFERROR(Payroll!H9,0) -> 0 | I22: =IFERROR(Payroll!I9,0) -> 0 | J22: =IFERROR(Payroll!J9,0) -> 0 | ... BJ22: =IFERROR(Payroll!BJ9,0) -> 0
A23: Fixed power, fuel & DG | B23: ₹ lakh | C23: =IFERROR(Assumptions!$C$43*(1+Assumptions!$C$11)^(1-1),0) -> 0 | D23: =IFERROR(Assumptions!$C$43*(1+Assumptions!$C$11)^(1-1),0) -> 0 | E23: =IFERROR(Assumptions!$C$43*(1+Assumptions!$C$11)^(1-1),0) -> 0 | F23: =IFERROR(Assumptions!$C$43*(1+Assumptions!$C$11)^(1-1),0) -> 0 | G23: =IFERROR(Assumptions!$C$43*(1+Assumptions!$C$11)^(1-1),0) -> 0 | H23: =IFERROR(Assumptions!$C$43*(1+Assumptions!$C$11)^(1-1),0) -> 0 | I23: =IFERROR(Assumptions!$C$43*(1+Assumptions!$C$11)^(1-1),0) -> 0 | J23: =IFERROR(Assumptions!$C$43*(1+Assumptions!$C$11)^(1-1),0) -> 0 | ... N23: =IFERROR(Assumptions!$C$43*(1+Assumptions!$C$11)^(1-1),0) -> 0 | O23: =IFERROR(Assumptions!$C$43*(1+Assumptions!$C$11)^(2-1),0) -> 0 | P23: =IFERROR(Assumptions!$C$43*(1+Assumptions!$C$11)^(2-1),0) -> 0 | Q23: =IFERROR(Assumptions!$C$43*(1+Assumptions!$C$11)^(2-1),0) -> 0 | R23: =IFERROR(Assumptions!$C$43*(1+Assumptions!$C$11)^(2-1),0) -> 0 | S23: =IFERROR(Assumptions!$C$43*(1+Assumptions!$C$11)^(2-1),0) -> 0 | T23: =IFERROR(Assumptions!$C$43*(1+Assumptions!$C$11)^(2-1),0) -> 0 | U23: =IFERROR(Assumptions!$C$43*(1+Assumptions!$C$11)^(2-1),0) -> 0 | V23: =IFERROR(Assumptions!$C$43*(1+Assumptions!$C$11)^(2-1),0) -> 0 | ... Z23: =IFERROR(Assumptions!$C$43*(1+Assumptions!$C$11)^(2-1),0) -> 0 | AA23: =IFERROR(Assumptions!$C$43*(1+Assumptions!$C$11)^(3-1),0) -> 0 | AB23: =IFERROR(Assumptions!$C$43*(1+Assumptions!$C$11)^(3-1),0) -> 0 | AC23: =IFERROR(Assumptions!$C$43*(1+Assumptions!$C$11)^(3-1),0) -> 0 | AD23: =IFERROR(Assumptions!$C$43*(1+Assumptions!$C$11)^(3-1),0) -> 0 | AE23: =IFERROR(Assumptions!$C$43*(1+Assumptions!$C$11)^(3-1),0) -> 0 | AF23: =IFERROR(Assumptions!$C$43*(1+Assumptions!$C$11)^(3-1),0) -> 0 | AG23: =IFERROR(Assumptions!$C$43*(1+Assumptions!$C$11)^(3-1),0) -> 0 | AH23: =IFERROR(Assumptions!$C$43*(1+Assumptions!$C$11)^(3-1),0) -> 0 | ... AL23: =IFERROR(Assumptions!$C$43*(1+Assumptions!$C$11)^(3-1),0) -> 0 | AM23: =IFERROR(Assumptions!$C$43*(1+Assumptions!$C$11)^(4-1),0) -> 0 | AN23: =IFERROR(Assumptions!$C$43*(1+Assumptions!$C$11)^(4-1),0) -> 0 | AO23: =IFERROR(Assumptions!$C$43*(1+Assumptions!$C$11)^(4-1),0) -> 0 | AP23: =IFERROR(Assumptions!$C$43*(1+Assumptions!$C$11)^(4-1),0) -> 0 | AQ23: =IFERROR(Assumptions!$C$43*(1+Assumptions!$C$11)^(4-1),0) -> 0 | AR23: =IFERROR(Assumptions!$C$43*(1+Assumptions!$C$11)^(4-1),0) -> 0 | AS23: =IFERROR(Assumptions!$C$43*(1+Assumptions!$C$11)^(4-1),0) -> 0 | AT23: =IFERROR(Assumptions!$C$43*(1+Assumptions!$C$11)^(4-1),0) -> 0 | ... AX23: =IFERROR(Assumptions!$C$43*(1+Assumptions!$C$11)^(4-1),0) -> 0 | AY23: =IFERROR(Assumptions!$C$43*(1+Assumptions!$C$11)^(5-1),0) -> 0 | AZ23: =IFERROR(Assumptions!$C$43*(1+Assumptions!$C$11)^(5-1),0) -> 0 | BA23: =IFERROR(Assumptions!$C$43*(1+Assumptions!$C$11)^(5-1),0) -> 0 | BB23: =IFERROR(Assumptions!$C$43*(1+Assumptions!$C$11)^(5-1),0) -> 0 | BC23: =IFERROR(Assumptions!$C$43*(1+Assumptions!$C$11)^(5-1),0) -> 0 | BD23: =IFERROR(Assumptions!$C$43*(1+Assumptions!$C$11)^(5-1),0) -> 0 | BE23: =IFERROR(Assumptions!$C$43*(1+Assumptions!$C$11)^(5-1),0) -> 0 | BF23: =IFERROR(Assumptions!$C$43*(1+Assumptions!$C$11)^(5-1),0) -> 0 | ... BJ23: =IFERROR(Assumptions!$C$43*(1+Assumptions!$C$11)^(5-1),0) -> 0
