Workbook

Sheet Cover
B2: CREDIT MONITORING ARRANGEMENT (CMA) REPORT
B3: Projected Financials for Bank Term-Loan & Working-Capital Appraisal
B5: Name of the Unit | C5: =Assumptions!C5 -> SaaS Solutions Pvt Ltd
B6: Constitution | C6: =Assumptions!C6 -> Private Limited
B7: Line of Activity | C7: =Assumptions!C7 -> B2B SaaS subscription product
B8: Term Loan applied for (₹) | C8: =Assumptions!C8 -> 4000000
B9: Promoters' Capital (₹) | C9: =Assumptions!C9 -> 1000000
B10: Projection horizon | C10: 5 years (60 months), monthly
B12: CONTENTS
B13: Assumptions | C13: All input variables — the single control panel for the model
B14: Production | C14: 60-month production plan (capacity × utilisation × phasing)
B15: Sales | C15: 60-month sales quantity, price and revenue
B16: Expenses | C16: 60-month operating expenses, interest and depreciation
B17: Profit | C17: 60-month P&L: EBITDA → EBIT → PBT → PAT
B18: Annual_Summary | C18: Consolidated 5-year figures feeding the CMA forms
B19: Form_II_Operating | C19: Form II — Operating statement (profitability)
B20: Form_III_BalanceSheet | C20: Form III — Projected balance sheet
B21: Form_IV_CA_CL | C21: Form IV — Current assets & current liabilities
B22: Form_V_MPBF | C22: Form V — Maximum permissible bank finance
B23: Form_VI_FundFlow | C23: Form VI — Fund-flow statement
B24: Repayment | C24: Term-loan repayment schedule
... B26: Ratios | C26: Key ratios — financial viability
B28: Enter data only in the blue cells on the Assumptions sheet; all other sheets recalculate automatically.

Sheet Dashboard
B1: CMA DASHBOARD — KEY METRICS AT A GLANCE
B3: Live summary — every figure below recalculates automatically from the Assumptions and calculation sheets.
B5: TERM LOAN AMOUNT | F5: PROMOTERS' CAPITAL | J5: AVERAGE DSCR (5-YR) | N5: TERM LOAN TENURE
B7: =Assumptions!C8 -> 4000000 | F7: =Assumptions!C9 -> 1000000 | J7: =DSCR!H14 -> 15.43369 | N7: =Assumptions!C11 -> 60
B10: YEAR-1 EBITDA MARGIN | F10: YEAR-1 NET PROFIT MARGIN | J10: YEAR-1 BREAK-EVEN (% SALES) | N10: YEAR-1 CURRENT RATIO
B12: =Ratios!C10 -> 0.3015625 | F12: =Ratios!C11 -> 0.21335866 | J12: =Ratios!C16 -> 0.36782619 | N12: =Ratios!C6 -> 5.1478711
B52: SELECT YEAR TO VIEW SNAPSHOT → | D52: 1
B54: REVENUE (SELECTED YEAR) | F54: EBITDA (SELECTED YEAR) | J54: PAT (SELECTED YEAR) | N54: DSCR (SELECTED YEAR)
B56: =INDEX(Annual_Summary!C8:G8,1,$D$52) -> 46080000 | F56: =INDEX(Annual_Summary!C22:G22,1,$D$52) -> 13896000 | J56: =INDEX(Annual_Summary!C26:G26,1,$D$52) -> 9831567.1 | N56: =INDEX(DSCR!C14:G14,1,$D$52) -> 7.9048475
B90: WC Component | C90: Days
B91: Raw Material Holding | C91: =Assumptions!C50 -> 0
B92: Finished Goods Holding | C92: =Assumptions!C51 -> 0
B93: Receivables | C93: =Assumptions!C52 -> 30
B94: Payables | C94: =Assumptions!C53 -> 30
B96: Ratio | C96: Year 1 | D96: Year 5
B97: Current Ratio | C97: =Ratios!C6 -> 5.1478711 | D97: =Ratios!G6 -> 14.987105
B98: Debt-Equity Ratio | C98: =Ratios!C7 -> 0.4966788 | D98: =Ratios!G7 -> 0.04855429
B99: EBITDA Margin | C99: =Ratios!C10 -> 0.3015625 | D99: =Ratios!G10 -> 0.31834236
B100: Net Profit Margin | C100: =Ratios!C11 -> 0.21335866 | D100: =Ratios!G11 -> 0.23312998

Sheet Assumptions
A1: ASSUMPTIONS — KEY INPUTS
A2: Enter values only in the blue/shaded cells. Every other sheet updates automatically.
B4: A. COMPANY & LOAN PARTICULARS | S4: Industry | T4: CapLabel | U4: ProdUnitLabel | V4: Cost1Long | W4: Cost1Short | X4: Cost2Long | Y4: Cost2Short | Z4: Cost3Short
B5: Name of the Unit | C5: SaaS Solutions Pvt Ltd | I5: INDUSTRY / BUSINESS TYPE → | J5: Technology & Software | S5: Agriculture & Farming | T5: Installed Capacity (land / livestock / output) | U5: Production (units) | V5: Raw material / input cost per unit (Year 1) | W5: Raw materials / inputs | X5: Power & fuel cost per unit (Year 1) | Y5: Power & fuel | Z5: Farm overheads
B6: Constitution (Proprietor / Partnership / Pvt Ltd) | C6: Private Limited | S6: Technology & Software | T6: Service Delivery Capacity (billable hours/licenses p.a.) | U6: Service delivery (units) | V6: Direct delivery cost per unit (Year 1) | W6: Direct delivery cost | X6: Infrastructure & hosting cost per unit (Year 1) | Y6: Infrastructure & hosting | Z6: Operating overheads
B7: Line of Activity / Product | C7: B2B SaaS subscription product | S7: Retail & E-Commerce | T7: Annual Purchase Capacity (units for resale) | U7: Purchase (units) | V7: Purchase cost of goods per unit (Year 1) | W7: Purchase cost of goods | X7: Freight & packaging cost per unit (Year 1) | Y7: Freight & packaging | Z7: Store overheads
B8: Term Loan applied for | C8: 4000000 | H8: ₹ | S8: Manufacturing | T8: Installed Capacity | U8: Production (units) | V8: Raw material cost per unit (Year 1) | W8: Raw materials | X8: Power & fuel cost per unit (Year 1) | Y8: Power & fuel | Z8: Factory overheads
B9: Promoters' Capital / Equity brought in | C9: 1000000 | H9: ₹ | S9: Tourism & Hospitality | T9: Room / Cover Capacity (room-nights or covers p.a.) | U9: Rooms sold / covers served (units) | V9: Direct service cost per unit (F&B, housekeeping) (Year 1) | W9: Direct service cost | X9: Power & fuel cost per unit (Year 1) | Y9: Power & fuel | Z9: Property overheads
B10: Interest rate on Term Loan | C10: 0.105 | H10: % p.a. | S10: Renewable Energy | T10: Installed Generation Capacity (units of energy p.a.) | U10: Energy generated (units) | V10: O&M cost per unit generated (Year 1) | W10: O&M cost | X10: Grid / power evacuation cost per unit (Year 1) | Y10: Grid / evacuation cost | Z10: Plant overheads
B11: Term Loan tenure | C11: 60 | H11: years | S11: Healthcare & Pharma | T11: Service / Production Capacity (patients or units p.a.) | U11: Patients served / units produced | V11: Consumables & medicine cost per unit (Year 1) | W11: Consumables & medicine | X11: Power & equipment running cost per unit (Year 1) | Y11: Power & equipment cost | Z11: Facility overheads
B12: Moratorium / holiday period | C12: 6 | H12: months | S12: Education & Training | T12: Service Capacity (student seats / batches p.a.) | U12: Students / batches served | V12: Direct delivery cost per unit (faculty, material) (Year 1) | W12: Direct delivery cost | X12: Infrastructure cost per unit (Year 1) | Y12: Infrastructure cost | Z12: Institute overheads
B13: Interest rate on Working Capital | C13: 0.12 | H13: % p.a. | S13: General Business | T13: Capacity (units / customers / hours p.a.) | U13: Output (units) | V13: Direct cost per unit (Year 1) | W13: Direct cost | X13: Overhead cost per unit (Year 1) | Y13: Overhead cost | Z13: Operating overheads
B14: Income Tax rate | C14: 0.25 | H14: % | S14: Construction & Real Estate | T14: Project Execution Capacity (sq.ft / units p.a.) | U14: Construction / units completed | V14: Construction material cost per unit (Year 1) | W14: Construction materials | X14: Site power & machinery cost per unit (Year 1) | Y14: Site power & machinery | Z14: Project overheads
B15: B. CAPACITY & PRODUCTION | S15: Food & Beverage / Restaurant | T15: Seating / Covers Capacity (covers p.a.) | U15: Covers served (units) | V15: Raw material (food & beverage) cost per unit (Year 1) | W15: Food & beverage cost | X15: Kitchen power & fuel cost per unit (Year 1) | Y15: Kitchen power & fuel | Z15: Restaurant overheads
B16: =IFERROR(VLOOKUP($J$5,$S$5:$Z$21,2,FALSE()),"Installed Capacity") -> Service Delivery Capacity (billable hours/licenses p.a.) | C16: 4800 | H16: units p.a. | S16: Transportation & Logistics | T16: Fleet / Route Capacity (trips or tonnage p.a.) | U16: Trips / tonnage handled (units) | V16: Fuel & running cost per unit (Year 1) | W16: Fuel & running cost | X16: Vehicle maintenance cost per unit (Year 1) | Y16: Vehicle maintenance | Z16: Fleet overheads
B17: Capacity Utilisation | C17: Yr 1 | D17: Yr 2 | E17: Yr 3 | F17: Yr 4 | G17: Yr 5 | S17: Textile & Garments | T17: Installed Capacity (garments/fabric units p.a.) | U17: Production (units) | V17: Raw material (yarn/fabric) cost per unit (Year 1) | W17: Raw materials (yarn/fabric) | X17: Power & fuel cost per unit (Year 1) | Y17: Power & fuel | Z17: Factory overheads
B18: → enter % for Year 1 … 5 | C18: 0.8 | D18: 0.85 | E18: 0.9 | F18: 0.95 | G18: 1 | H18: % | S18: Automobile / Auto Ancillary | T18: Installed Capacity (components/vehicles p.a.) | U18: Production (units) | V18: Raw material / component cost per unit (Year 1) | W18: Raw materials / components | X18: Power & fuel cost per unit (Year 1) | Y18: Power & fuel | Z18: Factory overheads
B19: C. MONTHLY PHASING FACTOR (optional — blank = equal spread) | S19: Import / Export Trading | T19: Annual Trading Capacity (units for import/export) | U19: Trading volume (units) | V19: Purchase / import cost per unit (Year 1) | W19: Purchase / import cost | X19: Freight, customs & logistics cost per unit (Year 1) | Y19: Freight & customs | Z19: Trading overheads
B20: Relative weight per month (M1…M12) | C20: M1 | D20: M2 | E20: M3 | F20: M4 | G20: M5 | H20: M6 | I20: M7 | J20: M8 | K20: M9 | L20: M10 | M20: M11 | N20: M12 | S20: Media & Entertainment | T20: Content / Production Capacity (units/hours p.a.) | U20: Content produced (units) | V20: Production cost per unit (Year 1) | W20: Production cost | X20: Equipment & studio cost per unit (Year 1) | Y20: Equipment & studio cost | Z20: Studio overheads
B21: → weights (e.g. 1.0 each, or seasonal) | C21: 0.083 | D21: 0.083 | E21: 0.083 | F21: 0.083 | G21: 0.083 | H21: 0.083 | I21: 0.083 | J21: 0.083 | K21: 0.083 | L21: 0.083 | M21: 0.083 | N21: 0.083 | S21: Mining & Minerals | T21: Installed Extraction Capacity (tonnes p.a.) | U21: Extraction (units) | V21: Raw material / extraction cost per unit (Year 1) | W21: Extraction cost | X21: Power & fuel cost per unit (Year 1) | Y21: Power & fuel | Z21: Mine overheads
B22: D. PRICE & VARIABLE COSTS (Year-1 base, escalated by the % below)
B23: Selling price per unit (Year 1) | C23: 12000 | H23: ₹/unit
B24: annual price escalation | C24: 0.05 | H24: %
B25: =IFERROR(VLOOKUP($J$5,$S$5:$Z$21,4,FALSE()),"Raw material cost per unit (Year 1)") -> Direct delivery cost per unit (Year 1) | C25: 3000 | H25: ₹/unit
B26: annual RM cost escalation | C26: 0.06 | H26: %
B27: =IFERROR(VLOOKUP($J$5,$S$5:$Z$21,6,FALSE()),"Power & fuel cost per unit (Year 1)") -> Infrastructure & hosting cost per unit (Year 1) | C27: 2000 | H27: ₹/unit
B28: annual power cost escalation | C28: 0.05 | H28: %
B29: Other variable cost per unit (Year 1) | C29: 1000 | H29: ₹/unit
B30: annual other-variable escalation | C30: 0.04 | H30: %
B31: E. FIXED / PERIOD COSTS (per month, Year-1 base, escalated below)
B32: Direct wages & salaries / month (Year 1) | C32: 400000 | H32: ₹/month
B33: annual wages escalation | C33: 0.07 | H33: %
B34: Factory overheads / month (Year 1) | C34: 100000 | H34: ₹/month
B35: annual factory-OH escalation | C35: 0.05 | H35: %
B36: Repairs & maintenance / month (Year 1) | C36: 20000 | H36: ₹/month
B37: annual R&M escalation | C37: 0.04 | H37: %
B38: Administrative expenses / month (Year 1) | C38: 50000 | H38: ₹/month
B39: annual admin escalation | C39: 0.05 | H39: %
B40: Selling & distribution | C40: 0.05 | H40: % of sales
B41: F. FIXED ASSETS & DEPRECIATION (straight-line on cost)
...

Sheet Production
A1: PRODUCTION PLAN — 60-MONTH PROJECTION
A2: Driven by Installed Capacity × Capacity Utilisation × Monthly phasing (Assumptions).
B3: YEAR 1 | O3: YEAR 2 | AB3: YEAR 3 | AO3: YEAR 4 | BB3: YEAR 5
A4: Particulars | B4: M1 | C4: M2 | D4: M3 | E4: M4 | F4: M5 | G4: M6 | H4: M7 | I4: M8 | J4: M9 | K4: M10 | L4: M11 | M4: M12 | N4: Yr 1 Total | O4: M13 | P4: M14 | Q4: M15 | R4: M16 | S4: M17 | T4: M18 | U4: M19 | V4: M20 | W4: M21 | X4: M22 | Y4: M23 | Z4: M24 | AA4: Yr 2 Total | AB4: M25 | AC4: M26 | AD4: M27 | AE4: M28 | AF4: M29 | AG4: M30 | AH4: M31 | AI4: M32 | AJ4: M33 | AK4: M34 | AL4: M35 | AM4: M36 | AN4: Yr 3 Total | AO4: M37 | AP4: M38 | AQ4: M39 | AR4: M40 | AS4: M41 | AT4: M42 | AU4: M43 | AV4: M44 | AW4: M45 | AX4: M46 | AY4: M47 | AZ4: M48 | BA4: Yr 4 Total | BB4: M49 | BC4: M50 | BD4: M51 | BE4: M52 | BF4: M53 | BG4: M54 | BH4: M55 | BI4: M56 | BJ4: M57 | BK4: M58 | BL4: M59 | BM4: M60 | BN4: Yr 5 Total
A5: Capacity utilisation (%) | B5: =Assumptions!$C$18 -> 0.8 | C5: =Assumptions!$C$18 -> 0.8 | D5: =Assumptions!$C$18 -> 0.8 | E5: =Assumptions!$C$18 -> 0.8 | F5: =Assumptions!$C$18 -> 0.8 | G5: =Assumptions!$C$18 -> 0.8 | H5: =Assumptions!$C$18 -> 0.8 | I5: =Assumptions!$C$18 -> 0.8 | ... N5: =Assumptions!$C$18 -> 0.8 | O5: =Assumptions!$D$18 -> 0.85 | P5: =Assumptions!$D$18 -> 0.85 | Q5: =Assumptions!$D$18 -> 0.85 | R5: =Assumptions!$D$18 -> 0.85 | S5: =Assumptions!$D$18 -> 0.85 | T5: =Assumptions!$D$18 -> 0.85 | U5: =Assumptions!$D$18 -> 0.85 | V5: =Assumptions!$D$18 -> 0.85 | ... AA5: =Assumptions!$D$18 -> 0.85 | AB5: =Assumptions!$E$18 -> 0.9 | AC5: =Assumptions!$E$18 -> 0.9 | AD5: =Assumptions!$E$18 -> 0.9 | AE5: =Assumptions!$E$18 -> 0.9 | AF5: =Assumptions!$E$18 -> 0.9 | AG5: =Assumptions!$E$18 -> 0.9 | AH5: =Assumptions!$E$18 -> 0.9 | AI5: =Assumptions!$E$18 -> 0.9 | ... AN5: =Assumptions!$E$18 -> 0.9 | AO5: =Assumptions!$F$18 -> 0.95 | AP5: =Assumptions!$F$18 -> 0.95 | AQ5: =Assumptions!$F$18 -> 0.95 | AR5: =Assumptions!$F$18 -> 0.95 | AS5: =Assumptions!$F$18 -> 0.95 | AT5: =Assumptions!$F$18 -> 0.95 | AU5: =Assumptions!$F$18 -> 0.95 | AV5: =Assumptions!$F$18 -> 0.95 | ... BA5: =Assumptions!$F$18 -> 0.95 | BB5: =Assumptions!$G$18 -> 1 | BC5: =Assumptions!$G$18 -> 1 | BD5: =Assumptions!$G$18 -> 1 | BE5: =Assumptions!$G$18 -> 1 | BF5: =Assumptions!$G$18 -> 1 | BG5: =Assumptions!$G$18 -> 1 | BH5: =Assumptions!$G$18 -> 1 | BI5: =Assumptions!$G$18 -> 1 | ... BN5: =Assumptions!$G$18 -> 1
A6: =IFERROR(VLOOKUP(Assumptions!$J$5,Assumptions!$S$5:$Z$21,3,FALSE()),"Production (units)") -> Service delivery (units) | B6: =(Assumptions!$C$16*Assumptions!$C$18/12)*IF(SUM(Assumptions!$C$21:$N$21)=0,1,12*Assumptions!$C$21/SUM(Assumptions!$C$21:$N$21)) -> 320 | C6: =(Assumptions!$C$16*Assumptions!$C$18/12)*IF(SUM(Assumptions!$C$21:$N$21)=0,1,12*Assumptions!$D$21/SUM(Assumptions!$C$21:$N$21)) -> 320 | D6: =(Assumptions!$C$16*Assumptions!$C$18/12)*IF(SUM(Assumptions!$C$21:$N$21)=0,1,12*Assumptions!$E$21/SUM(Assumptions!$C$21:$N$21)) -> 320 | E6: =(Assumptions!$C$16*Assumptions!$C$18/12)*IF(SUM(Assumptions!$C$21:$N$21)=0,1,12*Assumptions!$F$21/SUM(Assumptions!$C$21:$N$21)) -> 320 | F6: =(Assumptions!$C$16*Assumptions!$C$18/12)*IF(SUM(Assumptions!$C$21:$N$21)=0,1,12*Assumptions!$G$21/SUM(Assumptions!$C$21:$N$21)) -> 320 | G6: =(Assumptions!$C$16*Assumptions!$C$18/12)*IF(SUM(Assumptions!$C$21:$N$21)=0,1,12*Assumptions!$H$21/SUM(Assumptions!$C$21:$N$21)) -> 320 | H6: =(Assumptions!$C$16*Assumptions!$C$18/12)*IF(SUM(Assumptions!$C$21:$N$21)=0,1,12*Assumptions!$I$21/SUM(Assumptions!$C$21:$N$21)) -> 320 | I6: =(Assumptions!$C$16*Assumptions!$C$18/12)*IF(SUM(Assumptions!$C$21:$N$21)=0,1,12*Assumptions!$J$21/SUM(Assumptions!$C$21:$N$21)) -> 320 | J6: =(Assumptions!$C$16*Assumptions!$C$18/12)*IF(SUM(Assumptions!$C$21:$N$21)=0,1,12*Assumptions!$K$21/SUM(Assumptions!$C$21:$N$21)) -> 320 | K6: =(Assumptions!$C$16*Assumptions!$C$18/12)*IF(SUM(Assumptions!$C$21:$N$21)=0,1,12*Assumptions!$L$21/SUM(Assumptions!$C$21:$N$21)) -> 320 | L6: =(Assumptions!$C$16*Assumptions!$C$18/12)*IF(SUM(Assumptions!$C$21:$N$21)=0,1,12*Assumptions!$M$21/SUM(Assumptions!$C$21:$N$21)) -> 320 | M6: =(Assumptions!$C$16*Assumptions!$C$18/12)*IF(SUM(Assumptions!$C$21:$N$21)=0,1,12*Assumptions!$N$21/SUM(Assumptions!$C$21:$N$21)) -> 320 | N6: =SUM(B6:M6) -> 3840 | O6: =(Assumptions!$C$16*Assumptions!$D$18/12)*IF(SUM(Assumptions!$C$21:$N$21)=0,1,12*Assumptions!$C$21/SUM(Assumptions!$C$21:$N$21)) -> 340 | P6: =(Assumptions!$C$16*Assumptions!$D$18/12)*IF(SUM(Assumptions!$C$21:$N$21)=0,1,12*Assumptions!$D$21/SUM(Assumptions!$C$21:$N$21)) -> 340 | Q6: =(Assumptions!$C$16*Assumptions!$D$18/12)*IF(SUM(Assumptions!$C$21:$N$21)=0,1,12*Assumptions!$E$21/SUM(Assumptions!$C$21:$N$21)) -> 340 | R6: =(Assumptions!$C$16*Assumptions!$D$18/12)*IF(SUM(Assumptions!$C$21:$N$21)=0,1,12*Assumptions!$F$21/SUM(Assumptions!$C$21:$N$21)) -> 340 | S6: =(Assumptions!$C$16*Assumptions!$D$18/12)*IF(SUM(Assumptions!$C$21:$N$21)=0,1,12*Assumptions!$G$21/SUM(Assumptions!$C$21:$N$21)) -> 340 | T6: =(Assumptions!$C$16*Assumptions!$D$18/12)*IF(SUM(Assumptions!$C$21:$N$21)=0,1,12*Assumptions!$H$21/SUM(Assumptions!$C$21:$N$21)) -> 340 | U6: =(Assumptions!$C$16*Assumptions!$D$18/12)*IF(SUM(Assumptions!$C$21:$N$21)=0,1,12*Assumptions!$I$21/SUM(Assumptions!$C$21:$N$21)) -> 340 | V6: =(Assumptions!$C$16*Assumptions!$D$18/12)*IF(SUM(Assumptions!$C$21:$N$21)=0,1,12*Assumptions!$J$21/SUM(Assumptions!$C$21:$N$21)) -> 340 | W6: =(Assumptions!$C$16*Assumptions!$D$18/12)*IF(SUM(Assumptions!$C$21:$N$21)=0,1,12*Assumptions!$K$21/SUM(Assumptions!$C$21:$N$21)) -> 340 | X6: =(Assumptions!$C$16*Assumptions!$D$18/12)*IF(SUM(Assumptions!$C$21:$N$21)=0,1,12*Assumptions!$L$21/SUM(Assumptions!$C$21:$N$21)) -> 340 | Y6: =(Assumptions!$C$16*Assumptions!$D$18/12)*IF(SUM(Assumptions!$C$21:$N$21)=0,1,12*Assumptions!$M$21/SUM(Assumptions!$C$21:$N$21)) -> 340 | Z6: =(Assumptions!$C$16*Assumptions!$D$18/12)*IF(SUM(Assumptions!$C$21:$N$21)=0,1,12*Assumptions!$N$21/SUM(Assumptions!$C$21:$N$21)) -> 340 | AA6: =SUM(O6:Z6) -> 4080 | AB6: =(Assumptions!$C$16*Assumptions!$E$18/12)*IF(SUM(Assumptions!$C$21:$N$21)=0,1,12*Assumptions!$C$21/SUM(Assumptions!$C$21:$N$21)) -> 360 | AC6: =(Assumptions!$C$16*Assumptions!$E$18/12)*IF(SUM(Assumptions!$C$21:$N$21)=0,1,12*Assumptions!$D$21/SUM(Assumptions!$C$21:$N$21)) -> 360 | AD6: =(Assumptions!$C$16*Assumptions!$E$18/12)*IF(SUM(Assumptions!$C$21:$N$21)=0,1,12*Assumptions!$E$21/SUM(Assumptions!$C$21:$N$21)) -> 360 | AE6: =(Assumptions!$C$16*Assumptions!$E$18/12)*IF(SUM(Assumptions!$C$21:$N$21)=0,1,12*Assumptions!$F$21/SUM(Assumptions!$C$21:$N$21)) -> 360 | AF6: =(Assumptions!$C$16*Assumptions!$E$18/12)*IF(SUM(Assumptions!$C$21:$N$21)=0,1,12*Assumptions!$G$21/SUM(Assumptions!$C$21:$N$21)) -> 360 | AG6: =(Assumptions!$C$16*Assumptions!$E$18/12)*IF(SUM(Assumptions!$C$21:$N$21)=0,1,12*Assumptions!$H$21/SUM(Assumptions!$C$21:$N$21)) -> 360 | AH6: =(Assumptions!$C$16*Assumptions!$E$18/12)*IF(SUM(Assumptions!$C$21:$N$21)=0,1,12*Assumptions!$I$21/SUM(Assumptions!$C$21:$N$21)) -> 360 | AI6: =(Assumptions!$C$16*Assumptions!$E$18/12)*IF(SUM(Assumptions!$C$21:$N$21)=0,1,12*Assumptions!$J$21/SUM(Assumptions!$C$21:$N$21)) -> 360 | AJ6: =(Assumptions!$C$16*Assumptions!$E$18/12)*IF(SUM(Assumptions!$C$21:$N$21)=0,1,12*Assumptions!$K$21/SUM(Assumptions!$C$21:$N$21)) -> 360 | AK6: =(Assumptions!$C$16*Assumptions!$E$18/12)*IF(SUM(Assumptions!$C$21:$N$21)=0,1,12*Assumptions!$L$21/SUM(Assumptions!$C$21:$N$21)) -> 360 | AL6: =(Assumptions!$C$16*Assumptions!$E$18/12)*IF(SUM(Assumptions!$C$21:$N$21)=0,1,12*Assumptions!$M$21/SUM(Assumptions!$C$21:$N$21)) -> 360 | AM6: =(Assumptions!$C$16*Assumptions!$E$18/12)*IF(SUM(Assumptions!$C$21:$N$21)=0,1,12*Assumptions!$N$21/SUM(Assumptions!$C$21:$N$21)) -> 360 | AN6: =SUM(AB6:AM6) -> 4320 | AO6: =(Assumptions!$C$16*Assumptions!$F$18/12)*IF(SUM(Assumptions!$C$21:$N$21)=0,1,12*Assumptions!$C$21/SUM(Assumptions!$C$21:$N$21)) -> 380 | AP6: =(Assumptions!$C$16*Assumptions!$F$18/12)*IF(SUM(Assumptions!$C$21:$N$21)=0,1,12*Assumptions!$D$21/SUM(Assumptions!$C$21:$N$21)) -> 380 | AQ6: =(Assumptions!$C$16*Assumptions!$F$18/12)*IF(SUM(Assumptions!$C$21:$N$21)=0,1,12*Assumptions!$E$21/SUM(Assumptions!$C$21:$N$21)) -> 380 | AR6: =(Assumptions!$C$16*Assumptions!$F$18/12)*IF(SUM(Assumptions!$C$21:$N$21)=0,1,12*Assumptions!$F$21/SUM(Assumptions!$C$21:$N$21)) -> 380 | AS6: =(Assumptions!$C$16*Assumptions!$F$18/12)*IF(SUM(Assumptions!$C$21:$N$21)=0,1,12*Assumptions!$G$21/SUM(Assumptions!$C$21:$N$21)) -> 380 | AT6: =(Assumptions!$C$16*Assumptions!$F$18/12)*IF(SUM(Assumptions!$C$21:$N$21)=0,1,12*Assumptions!$H$21/SUM(Assumptions!$C$21:$N$21)) -> 380 | AU6: =(Assumptions!$C$16*Assumptions!$F$18/12)*IF(SUM(Assumptions!$C$21:$N$21)=0,1,12*Assumptions!$I$21/SUM(Assumptions!$C$21:$N$21)) -> 380 | AV6: =(Assumptions!$C$16*Assumptions!$F$18/12)*IF(SUM(Assumptions!$C$21:$N$21)=0,1,12*Assumptions!$J$21/SUM(Assumptions!$C$21:$N$21)) -> 380 | AW6: =(Assumptions!$C$16*Assumptions!$F$18/12)*IF(SUM(Assumptions!$C$21:$N$21)=0,1,12*Assumptions!$K$21/SUM(Assumptions!$C$21:$N$21)) -> 380 | AX6: =(Assumptions!$C$16*Assumptions!$F$18/12)*IF(SUM(Assumptions!$C$21:$N$21)=0,1,12*Assumptions!$L$21/SUM(Assumptions!$C$21:$N$21)) -> 380 | AY6: =(Assumptions!$C$16*Assumptions!$F$18/12)*IF(SUM(Assumptions!$C$21:$N$21)=0,1,12*Assumptions!$M$21/SUM(Assumptions!$C$21:$N$21)) -> 380 | AZ6: =(Assumptions!$C$16*Assumptions!$F$18/12)*IF(SUM(Assumptions!$C$21:$N$21)=0,1,12*Assumptions!$N$21/SUM(Assumptions!$C$21:$N$21)) -> 380 | BA6: =SUM(AO6:AZ6) -> 4560 | BB6: =(Assumptions!$C$16*Assumptions!$G$18/12)*IF(SUM(Assumptions!$C$21:$N$21)=0,1,12*Assumptions!$C$21/SUM(Assumptions!$C$21:$N$21)) -> 400 | BC6: =(Assumptions!$C$16*Assumptions!$G$18/12)*IF(SUM(Assumptions!$C$21:$N$21)=0,1,12*Assumptions!$D$21/SUM(Assumptions!$C$21:$N$21)) -> 400 | BD6: =(Assumptions!$C$16*Assumptions!$G$18/12)*IF(SUM(Assumptions!$C$21:$N$21)=0,1,12*Assumptions!$E$21/SUM(Assumptions!$C$21:$N$21)) -> 400 | BE6: =(Assumptions!$C$16*Assumptions!$G$18/12)*IF(SUM(Assumptions!$C$21:$N$21)=0,1,12*Assumptions!$F$21/SUM(Assumptions!$C$21:$N$21)) -> 400 | BF6: =(Assumptions!$C$16*Assumptions!$G$18/12)*IF(SUM(Assumptions!$C$21:$N$21)=0,1,12*Assumptions!$G$21/SUM(Assumptions!$C$21:$N$21)) -> 400 | BG6: =(Assumptions!$C$16*Assumptions!$G$18/12)*IF(SUM(Assumptions!$C$21:$N$21)=0,1,12*Assumptions!$H$21/SUM(Assumptions!$C$21:$N$21)) -> 400 | BH6: =(Assumptions!$C$16*Assumptions!$G$18/12)*IF(SUM(Assumptions!$C$21:$N$21)=0,1,12*Assumptions!$I$21/SUM(Assumptions!$C$21:$N$21)) -> 400 | BI6: =(Assumptions!$C$16*Assumptions!$G$18/12)*IF(SUM(Assumptions!$C$21:$N$21)=0,1,12*Assumptions!$J$21/SUM(Assumptions!$C$21:$N$21)) -> 400 | BJ6: =(Assumptions!$C$16*Assumptions!$G$18/12)*IF(SUM(Assumptions!$C$21:$N$21)=0,1,12*Assumptions!$K$21/SUM(Assumptions!$C$21:$N$21)) -> 400 | BK6: =(Assumptions!$C$16*Assumptions!$G$18/12)*IF(SUM(Assumptions!$C$21:$N$21)=0,1,12*Assumptions!$L$21/SUM(Assumptions!$C$21:$N$21)) -> 400 | BL6: =(Assumptions!$C$16*Assumptions!$G$18/12)*IF(SUM(Assumptions!$C$21:$N$21)=0,1,12*Assumptions!$M$21/SUM(Assumptions!$C$21:$N$21)) -> 400 | BM6: =(Assumptions!$C$16*Assumptions!$G$18/12)*IF(SUM(Assumptions!$C$21:$N$21)=0,1,12*Assumptions!$N$21/SUM(Assumptions!$C$21:$N$21)) -> 400 | BN6: =SUM(BB6:BM6) -> 4800

Sheet Sales
A1: SALES PLAN — 60-MONTH PROJECTION
A2: Sales quantity = production; revenue = quantity × escalated selling price.
B3: YEAR 1 | O3: YEAR 2 | AB3: YEAR 3 | AO3: YEAR 4 | BB3: YEAR 5
A4: Particulars | B4: M1 | C4: M2 | D4: M3 | E4: M4 | F4: M5 | G4: M6 | H4: M7 | I4: M8 | J4: M9 | K4: M10 | L4: M11 | M4: M12 | N4: Yr 1 Total | O4: M13 | P4: M14 | Q4: M15 | R4: M16 | S4: M17 | T4: M18 | U4: M19 | V4: M20 | W4: M21 | X4: M22 | Y4: M23 | Z4: M24 | AA4: Yr 2 Total | AB4: M25 | AC4: M26 | AD4: M27 | AE4: M28 | AF4: M29 | AG4: M30 | AH4: M31 | AI4: M32 | AJ4: M33 | AK4: M34 | AL4: M35 | AM4: M36 | AN4: Yr 3 Total | AO4: M37 | AP4: M38 | AQ4: M39 | AR4: M40 | AS4: M41 | AT4: M42 | AU4: M43 | AV4: M44 | AW4: M45 | AX4: M46 | AY4: M47 | AZ4: M48 | BA4: Yr 4 Total | BB4: M49 | BC4: M50 | BD4: M51 | BE4: M52 | BF4: M53 | BG4: M54 | BH4: M55 | BI4: M56 | BJ4: M57 | BK4: M58 | BL4: M59 | BM4: M60 | BN4: Yr 5 Total
A5: Sales quantity (units) | B5: =Production!B6 -> 320 | C5: =Production!C6 -> 320 | D5: =Production!D6 -> 320 | E5: =Production!E6 -> 320 | F5: =Production!F6 -> 320 | G5: =Production!G6 -> 320 | H5: =Production!H6 -> 320 | I5: =Production!I6 -> 320 | ... M5: =Production!M6 -> 320 | N5: =SUM(B5:M5) -> 3840 | O5: =Production!O6 -> 340 | P5: =Production!P6 -> 340 | Q5: =Production!Q6 -> 340 | R5: =Production!R6 -> 340 | S5: =Production!S6 -> 340 | T5: =Production!T6 -> 340 | U5: =Production!U6 -> 340 | V5: =Production!V6 -> 340 | ... Z5: =Production!Z6 -> 340 | AA5: =SUM(O5:Z5) -> 4080 | AB5: =Production!AB6 -> 360 | AC5: =Production!AC6 -> 360 | AD5: =Production!AD6 -> 360 | AE5: =Production!AE6 -> 360 | AF5: =Production!AF6 -> 360 | AG5: =Production!AG6 -> 360 | AH5: =Production!AH6 -> 360 | AI5: =Production!AI6 -> 360 | ... AM5: =Production!AM6 -> 360 | AN5: =SUM(AB5:AM5) -> 4320 | AO5: =Production!AO6 -> 380 | AP5: =Production!AP6 -> 380 | AQ5: =Production!AQ6 -> 380 | AR5: =Production!AR6 -> 380 | AS5: =Production!AS6 -> 380 | AT5: =Production!AT6 -> 380 | AU5: =Production!AU6 -> 380 | AV5: =Production!AV6 -> 380 | ... AZ5: =Production!AZ6 -> 380 | BA5: =SUM(AO5:AZ5) -> 4560 | BB5: =Production!BB6 -> 400 | BC5: =Production!BC6 -> 400 | BD5: =Production!BD6 -> 400 | BE5: =Production!BE6 -> 400 | BF5: =Production!BF6 -> 400 | BG5: =Production!BG6 -> 400 | BH5: =Production!BH6 -> 400 | BI5: =Production!BI6 -> 400 | ... BM5: =Production!BM6 -> 400 | BN5: =SUM(BB5:BM5) -> 4800
A6: Selling price (₹ / unit) | B6: =Assumptions!$C$23*(1+Assumptions!$C$24)^0 -> 12000 | C6: =Assumptions!$C$23*(1+Assumptions!$C$24)^0 -> 12000 | D6: =Assumptions!$C$23*(1+Assumptions!$C$24)^0 -> 12000 | E6: =Assumptions!$C$23*(1+Assumptions!$C$24)^0 -> 12000 | F6: =Assumptions!$C$23*(1+Assumptions!$C$24)^0 -> 12000 | G6: =Assumptions!$C$23*(1+Assumptions!$C$24)^0 -> 12000 | H6: =Assumptions!$C$23*(1+Assumptions!$C$24)^0 -> 12000 | I6: =Assumptions!$C$23*(1+Assumptions!$C$24)^0 -> 12000 | ... N6: =Assumptions!$C$23*(1+Assumptions!$C$24)^0 -> 12000 | O6: =Assumptions!$C$23*(1+Assumptions!$C$24)^1 -> 12600 | P6: =Assumptions!$C$23*(1+Assumptions!$C$24)^1 -> 12600 | Q6: =Assumptions!$C$23*(1+Assumptions!$C$24)^1 -> 12600 | R6: =Assumptions!$C$23*(1+Assumptions!$C$24)^1 -> 12600 | S6: =Assumptions!$C$23*(1+Assumptions!$C$24)^1 -> 12600 | T6: =Assumptions!$C$23*(1+Assumptions!$C$24)^1 -> 12600 | U6: =Assumptions!$C$23*(1+Assumptions!$C$24)^1 -> 12600 | V6: =Assumptions!$C$23*(1+Assumptions!$C$24)^1 -> 12600 | ... AA6: =Assumptions!$C$23*(1+Assumptions!$C$24)^1 -> 12600 | AB6: =Assumptions!$C$23*(1+Assumptions!$C$24)^2 -> 13230 | AC6: =Assumptions!$C$23*(1+Assumptions!$C$24)^2 -> 13230 | AD6: =Assumptions!$C$23*(1+Assumptions!$C$24)^2 -> 13230 | AE6: =Assumptions!$C$23*(1+Assumptions!$C$24)^2 -> 13230 | AF6: =Assumptions!$C$23*(1+Assumptions!$C$24)^2 -> 13230 | AG6: =Assumptions!$C$23*(1+Assumptions!$C$24)^2 -> 13230 | AH6: =Assumptions!$C$23*(1+Assumptions!$C$24)^2 -> 13230 | AI6: =Assumptions!$C$23*(1+Assumptions!$C$24)^2 -> 13230 | ... AN6: =Assumptions!$C$23*(1+Assumptions!$C$24)^2 -> 13230 | AO6: =Assumptions!$C$23*(1+Assumptions!$C$24)^3 -> 13891.5 | AP6: =Assumptions!$C$23*(1+Assumptions!$C$24)^3 -> 13891.5 | AQ6: =Assumptions!$C$23*(1+Assumptions!$C$24)^3 -> 13891.5 | AR6: =Assumptions!$C$23*(1+Assumptions!$C$24)^3 -> 13891.5 | AS6: =Assumptions!$C$23*(1+Assumptions!$C$24)^3 -> 13891.5 | AT6: =Assumptions!$C$23*(1+Assumptions!$C$24)^3 -> 13891.5 | AU6: =Assumptions!$C$23*(1+Assumptions!$C$24)^3 -> 13891.5 | AV6: =Assumptions!$C$23*(1+Assumptions!$C$24)^3 -> 13891.5 | ... BA6: =Assumptions!$C$23*(1+Assumptions!$C$24)^3 -> 13891.5 | BB6: =Assumptions!$C$23*(1+Assumptions!$C$24)^4 -> 14586.075 | BC6: =Assumptions!$C$23*(1+Assumptions!$C$24)^4 -> 14586.075 | BD6: =Assumptions!$C$23*(1+Assumptions!$C$24)^4 -> 14586.075 | BE6: =Assumptions!$C$23*(1+Assumptions!$C$24)^4 -> 14586.075 | BF6: =Assumptions!$C$23*(1+Assumptions!$C$24)^4 -> 14586.075 | BG6: =Assumptions!$C$23*(1+Assumptions!$C$24)^4 -> 14586.075 | BH6: =Assumptions!$C$23*(1+Assumptions!$C$24)^4 -> 14586.075 | BI6: =Assumptions!$C$23*(1+Assumptions!$C$24)^4 -> 14586.075 | ... BN6: =Assumptions!$C$23*(1+Assumptions!$C$24)^4 -> 14586.075
A7: Net Sales / Revenue (₹) | B7: =B5*B6 -> 3840000 | C7: =C5*C6 -> 3840000 | D7: =D5*D6 -> 3840000 | E7: =E5*E6 -> 3840000 | F7: =F5*F6 -> 3840000 | G7: =G5*G6 -> 3840000 | H7: =H5*H6 -> 3840000 | I7: =I5*I6 -> 3840000 | ... M7: =M5*M6 -> 3840000 | N7: =SUM(B7:M7) -> 46080000 | O7: =O5*O6 -> 4284000 | P7: =P5*P6 -> 4284000 | Q7: =Q5*Q6 -> 4284000 | R7: =R5*R6 -> 4284000 | S7: =S5*S6 -> 4284000 | T7: =T5*T6 -> 4284000 | U7: =U5*U6 -> 4284000 | V7: =V5*V6 -> 4284000 | ... Z7: =Z5*Z6 -> 4284000 | AA7: =SUM(O7:Z7) -> 51408000 | AB7: =AB5*AB6 -> 4762800 | AC7: =AC5*AC6 -> 4762800 | AD7: =AD5*AD6 -> 4762800 | AE7: =AE5*AE6 -> 4762800 | AF7: =AF5*AF6 -> 4762800 | AG7: =AG5*AG6 -> 4762800 | AH7: =AH5*AH6 -> 4762800 | AI7: =AI5*AI6 -> 4762800 | ... AM7: =AM5*AM6 -> 4762800 | AN7: =SUM(AB7:AM7) -> 57153600 | AO7: =AO5*AO6 -> 5278770 | AP7: =AP5*AP6 -> 5278770 | AQ7: =AQ5*AQ6 -> 5278770 | AR7: =AR5*AR6 -> 5278770 | AS7: =AS5*AS6 -> 5278770 | AT7: =AT5*AT6 -> 5278770 | AU7: =AU5*AU6 -> 5278770 | AV7: =AV5*AV6 -> 5278770 | ... AZ7: =AZ5*AZ6 -> 5278770 | BA7: =SUM(AO7:AZ7) -> 63345240 | BB7: =BB5*BB6 -> 5834430 | BC7: =BC5*BC6 -> 5834430 | BD7: =BD5*BD6 -> 5834430 | BE7: =BE5*BE6 -> 5834430 | BF7: =BF5*BF6 -> 5834430 | BG7: =BG5*BG6 -> 5834430 | BH7: =BH5*BH6 -> 5834430 | BI7: =BI5*BI6 -> 5834430 | ... BM7: =BM5*BM6 -> 5834430 | BN7: =SUM(BB7:BM7) -> 70013160

Sheet Expenses
A1: OPERATING EXPENSES — 60-MONTH PROJECTION
A2: Variable costs scale with production; period costs escalate annually; interest & depreciation linked.
B3: YEAR 1 | O3: YEAR 2 | AB3: YEAR 3 | AO3: YEAR 4 | BB3: YEAR 5
A4: Particulars | B4: M1 | C4: M2 | D4: M3 | E4: M4 | F4: M5 | G4: M6 | H4: M7 | I4: M8 | J4: M9 | K4: M10 | L4: M11 | M4: M12 | N4: Yr 1 Total | O4: M13 | P4: M14 | Q4: M15 | R4: M16 | S4: M17 | T4: M18 | U4: M19 | V4: M20 | W4: M21 | X4: M22 | Y4: M23 | Z4: M24 | AA4: Yr 2 Total | AB4: M25 | AC4: M26 | AD4: M27 | AE4: M28 | AF4: M29 | AG4: M30 | AH4: M31 | AI4: M32 | AJ4: M33 | AK4: M34 | AL4: M35 | AM4: M36 | AN4: Yr 3 Total | AO4: M37 | AP4: M38 | AQ4: M39 | AR4: M40 | AS4: M41 | AT4: M42 | AU4: M43 | AV4: M44 | AW4: M45 | AX4: M46 | AY4: M47 | AZ4: M48 | BA4: Yr 4 Total | BB4: M49 | BC4: M50 | BD4: M51 | BE4: M52 | BF4: M53 | BG4: M54 | BH4: M55 | BI4: M56 | BJ4: M57 | BK4: M58 | BL4: M59 | BM4: M60 | BN4: Yr 5 Total
A5: =IFERROR(VLOOKUP(Assumptions!$J$5,Assumptions!$S$5:$Z$21,5,FALSE()),"Raw materials") -> Direct delivery cost | B5: =Production!B6*(Assumptions!$C$25*(1+Assumptions!$C$26)^0) -> 960000 | C5: =Production!C6*(Assumptions!$C$25*(1+Assumptions!$C$26)^0) -> 960000 | D5: =Production!D6*(Assumptions!$C$25*(1+Assumptions!$C$26)^0) -> 960000 | E5: =Production!E6*(Assumptions!$C$25*(1+Assumptions!$C$26)^0) -> 960000 | F5: =Production!F6*(Assumptions!$C$25*(1+Assumptions!$C$26)^0) -> 960000 | G5: =Production!G6*(Assumptions!$C$25*(1+Assumptions!$C$26)^0) -> 960000 | H5: =Production!H6*(Assumptions!$C$25*(1+Assumptions!$C$26)^0) -> 960000 | I5: =Production!I6*(Assumptions!$C$25*(1+Assumptions!$C$26)^0) -> 960000 | ... M5: =Production!M6*(Assumptions!$C$25*(1+Assumptions!$C$26)^0) -> 960000 | N5: =SUM(B5:M5) -> 11520000 | O5: =Production!O6*(Assumptions!$C$25*(1+Assumptions!$C$26)^1) -> 1081200 | P5: =Production!P6*(Assumptions!$C$25*(1+Assumptions!$C$26)^1) -> 1081200 | Q5: =Production!Q6*(Assumptions!$C$25*(1+Assumptions!$C$26)^1) -> 1081200 | R5: =Production!R6*(Assumptions!$C$25*(1+Assumptions!$C$26)^1) -> 1081200 | S5: =Production!S6*(Assumptions!$C$25*(1+Assumptions!$C$26)^1) -> 1081200 | T5: =Production!T6*(Assumptions!$C$25*(1+Assumptions!$C$26)^1) -> 1081200 | U5: =Production!U6*(Assumptions!$C$25*(1+Assumptions!$C$26)^1) -> 1081200 | V5: =Production!V6*(Assumptions!$C$25*(1+Assumptions!$C$26)^1) -> 1081200 | ... Z5: =Production!Z6*(Assumptions!$C$25*(1+Assumptions!$C$26)^1) -> 1081200 | AA5: =SUM(O5:Z5) -> 12974400 | AB5: =Production!AB6*(Assumptions!$C$25*(1+Assumptions!$C$26)^2) -> 1213488 | AC5: =Production!AC6*(Assumptions!$C$25*(1+Assumptions!$C$26)^2) -> 1213488 | AD5: =Production!AD6*(Assumptions!$C$25*(1+Assumptions!$C$26)^2) -> 1213488 | AE5: =Production!AE6*(Assumptions!$C$25*(1+Assumptions!$C$26)^2) -> 1213488 | AF5: =Production!AF6*(Assumptions!$C$25*(1+Assumptions!$C$26)^2) -> 1213488 | AG5: =Production!AG6*(Assumptions!$C$25*(1+Assumptions!$C$26)^2) -> 1213488 | AH5: =Production!AH6*(Assumptions!$C$25*(1+Assumptions!$C$26)^2) -> 1213488 | AI5: =Production!AI6*(Assumptions!$C$25*(1+Assumptions!$C$26)^2) -> 1213488 | ... AM5: =Production!AM6*(Assumptions!$C$25*(1+Assumptions!$C$26)^2) -> 1213488 | AN5: =SUM(AB5:AM5) -> 14561856 | AO5: =Production!AO6*(Assumptions!$C$25*(1+Assumptions!$C$26)^3) -> 1357758.2 | AP5: =Production!AP6*(Assumptions!$C$25*(1+Assumptions!$C$26)^3) -> 1357758.2 | AQ5: =Production!AQ6*(Assumptions!$C$25*(1+Assumptions!$C$26)^3) -> 1357758.2 | AR5: =Production!AR6*(Assumptions!$C$25*(1+Assumptions!$C$26)^3) -> 1357758.2 | AS5: =Production!AS6*(Assumptions!$C$25*(1+Assumptions!$C$26)^3) -> 1357758.2 | AT5: =Production!AT6*(Assumptions!$C$25*(1+Assumptions!$C$26)^3) -> 1357758.2 | AU5: =Production!AU6*(Assumptions!$C$25*(1+Assumptions!$C$26)^3) -> 1357758.2 | AV5: =Production!AV6*(Assumptions!$C$25*(1+Assumptions!$C$26)^3) -> 1357758.2 | ... AZ5: =Production!AZ6*(Assumptions!$C$25*(1+Assumptions!$C$26)^3) -> 1357758.2 | BA5: =SUM(AO5:AZ5) -> 16293099 | BB5: =Production!BB6*(Assumptions!$C$25*(1+Assumptions!$C$26)^4) -> 1514972.4 | BC5: =Production!BC6*(Assumptions!$C$25*(1+Assumptions!$C$26)^4) -> 1514972.4 | BD5: =Production!BD6*(Assumptions!$C$25*(1+Assumptions!$C$26)^4) -> 1514972.4 | BE5: =Production!BE6*(Assumptions!$C$25*(1+Assumptions!$C$26)^4) -> 1514972.4 | BF5: =Production!BF6*(Assumptions!$C$25*(1+Assumptions!$C$26)^4) -> 1514972.4 | BG5: =Production!BG6*(Assumptions!$C$25*(1+Assumptions!$C$26)^4) -> 1514972.4 | BH5: =Production!BH6*(Assumptions!$C$25*(1+Assumptions!$C$26)^4) -> 1514972.4 | BI5: =Production!BI6*(Assumptions!$C$25*(1+Assumptions!$C$26)^4) -> 1514972.4 | ... BM5: =Production!BM6*(Assumptions!$C$25*(1+Assumptions!$C$26)^4) -> 1514972.4 | BN5: =SUM(BB5:BM5) -> 18179668
A6: =IFERROR(VLOOKUP(Assumptions!$J$5,Assumptions!$S$5:$Z$21,7,FALSE()),"Power & fuel") -> Infrastructure & hosting | B6: =Production!B6*(Assumptions!$C$27*(1+Assumptions!$C$28)^0) -> 640000 | C6: =Production!C6*(Assumptions!$C$27*(1+Assumptions!$C$28)^0) -> 640000 | D6: =Production!D6*(Assumptions!$C$27*(1+Assumptions!$C$28)^0) -> 640000 | E6: =Production!E6*(Assumptions!$C$27*(1+Assumptions!$C$28)^0) -> 640000 | F6: =Production!F6*(Assumptions!$C$27*(1+Assumptions!$C$28)^0) -> 640000 | G6: =Production!G6*(Assumptions!$C$27*(1+Assumptions!$C$28)^0) -> 640000 | H6: =Production!H6*(Assumptions!$C$27*(1+Assumptions!$C$28)^0) -> 640000 | I6: =Production!I6*(Assumptions!$C$27*(1+Assumptions!$C$28)^0) -> 640000 | ... M6: =Production!M6*(Assumptions!$C$27*(1+Assumptions!$C$28)^0) -> 640000 | N6: =SUM(B6:M6) -> 7680000 | O6: =Production!O6*(Assumptions!$C$27*(1+Assumptions!$C$28)^1) -> 714000 | P6: =Production!P6*(Assumptions!$C$27*(1+Assumptions!$C$28)^1) -> 714000 | Q6: =Production!Q6*(Assumptions!$C$27*(1+Assumptions!$C$28)^1) -> 714000 | R6: =Production!R6*(Assumptions!$C$27*(1+Assumptions!$C$28)^1) -> 714000 | S6: =Production!S6*(Assumptions!$C$27*(1+Assumptions!$C$28)^1) -> 714000 | T6: =Production!T6*(Assumptions!$C$27*(1+Assumptions!$C$28)^1) -> 714000 | U6: =Production!U6*(Assumptions!$C$27*(1+Assumptions!$C$28)^1) -> 714000 | V6: =Production!V6*(Assumptions!$C$27*(1+Assumptions!$C$28)^1) -> 714000 | ... Z6: =Production!Z6*(Assumptions!$C$27*(1+Assumptions!$C$28)^1) -> 714000 | AA6: =SUM(O6:Z6) -> 8568000 | AB6: =Production!AB6*(Assumptions!$C$27*(1+Assumptions!$C$28)^2) -> 793800 | AC6: =Production!AC6*(Assumptions!$C$27*(1+Assumptions!$C$28)^2) -> 793800 | AD6: =Production!AD6*(Assumptions!$C$27*(1+Assumptions!$C$28)^2) -> 793800 | AE6: =Production!AE6*(Assumptions!$C$27*(1+Assumptions!$C$28)^2) -> 793800 | AF6: =Production!AF6*(Assumptions!$C$27*(1+Assumptions!$C$28)^2) -> 793800 | AG6: =Production!AG6*(Assumptions!$C$27*(1+Assumptions!$C$28)^2) -> 793800 | AH6: =Production!AH6*(Assumptions!$C$27*(1+Assumptions!$C$28)^2) -> 793800 | AI6: =Production!AI6*(Assumptions!$C$27*(1+Assumptions!$C$28)^2) -> 793800 | ... AM6: =Production!AM6*(Assumptions!$C$27*(1+Assumptions!$C$28)^2) -> 793800 | AN6: =SUM(AB6:AM6) -> 9525600 | AO6: =Production!AO6*(Assumptions!$C$27*(1+Assumptions!$C$28)^3) -> 879795 | AP6: =Production!AP6*(Assumptions!$C$27*(1+Assumptions!$C$28)^3) -> 879795 | AQ6: =Production!AQ6*(Assumptions!$C$27*(1+Assumptions!$C$28)^3) -> 879795 | AR6: =Production!AR6*(Assumptions!$C$27*(1+Assumptions!$C$28)^3) -> 879795 | AS6: =Production!AS6*(Assumptions!$C$27*(1+Assumptions!$C$28)^3) -> 879795 | AT6: =Production!AT6*(Assumptions!$C$27*(1+Assumptions!$C$28)^3) -> 879795 | AU6: =Production!AU6*(Assumptions!$C$27*(1+Assumptions!$C$28)^3) -> 879795 | AV6: =Production!AV6*(Assumptions!$C$27*(1+Assumptions!$C$28)^3) -> 879795 | ... AZ6: =Production!AZ6*(Assumptions!$C$27*(1+Assumptions!$C$28)^3) -> 879795 | BA6: =SUM(AO6:AZ6) -> 10557540 | BB6: =Production!BB6*(Assumptions!$C$27*(1+Assumptions!$C$28)^4) -> 972405 | BC6: =Production!BC6*(Assumptions!$C$27*(1+Assumptions!$C$28)^4) -> 972405 | BD6: =Production!BD6*(Assumptions!$C$27*(1+Assumptions!$C$28)^4) -> 972405 | BE6: =Production!BE6*(Assumptions!$C$27*(1+Assumptions!$C$28)^4) -> 972405 | BF6: =Production!BF6*(Assumptions!$C$27*(1+Assumptions!$C$28)^4) -> 972405 | BG6: =Production!BG6*(Assumptions!$C$27*(1+Assumptions!$C$28)^4) -> 972405 | BH6: =Production!BH6*(Assumptions!$C$27*(1+Assumptions!$C$28)^4) -> 972405 | BI6: =Production!BI6*(Assumptions!$C$27*(1+Assumptions!$C$28)^4) -> 972405 | ... BM6: =Production!BM6*(Assumptions!$C$27*(1+Assumptions!$C$28)^4) -> 972405 | BN6: =SUM(BB6:BM6) -> 11668860
A7: Direct wages & salaries | B7: =Assumptions!$C$32*(1+Assumptions!$C$33)^0 -> 400000 | C7: =Assumptions!$C$32*(1+Assumptions!$C$33)^0 -> 400000 | D7: =Assumptions!$C$32*(1+Assumptions!$C$33)^0 -> 400000 | E7: =Assumptions!$C$32*(1+Assumptions!$C$33)^0 -> 400000 | F7: =Assumptions!$C$32*(1+Assumptions!$C$33)^0 -> 400000 | G7: =Assumptions!$C$32*(1+Assumptions!$C$33)^0 -> 400000 | H7: =Assumptions!$C$32*(1+Assumptions!$C$33)^0 -> 400000 | I7: =Assumptions!$C$32*(1+Assumptions!$C$33)^0 -> 400000 | ... M7: =Assumptions!$C$32*(1+Assumptions!$C$33)^0 -> 400000 | N7: =SUM(B7:M7) -> 4800000 | O7: =Assumptions!$C$32*(1+Assumptions!$C$33)^1 -> 428000 | P7: =Assumptions!$C$32*(1+Assumptions!$C$33)^1 -> 428000 | Q7: =Assumptions!$C$32*(1+Assumptions!$C$33)^1 -> 428000 | R7: =Assumptions!$C$32*(1+Assumptions!$C$33)^1 -> 428000 | S7: =Assumptions!$C$32*(1+Assumptions!$C$33)^1 -> 428000 | T7: =Assumptions!$C$32*(1+Assumptions!$C$33)^1 -> 428000 | U7: =Assumptions!$C$32*(1+Assumptions!$C$33)^1 -> 428000 | V7: =Assumptions!$C$32*(1+Assumptions!$C$33)^1 -> 428000 | ... Z7: =Assumptions!$C$32*(1+Assumptions!$C$33)^1 -> 428000 | AA7: =SUM(O7:Z7) -> 5136000 | AB7: =Assumptions!$C$32*(1+Assumptions!$C$33)^2 -> 457960 | AC7: =Assumptions!$C$32*(1+Assumptions!$C$33)^2 -> 457960 | AD7: =Assumptions!$C$32*(1+Assumptions!$C$33)^2 -> 457960 | AE7: =Assumptions!$C$32*(1+Assumptions!$C$33)^2 -> 457960 | AF7: =Assumptions!$C$32*(1+Assumptions!$C$33)^2 -> 457960 | AG7: =Assumptions!$C$32*(1+Assumptions!$C$33)^2 -> 457960 | AH7: =Assumptions!$C$32*(1+Assumptions!$C$33)^2 -> 457960 | AI7: =Assumptions!$C$32*(1+Assumptions!$C$33)^2 -> 457960 | ... AM7: =Assumptions!$C$32*(1+Assumptions!$C$33)^2 -> 457960 | AN7: =SUM(AB7:AM7) -> 5495520 | AO7: =Assumptions!$C$32*(1+Assumptions!$C$33)^3 -> 490017.2 | AP7: =Assumptions!$C$32*(1+Assumptions!$C$33)^3 -> 490017.2 | AQ7: =Assumptions!$C$32*(1+Assumptions!$C$33)^3 -> 490017.2 | AR7: =Assumptions!$C$32*(1+Assumptions!$C$33)^3 -> 490017.2 | AS7: =Assumptions!$C$32*(1+Assumptions!$C$33)^3 -> 490017.2 | AT7: =Assumptions!$C$32*(1+Assumptions!$C$33)^3 -> 490017.2 | AU7: =Assumptions!$C$32*(1+Assumptions!$C$33)^3 -> 490017.2 | AV7: =Assumptions!$C$32*(1+Assumptions!$C$33)^3 -> 490017.2 | ... AZ7: =Assumptions!$C$32*(1+Assumptions!$C$33)^3 -> 490017.2 | BA7: =SUM(AO7:AZ7) -> 5880206.4 | BB7: =Assumptions!$C$32*(1+Assumptions!$C$33)^4 -> 524318.4 | BC7: =Assumptions!$C$32*(1+Assumptions!$C$33)^4 -> 524318.4 | BD7: =Assumptions!$C$32*(1+Assumptions!$C$33)^4 -> 524318.4 | BE7: =Assumptions!$C$32*(1+Assumptions!$C$33)^4 -> 524318.4 | BF7: =Assumptions!$C$32*(1+Assumptions!$C$33)^4 -> 524318.4 | BG7: =Assumptions!$C$32*(1+Assumptions!$C$33)^4 -> 524318.4 | BH7: =Assumptions!$C$32*(1+Assumptions!$C$33)^4 -> 524318.4 | BI7: =Assumptions!$C$32*(1+Assumptions!$C$33)^4 -> 524318.4 | ... BM7: =Assumptions!$C$32*(1+Assumptions!$C$33)^4 -> 524318.4 | BN7: =SUM(BB7:BM7) -> 6291820.8
A8: Other variable cost | B8: =Production!B6*(Assumptions!$C$29*(1+Assumptions!$C$30)^0) -> 320000 | C8: =Production!C6*(Assumptions!$C$29*(1+Assumptions!$C$30)^0) -> 320000 | D8: =Production!D6*(Assumptions!$C$29*(1+Assumptions!$C$30)^0) -> 320000 | E8: =Production!E6*(Assumptions!$C$29*(1+Assumptions!$C$30)^0) -> 320000 | F8: =Production!F6*(Assumptions!$C$29*(1+Assumptions!$C$30)^0) -> 320000 | G8: =Production!G6*(Assumptions!$C$29*(1+Assumptions!$C$30)^0) -> 320000 | H8: =Production!H6*(Assumptions!$C$29*(1+Assumptions!$C$30)^0) -> 320000 | I8: =Production!I6*(Assumptions!$C$29*(1+Assumptions!$C$30)^0) -> 320000 | ... M8: =Production!M6*(Assumptions!$C$29*(1+Assumptions!$C$30)^0) -> 320000 | N8: =SUM(B8:M8) -> 3840000 | O8: =Production!O6*(Assumptions!$C$29*(1+Assumptions!$C$30)^1) -> 353600 | P8: =Production!P6*(Assumptions!$C$29*(1+Assumptions!$C$30)^1) -> 353600 | Q8: =Production!Q6*(Assumptions!$C$29*(1+Assumptions!$C$30)^1) -> 353600 | R8: =Production!R6*(Assumptions!$C$29*(1+Assumptions!$C$30)^1) -> 353600 | S8: =Production!S6*(Assumptions!$C$29*(1+Assumptions!$C$30)^1) -> 353600 | T8: =Production!T6*(Assumptions!$C$29*(1+Assumptions!$C$30)^1) -> 353600 | U8: =Production!U6*(Assumptions!$C$29*(1+Assumptions!$C$30)^1) -> 353600 | V8: =Production!V6*(Assumptions!$C$29*(1+Assumptions!$C$30)^1) -> 353600 | ... Z8: =Production!Z6*(Assumptions!$C$29*(1+Assumptions!$C$30)^1) -> 353600 | AA8: =SUM(O8:Z8) -> 4243200 | AB8: =Production!AB6*(Assumptions!$C$29*(1+Assumptions!$C$30)^2) -> 389376 | AC8: =Production!AC6*(Assumptions!$C$29*(1+Assumptions!$C$30)^2) -> 389376 | AD8: =Production!AD6*(Assumptions!$C$29*(1+Assumptions!$C$30)^2) -> 389376 | AE8: =Production!AE6*(Assumptions!$C$29*(1+Assumptions!$C$30)^2) -> 389376 | AF8: =Production!AF6*(Assumptions!$C$29*(1+Assumptions!$C$30)^2) -> 389376 | AG8: =Production!AG6*(Assumptions!$C$29*(1+Assumptions!$C$30)^2) -> 389376 | AH8: =Production!AH6*(Assumptions!$C$29*(1+Assumptions!$C$30)^2) -> 389376 | AI8: =Production!AI6*(Assumptions!$C$29*(1+Assumptions!$C$30)^2) -> 389376 | ... AM8: =Production!AM6*(Assumptions!$C$29*(1+Assumptions!$C$30)^2) -> 389376 | AN8: =SUM(AB8:AM8) -> 4672512 | AO8: =Production!AO6*(Assumptions!$C$29*(1+Assumptions!$C$30)^3) -> 427448.32 | AP8: =Production!AP6*(Assumptions!$C$29*(1+Assumptions!$C$30)^3) -> 427448.32 | AQ8: =Production!AQ6*(Assumptions!$C$29*(1+Assumptions!$C$30)^3) -> 427448.32 | AR8: =Production!AR6*(Assumptions!$C$29*(1+Assumptions!$C$30)^3) -> 427448.32 | AS8: =Production!AS6*(Assumptions!$C$29*(1+Assumptions!$C$30)^3) -> 427448.32 | AT8: =Production!AT6*(Assumptions!$C$29*(1+Assumptions!$C$30)^3) -> 427448.32 | AU8: =Production!AU6*(Assumptions!$C$29*(1+Assumptions!$C$30)^3) -> 427448.32 | AV8: =Production!AV6*(Assumptions!$C$29*(1+Assumptions!$C$30)^3) -> 427448.32 | ... AZ8: =Production!AZ6*(Assumptions!$C$29*(1+Assumptions!$C$30)^3) -> 427448.32 | BA8: =SUM(AO8:AZ8) -> 5129379.8 | BB8: =Production!BB6*(Assumptions!$C$29*(1+Assumptions!$C$30)^4) -> 467943.42 | BC8: =Production!BC6*(Assumptions!$C$29*(1+Assumptions!$C$30)^4) -> 467943.42 | BD8: =Production!BD6*(Assumptions!$C$29*(1+Assumptions!$C$30)^4) -> 467943.42 | BE8: =Production!BE6*(Assumptions!$C$29*(1+Assumptions!$C$30)^4) -> 467943.42 | BF8: =Production!BF6*(Assumptions!$C$29*(1+Assumptions!$C$30)^4) -> 467943.42 | BG8: =Production!BG6*(Assumptions!$C$29*(1+Assumptions!$C$30)^4) -> 467943.42 | BH8: =Production!BH6*(Assumptions!$C$29*(1+Assumptions!$C$30)^4) -> 467943.42 | BI8: =Production!BI6*(Assumptions!$C$29*(1+Assumptions!$C$30)^4) -> 467943.42 | ... BM8: =Production!BM6*(Assumptions!$C$29*(1+Assumptions!$C$30)^4) -> 467943.42 | BN8: =SUM(BB8:BM8) -> 5615321.1
A9: =IFERROR(VLOOKUP(Assumptions!$J$5,Assumptions!$S$5:$Z$21,8,FALSE()),"Factory overheads") -> Operating overheads | B9: =Assumptions!$C$34*(1+Assumptions!$C$35)^0 -> 100000 | C9: =Assumptions!$C$34*(1+Assumptions!$C$35)^0 -> 100000 | D9: =Assumptions!$C$34*(1+Assumptions!$C$35)^0 -> 100000 | E9: =Assumptions!$C$34*(1+Assumptions!$C$35)^0 -> 100000 | F9: =Assumptions!$C$34*(1+Assumptions!$C$35)^0 -> 100000 | G9: =Assumptions!$C$34*(1+Assumptions!$C$35)^0 -> 100000 | H9: =Assumptions!$C$34*(1+Assumptions!$C$35)^0 -> 100000 | I9: =Assumptions!$C$34*(1+Assumptions!$C$35)^0 -> 100000 | ... M9: =Assumptions!$C$34*(1+Assumptions!$C$35)^0 -> 100000 | N9: =SUM(B9:M9) -> 1200000 | O9: =Assumptions!$C$34*(1+Assumptions!$C$35)^1 -> 105000 | P9: =Assumptions!$C$34*(1+Assumptions!$C$35)^1 -> 105000 | Q9: =Assumptions!$C$34*(1+Assumptions!$C$35)^1 -> 105000 | R9: =Assumptions!$C$34*(1+Assumptions!$C$35)^1 -> 105000 | S9: =Assumptions!$C$34*(1+Assumptions!$C$35)^1 -> 105000 | T9: =Assumptions!$C$34*(1+Assumptions!$C$35)^1 -> 105000 | U9: =Assumptions!$C$34*(1+Assumptions!$C$35)^1 -> 105000 | V9: =Assumptions!$C$34*(1+Assumptions!$C$35)^1 -> 105000 | ... Z9: =Assumptions!$C$34*(1+Assumptions!$C$35)^1 -> 105000 | AA9: =SUM(O9:Z9) -> 1260000 | AB9: =Assumptions!$C$34*(1+Assumptions!$C$35)^2 -> 110250 | AC9: =Assumptions!$C$34*(1+Assumptions!$C$35)^2 -> 110250 | AD9: =Assumptions!$C$34*(1+Assumptions!$C$35)^2 -> 110250 | AE9: =Assumptions!$C$34*(1+Assumptions!$C$35)^2 -> 110250 | AF9: =Assumptions!$C$34*(1+Assumptions!$C$35)^2 -> 110250 | AG9: =Assumptions!$C$34*(1+Assumptions!$C$35)^2 -> 110250 | AH9: =Assumptions!$C$34*(1+Assumptions!$C$35)^2 -> 110250 | AI9: =Assumptions!$C$34*(1+Assumptions!$C$35)^2 -> 110250 | ... AM9: =Assumptions!$C$34*(1+Assumptions!$C$35)^2 -> 110250 | AN9: =SUM(AB9:AM9) -> 1323000 | AO9: =Assumptions!$C$34*(1+Assumptions!$C$35)^3 -> 115762.5 | AP9: =Assumptions!$C$34*(1+Assumptions!$C$35)^3 -> 115762.5 | AQ9: =Assumptions!$C$34*(1+Assumptions!$C$35)^3 -> 115762.5 | AR9: =Assumptions!$C$34*(1+Assumptions!$C$35)^3 -> 115762.5 | AS9: =Assumptions!$C$34*(1+Assumptions!$C$35)^3 -> 115762.5 | AT9: =Assumptions!$C$34*(1+Assumptions!$C$35)^3 -> 115762.5 | AU9: =Assumptions!$C$34*(1+Assumptions!$C$35)^3 -> 115762.5 | AV9: =Assumptions!$C$34*(1+Assumptions!$C$35)^3 -> 115762.5 | ... AZ9: =Assumptions!$C$34*(1+Assumptions!$C$35)^3 -> 115762.5 | BA9: =SUM(AO9:AZ9) -> 1389150 | BB9: =Assumptions!$C$34*(1+Assumptions!$C$35)^4 -> 121550.62 | BC9: =Assumptions!$C$34*(1+Assumptions!$C$35)^4 -> 121550.62 | BD9: =Assumptions!$C$34*(1+Assumptions!$C$35)^4 -> 121550.62 | BE9: =Assumptions!$C$34*(1+Assumptions!$C$35)^4 -> 121550.62 | BF9: =Assumptions!$C$34*(1+Assumptions!$C$35)^4 -> 121550.62 | BG9: =Assumptions!$C$34*(1+Assumptions!$C$35)^4 -> 121550.62 | BH9: =Assumptions!$C$34*(1+Assumptions!$C$35)^4 -> 121550.62 | BI9: =Assumptions!$C$34*(1+Assumptions!$C$35)^4 -> 121550.62 | ... BM9: =Assumptions!$C$34*(1+Assumptions!$C$35)^4 -> 121550.62 | BN9: =SUM(BB9:BM9) -> 1458607.5
A10: Repairs & maintenance | B10: =Assumptions!$C$36*(1+Assumptions!$C$37)^0 -> 20000 | C10: =Assumptions!$C$36*(1+Assumptions!$C$37)^0 -> 20000 | D10: =Assumptions!$C$36*(1+Assumptions!$C$37)^0 -> 20000 | E10: =Assumptions!$C$36*(1+Assumptions!$C$37)^0 -> 20000 | F10: =Assumptions!$C$36*(1+Assumptions!$C$37)^0 -> 20000 | G10: =Assumptions!$C$36*(1+Assumptions!$C$37)^0 -> 20000 | H10: =Assumptions!$C$36*(1+Assumptions!$C$37)^0 -> 20000 | I10: =Assumptions!$C$36*(1+Assumptions!$C$37)^0 -> 20000 | ... M10: =Assumptions!$C$36*(1+Assumptions!$C$37)^0 -> 20000 | N10: =SUM(B10:M10) -> 240000 | O10: =Assumptions!$C$36*(1+Assumptions!$C$37)^1 -> 20800 | P10: =Assumptions!$C$36*(1+Assumptions!$C$37)^1 -> 20800 | Q10: =Assumptions!$C$36*(1+Assumptions!$C$37)^1 -> 20800 | R10: =Assumptions!$C$36*(1+Assumptions!$C$37)^1 -> 20800 | S10: =Assumptions!$C$36*(1+Assumptions!$C$37)^1 -> 20800 | T10: =Assumptions!$C$36*(1+Assumptions!$C$37)^1 -> 20800 | U10: =Assumptions!$C$36*(1+Assumptions!$C$37)^1 -> 20800 | V10: =Assumptions!$C$36*(1+Assumptions!$C$37)^1 -> 20800 | ... Z10: =Assumptions!$C$36*(1+Assumptions!$C$37)^1 -> 20800 | AA10: =SUM(O10:Z10) -> 249600 | AB10: =Assumptions!$C$36*(1+Assumptions!$C$37)^2 -> 21632 | AC10: =Assumptions!$C$36*(1+Assumptions!$C$37)^2 -> 21632 | AD10: =Assumptions!$C$36*(1+Assumptions!$C$37)^2 -> 21632 | AE10: =Assumptions!$C$36*(1+Assumptions!$C$37)^2 -> 21632 | AF10: =Assumptions!$C$36*(1+Assumptions!$C$37)^2 -> 21632 | AG10: =Assumptions!$C$36*(1+Assumptions!$C$37)^2 -> 21632 | AH10: =Assumptions!$C$36*(1+Assumptions!$C$37)^2 -> 21632 | AI10: =Assumptions!$C$36*(1+Assumptions!$C$37)^2 -> 21632 | ... AM10: =Assumptions!$C$36*(1+Assumptions!$C$37)^2 -> 21632 | AN10: =SUM(AB10:AM10) -> 259584 | AO10: =Assumptions!$C$36*(1+Assumptions!$C$37)^3 -> 22497.28 | AP10: =Assumptions!$C$36*(1+Assumptions!$C$37)^3 -> 22497.28 | AQ10: =Assumptions!$C$36*(1+Assumptions!$C$37)^3 -> 22497.28 | AR10: =Assumptions!$C$36*(1+Assumptions!$C$37)^3 -> 22497.28 | AS10: =Assumptions!$C$36*(1+Assumptions!$C$37)^3 -> 22497.28 | AT10: =Assumptions!$C$36*(1+Assumptions!$C$37)^3 -> 22497.28 | AU10: =Assumptions!$C$36*(1+Assumptions!$C$37)^3 -> 22497.28 | AV10: =Assumptions!$C$36*(1+Assumptions!$C$37)^3 -> 22497.28 | ... AZ10: =Assumptions!$C$36*(1+Assumptions!$C$37)^3 -> 22497.28 | BA10: =SUM(AO10:AZ10) -> 269967.36 | BB10: =Assumptions!$C$36*(1+Assumptions!$C$37)^4 -> 23397.171 | BC10: =Assumptions!$C$36*(1+Assumptions!$C$37)^4 -> 23397.171 | BD10: =Assumptions!$C$36*(1+Assumptions!$C$37)^4 -> 23397.171 | BE10: =Assumptions!$C$36*(1+Assumptions!$C$37)^4 -> 23397.171 | BF10: =Assumptions!$C$36*(1+Assumptions!$C$37)^4 -> 23397.171 | BG10: =Assumptions!$C$36*(1+Assumptions!$C$37)^4 -> 23397.171 | BH10: =Assumptions!$C$36*(1+Assumptions!$C$37)^4 -> 23397.171 | BI10: =Assumptions!$C$36*(1+Assumptions!$C$37)^4 -> 23397.171 | ... BM10: =Assumptions!$C$36*(1+Assumptions!$C$37)^4 -> 23397.171 | BN10: =SUM(BB10:BM10) -> 280766.05
A11: Administrative expenses | B11: =Assumptions!$C$38*(1+Assumptions!$C$39)^0 -> 50000 | C11: =Assumptions!$C$38*(1+Assumptions!$C$39)^0 -> 50000 | D11: =Assumptions!$C$38*(1+Assumptions!$C$39)^0 -> 50000 | E11: =Assumptions!$C$38*(1+Assumptions!$C$39)^0 -> 50000 | F11: =Assumptions!$C$38*(1+Assumptions!$C$39)^0 -> 50000 | G11: =Assumptions!$C$38*(1+Assumptions!$C$39)^0 -> 50000 | H11: =Assumptions!$C$38*(1+Assumptions!$C$39)^0 -> 50000 | I11: =Assumptions!$C$38*(1+Assumptions!$C$39)^0 -> 50000 | ... M11: =Assumptions!$C$38*(1+Assumptions!$C$39)^0 -> 50000 | N11: =SUM(B11:M11) -> 600000 | O11: =Assumptions!$C$38*(1+Assumptions!$C$39)^1 -> 52500 | P11: =Assumptions!$C$38*(1+Assumptions!$C$39)^1 -> 52500 | Q11: =Assumptions!$C$38*(1+Assumptions!$C$39)^1 -> 52500 | R11: =Assumptions!$C$38*(1+Assumptions!$C$39)^1 -> 52500 | S11: =Assumptions!$C$38*(1+Assumptions!$C$39)^1 -> 52500 | T11: =Assumptions!$C$38*(1+Assumptions!$C$39)^1 -> 52500 | U11: =Assumptions!$C$38*(1+Assumptions!$C$39)^1 -> 52500 | V11: =Assumptions!$C$38*(1+Assumptions!$C$39)^1 -> 52500 | ... Z11: =Assumptions!$C$38*(1+Assumptions!$C$39)^1 -> 52500 | AA11: =SUM(O11:Z11) -> 630000 | AB11: =Assumptions!$C$38*(1+Assumptions!$C$39)^2 -> 55125 | AC11: =Assumptions!$C$38*(1+Assumptions!$C$39)^2 -> 55125 | AD11: =Assumptions!$C$38*(1+Assumptions!$C$39)^2 -> 55125 | AE11: =Assumptions!$C$38*(1+Assumptions!$C$39)^2 -> 55125 | AF11: =Assumptions!$C$38*(1+Assumptions!$C$39)^2 -> 55125 | AG11: =Assumptions!$C$38*(1+Assumptions!$C$39)^2 -> 55125 | AH11: =Assumptions!$C$38*(1+Assumptions!$C$39)^2 -> 55125 | AI11: =Assumptions!$C$38*(1+Assumptions!$C$39)^2 -> 55125 | ... AM11: =Assumptions!$C$38*(1+Assumptions!$C$39)^2 -> 55125 | AN11: =SUM(AB11:AM11) -> 661500 | AO11: =Assumptions!$C$38*(1+Assumptions!$C$39)^3 -> 57881.25 | AP11: =Assumptions!$C$38*(1+Assumptions!$C$39)^3 -> 57881.25 | AQ11: =Assumptions!$C$38*(1+Assumptions!$C$39)^3 -> 57881.25 | AR11: =Assumptions!$C$38*(1+Assumptions!$C$39)^3 -> 57881.25 | AS11: =Assumptions!$C$38*(1+Assumptions!$C$39)^3 -> 57881.25 | AT11: =Assumptions!$C$38*(1+Assumptions!$C$39)^3 -> 57881.25 | AU11: =Assumptions!$C$38*(1+Assumptions!$C$39)^3 -> 57881.25 | AV11: =Assumptions!$C$38*(1+Assumptions!$C$39)^3 -> 57881.25 | ... AZ11: =Assumptions!$C$38*(1+Assumptions!$C$39)^3 -> 57881.25 | BA11: =SUM(AO11:AZ11) -> 694575 | BB11: =Assumptions!$C$38*(1+Assumptions!$C$39)^4 -> 60775.312 | BC11: =Assumptions!$C$38*(1+Assumptions!$C$39)^4 -> 60775.312 | BD11: =Assumptions!$C$38*(1+Assumptions!$C$39)^4 -> 60775.312 | BE11: =Assumptions!$C$38*(1+Assumptions!$C$39)^4 -> 60775.312 | BF11: =Assumptions!$C$38*(1+Assumptions!$C$39)^4 -> 60775.312 | BG11: =Assumptions!$C$38*(1+Assumptions!$C$39)^4 -> 60775.312 | BH11: =Assumptions!$C$38*(1+Assumptions!$C$39)^4 -> 60775.312 | BI11: =Assumptions!$C$38*(1+Assumptions!$C$39)^4 -> 60775.312 | ... BM11: =Assumptions!$C$38*(1+Assumptions!$C$39)^4 -> 60775.312 | BN11: =SUM(BB11:BM11) -> 729303.75
A12: Selling & distribution | B12: =Sales!B7*Assumptions!$C$40 -> 192000 | C12: =Sales!C7*Assumptions!$C$40 -> 192000 | D12: =Sales!D7*Assumptions!$C$40 -> 192000 | E12: =Sales!E7*Assumptions!$C$40 -> 192000 | F12: =Sales!F7*Assumptions!$C$40 -> 192000 | G12: =Sales!G7*Assumptions!$C$40 -> 192000 | H12: =Sales!H7*Assumptions!$C$40 -> 192000 | I12: =Sales!I7*Assumptions!$C$40 -> 192000 | ... M12: =Sales!M7*Assumptions!$C$40 -> 192000 | N12: =SUM(B12:M12) -> 2304000 | O12: =Sales!O7*Assumptions!$C$40 -> 214200 | P12: =Sales!P7*Assumptions!$C$40 -> 214200 | Q12: =Sales!Q7*Assumptions!$C$40 -> 214200 | R12: =Sales!R7*Assumptions!$C$40 -> 214200 | S12: =Sales!S7*Assumptions!$C$40 -> 214200 | T12: =Sales!T7*Assumptions!$C$40 -> 214200 | U12: =Sales!U7*Assumptions!$C$40 -> 214200 | V12: =Sales!V7*Assumptions!$C$40 -> 214200 | ... Z12: =Sales!Z7*Assumptions!$C$40 -> 214200 | AA12: =SUM(O12:Z12) -> 2570400 | AB12: =Sales!AB7*Assumptions!$C$40 -> 238140 | AC12: =Sales!AC7*Assumptions!$C$40 -> 238140 | AD12: =Sales!AD7*Assumptions!$C$40 -> 238140 | AE12: =Sales!AE7*Assumptions!$C$40 -> 238140 | AF12: =Sales!AF7*Assumptions!$C$40 -> 238140 | AG12: =Sales!AG7*Assumptions!$C$40 -> 238140 | AH12: =Sales!AH7*Assumptions!$C$40 -> 238140 | AI12: =Sales!AI7*Assumptions!$C$40 -> 238140 | ... AM12: =Sales!AM7*Assumptions!$C$40 -> 238140 | AN12: =SUM(AB12:AM12) -> 2857680 | AO12: =Sales!AO7*Assumptions!$C$40 -> 263938.5 | AP12: =Sales!AP7*Assumptions!$C$40 -> 263938.5 | AQ12: =Sales!AQ7*Assumptions!$C$40 -> 263938.5 | AR12: =Sales!AR7*Assumptions!$C$40 -> 263938.5 | AS12: =Sales!AS7*Assumptions!$C$40 -> 263938.5 | AT12: =Sales!AT7*Assumptions!$C$40 -> 263938.5 | AU12: =Sales!AU7*Assumptions!$C$40 -> 263938.5 | AV12: =Sales!AV7*Assumptions!$C$40 -> 263938.5 | ... AZ12: =Sales!AZ7*Assumptions!$C$40 -> 263938.5 | BA12: =SUM(AO12:AZ12) -> 3167262 | BB12: =Sales!BB7*Assumptions!$C$40 -> 291721.5 | BC12: =Sales!BC7*Assumptions!$C$40 -> 291721.5 | BD12: =Sales!BD7*Assumptions!$C$40 -> 291721.5 | BE12: =Sales!BE7*Assumptions!$C$40 -> 291721.5 | BF12: =Sales!BF7*Assumptions!$C$40 -> 291721.5 | BG12: =Sales!BG7*Assumptions!$C$40 -> 291721.5 | BH12: =Sales!BH7*Assumptions!$C$40 -> 291721.5 | BI12: =Sales!BI7*Assumptions!$C$40 -> 291721.5 | ... BM12: =Sales!BM7*Assumptions!$C$40 -> 291721.5 | BN12: =SUM(BB12:BM12) -> 3500658
