Workbook

Sheet Cover
B2: CREDIT MONITORING ARRANGEMENT (CMA) REPORT
B3: Projected Financials for Bank Term-Loan & Working-Capital Appraisal
B5: Name of the Unit | C5: =Assumptions!C5 -> Plastic Packaging Containers Unit
B6: Constitution | C6: =Assumptions!C6 -> Proprietorship
B7: Line of Activity | C7: =Assumptions!C7 -> Manufacturing of plastic packaging containers for FMCG companies
B8: Term Loan applied for (₹) | C8: =Assumptions!C8 -> 6000000
B9: Promoters' Capital (₹) | C9: =Assumptions!C9 -> 1500000
B10: Projection horizon | C10: 5 years (60 months), monthly
B12: CONTENTS
B13: Assumptions | C13: All input variables — the single control panel for the model
B14: Production | C14: 60-month production plan (capacity × utilisation × phasing)
B15: Sales | C15: 60-month sales quantity, price and revenue
B16: Expenses | C16: 60-month operating expenses, interest and depreciation
B17: Profit | C17: 60-month P&L: EBITDA → EBIT → PBT → PAT
B18: Annual_Summary | C18: Consolidated 5-year figures feeding the CMA forms
B19: Form_II_Operating | C19: Form II — Operating statement (profitability)
B20: Form_III_BalanceSheet | C20: Form III — Projected balance sheet
B21: Form_IV_CA_CL | C21: Form IV — Current assets & current liabilities
B22: Form_V_MPBF | C22: Form V — Maximum permissible bank finance
B23: Form_VI_FundFlow | C23: Form VI — Fund-flow statement
B24: Repayment | C24: Term-loan repayment schedule
... B26: Ratios | C26: Key ratios — financial viability
B28: Enter data only in the blue cells on the Assumptions sheet; all other sheets recalculate automatically.

Sheet Assumptions
A1: ASSUMPTIONS — KEY INPUTS
A2: Enter values only in the blue/shaded cells. Every other sheet updates automatically.
B4: A. COMPANY & LOAN PARTICULARS | S4: Industry | T4: CapLabel | U4: ProdUnitLabel | V4: Cost1Long | W4: Cost1Short | X4: Cost2Long | Y4: Cost2Short | Z4: Cost3Short
B5: Name of the Unit | C5: Plastic Packaging Containers Unit | I5: INDUSTRY / BUSINESS TYPE → | J5: Manufacturing | S5: Agriculture & Farming | T5: Installed Capacity (land / livestock / output) | U5: Production (units) | V5: Raw material / input cost per unit (Year 1) | W5: Raw materials / inputs | X5: Power & fuel cost per unit (Year 1) | Y5: Power & fuel | Z5: Farm overheads
B6: Constitution (Proprietor / Partnership / Pvt Ltd) | C6: Proprietorship | S6: Technology & Software | T6: Service Delivery Capacity (billable hours/licenses p.a.) | U6: Service delivery (units) | V6: Direct delivery cost per unit (Year 1) | W6: Direct delivery cost | X6: Infrastructure & hosting cost per unit (Year 1) | Y6: Infrastructure & hosting | Z6: Operating overheads
B7: Line of Activity / Product | C7: Manufacturing of plastic packaging containers for FMCG companies | S7: Retail & E-Commerce | T7: Annual Purchase Capacity (units for resale) | U7: Purchase (units) | V7: Purchase cost of goods per unit (Year 1) | W7: Purchase cost of goods | X7: Freight & packaging cost per unit (Year 1) | Y7: Freight & packaging | Z7: Store overheads
B8: Term Loan applied for | C8: 6000000 | H8: ₹ | S8: Manufacturing | T8: Installed Capacity | U8: Production (units) | V8: Raw material cost per unit (Year 1) | W8: Raw materials | X8: Power & fuel cost per unit (Year 1) | Y8: Power & fuel | Z8: Factory overheads
B9: Promoters' Capital / Equity brought in | C9: 1500000 | H9: ₹ | S9: Tourism & Hospitality | T9: Room / Cover Capacity (room-nights or covers p.a.) | U9: Rooms sold / covers served (units) | V9: Direct service cost per unit (F&B, housekeeping) (Year 1) | W9: Direct service cost | X9: Power & fuel cost per unit (Year 1) | Y9: Power & fuel | Z9: Property overheads
B10: Interest rate on Term Loan | C10: 0.105 | H10: % p.a. | S10: Renewable Energy | T10: Installed Generation Capacity (units of energy p.a.) | U10: Energy generated (units) | V10: O&M cost per unit generated (Year 1) | W10: O&M cost | X10: Grid / power evacuation cost per unit (Year 1) | Y10: Grid / evacuation cost | Z10: Plant overheads
B11: Term Loan tenure | C11: 60 | H11: years | S11: Healthcare & Pharma | T11: Service / Production Capacity (patients or units p.a.) | U11: Patients served / units produced | V11: Consumables & medicine cost per unit (Year 1) | W11: Consumables & medicine | X11: Power & equipment running cost per unit (Year 1) | Y11: Power & equipment cost | Z11: Facility overheads
B12: Moratorium / holiday period | C12: 6 | H12: months | S12: Education & Training | T12: Service Capacity (student seats / batches p.a.) | U12: Students / batches served | V12: Direct delivery cost per unit (faculty, material) (Year 1) | W12: Direct delivery cost | X12: Infrastructure cost per unit (Year 1) | Y12: Infrastructure cost | Z12: Institute overheads
B13: Interest rate on Working Capital | C13: 0.12 | H13: % p.a. | S13: General Business | T13: Capacity (units / customers / hours p.a.) | U13: Output (units) | V13: Direct cost per unit (Year 1) | W13: Direct cost | X13: Overhead cost per unit (Year 1) | Y13: Overhead cost | Z13: Operating overheads
B14: Income Tax rate | C14: 0.25 | H14: % | S14: Construction & Real Estate | T14: Project Execution Capacity (sq.ft / units p.a.) | U14: Construction / units completed | V14: Construction material cost per unit (Year 1) | W14: Construction materials | X14: Site power & machinery cost per unit (Year 1) | Y14: Site power & machinery | Z14: Project overheads
B15: B. CAPACITY & PRODUCTION | S15: Food & Beverage / Restaurant | T15: Seating / Covers Capacity (covers p.a.) | U15: Covers served (units) | V15: Raw material (food & beverage) cost per unit (Year 1) | W15: Food & beverage cost | X15: Kitchen power & fuel cost per unit (Year 1) | Y15: Kitchen power & fuel | Z15: Restaurant overheads
B16: =IFERROR(VLOOKUP($J$5,$S$5:$Z$21,2,FALSE()),"Installed Capacity") -> Installed Capacity | C16: 12000000 | H16: units p.a. | S16: Transportation & Logistics | T16: Fleet / Route Capacity (trips or tonnage p.a.) | U16: Trips / tonnage handled (units) | V16: Fuel & running cost per unit (Year 1) | W16: Fuel & running cost | X16: Vehicle maintenance cost per unit (Year 1) | Y16: Vehicle maintenance | Z16: Fleet overheads
B17: Capacity Utilisation | C17: Yr 1 | D17: Yr 2 | E17: Yr 3 | F17: Yr 4 | G17: Yr 5 | S17: Textile & Garments | T17: Installed Capacity (garments/fabric units p.a.) | U17: Production (units) | V17: Raw material (yarn/fabric) cost per unit (Year 1) | W17: Raw materials (yarn/fabric) | X17: Power & fuel cost per unit (Year 1) | Y17: Power & fuel | Z17: Factory overheads
B18: → enter % for Year 1 … 5 | C18: 0.6 | D18: 0.65 | E18: 0.7 | F18: 0.75 | G18: 0.8 | H18: % | S18: Automobile / Auto Ancillary | T18: Installed Capacity (components/vehicles p.a.) | U18: Production (units) | V18: Raw material / component cost per unit (Year 1) | W18: Raw materials / components | X18: Power & fuel cost per unit (Year 1) | Y18: Power & fuel | Z18: Factory overheads
B19: C. MONTHLY PHASING FACTOR (optional — blank = equal spread) | S19: Import / Export Trading | T19: Annual Trading Capacity (units for import/export) | U19: Trading volume (units) | V19: Purchase / import cost per unit (Year 1) | W19: Purchase / import cost | X19: Freight, customs & logistics cost per unit (Year 1) | Y19: Freight & customs | Z19: Trading overheads
B20: Relative weight per month (M1…M12) | C20: M1 | D20: M2 | E20: M3 | F20: M4 | G20: M5 | H20: M6 | I20: M7 | J20: M8 | K20: M9 | L20: M10 | M20: M11 | N20: M12 | S20: Media & Entertainment | T20: Content / Production Capacity (units/hours p.a.) | U20: Content produced (units) | V20: Production cost per unit (Year 1) | W20: Production cost | X20: Equipment & studio cost per unit (Year 1) | Y20: Equipment & studio cost | Z20: Studio overheads
B21: → weights (e.g. 1.0 each, or seasonal) | C21: 0.08 | D21: 0.08 | E21: 0.08 | F21: 0.09 | G21: 0.09 | H21: 0.09 | I21: 0.08 | J21: 0.08 | K21: 0.08 | L21: 0.09 | M21: 0.09 | N21: 0.07 | S21: Mining & Minerals | T21: Installed Extraction Capacity (tonnes p.a.) | U21: Extraction (units) | V21: Raw material / extraction cost per unit (Year 1) | W21: Extraction cost | X21: Power & fuel cost per unit (Year 1) | Y21: Power & fuel | Z21: Mine overheads
B22: D. PRICE & VARIABLE COSTS (Year-1 base, escalated by the % below)
B23: Selling price per unit (Year 1) | C23: 5 | H23: ₹/unit
B24: annual price escalation | C24: 0.04 | H24: %
B25: =IFERROR(VLOOKUP($J$5,$S$5:$Z$21,4,FALSE()),"Raw material cost per unit (Year 1)") -> Raw material cost per unit (Year 1) | C25: 2.5 | H25: ₹/unit
B26: annual RM cost escalation | C26: 0.05 | H26: %
B27: =IFERROR(VLOOKUP($J$5,$S$5:$Z$21,6,FALSE()),"Power & fuel cost per unit (Year 1)") -> Power & fuel cost per unit (Year 1) | C27: 0.3 | H27: ₹/unit
B28: annual power cost escalation | C28: 0.06 | H28: %
B29: Other variable cost per unit (Year 1) | C29: 0.2 | H29: ₹/unit
B30: annual other-variable escalation | C30: 0.04 | H30: %
B31: E. FIXED / PERIOD COSTS (per month, Year-1 base, escalated below)
B32: Direct wages & salaries / month (Year 1) | C32: 150000 | H32: ₹/month
B33: annual wages escalation | C33: 0.05 | H33: %
B34: Factory overheads / month (Year 1) | C34: 100000 | H34: ₹/month
B35: annual factory-OH escalation | C35: 0.05 | H35: %
B36: Repairs & maintenance / month (Year 1) | C36: 30000 | H36: ₹/month
B37: annual R&M escalation | C37: 0.04 | H37: %
B38: Administrative expenses / month (Year 1) | C38: 50000 | H38: ₹/month
B39: annual admin escalation | C39: 0.04 | H39: %
B40: Selling & distribution | C40: 0.02 | H40: % of sales
B41: F. FIXED ASSETS & DEPRECIATION (straight-line on cost)
...

Sheet Production
A1: PRODUCTION PLAN — 60-MONTH PROJECTION
A2: Driven by Installed Capacity × Capacity Utilisation × Monthly phasing (Assumptions).
B3: YEAR 1 | O3: YEAR 2 | AB3: YEAR 3 | AO3: YEAR 4 | BB3: YEAR 5
A4: Particulars | B4: M1 | C4: M2 | D4: M3 | E4: M4 | F4: M5 | G4: M6 | H4: M7 | I4: M8 | J4: M9 | K4: M10 | L4: M11 | M4: M12 | N4: Yr 1 Total | O4: M13 | P4: M14 | Q4: M15 | R4: M16 | S4: M17 | T4: M18 | U4: M19 | V4: M20 | W4: M21 | X4: M22 | Y4: M23 | Z4: M24 | AA4: Yr 2 Total | AB4: M25 | AC4: M26 | AD4: M27 | AE4: M28 | AF4: M29 | AG4: M30 | AH4: M31 | AI4: M32 | AJ4: M33 | AK4: M34 | AL4: M35 | AM4: M36 | AN4: Yr 3 Total | AO4: M37 | AP4: M38 | AQ4: M39 | AR4: M40 | AS4: M41 | AT4: M42 | AU4: M43 | AV4: M44 | AW4: M45 | AX4: M46 | AY4: M47 | AZ4: M48 | BA4: Yr 4 Total | BB4: M49 | BC4: M50 | BD4: M51 | BE4: M52 | BF4: M53 | BG4: M54 | BH4: M55 | BI4: M56 | BJ4: M57 | BK4: M58 | BL4: M59 | BM4: M60 | BN4: Yr 5 Total
A5: Capacity utilisation (%) | B5: =Assumptions!$C$18 -> 0.6 | C5: =Assumptions!$C$18 -> 0.6 | D5: =Assumptions!$C$18 -> 0.6 | E5: =Assumptions!$C$18 -> 0.6 | F5: =Assumptions!$C$18 -> 0.6 | G5: =Assumptions!$C$18 -> 0.6 | H5: =Assumptions!$C$18 -> 0.6 | I5: =Assumptions!$C$18 -> 0.6 | ... N5: =Assumptions!$C$18 -> 0.6 | O5: =Assumptions!$D$18 -> 0.65 | P5: =Assumptions!$D$18 -> 0.65 | Q5: =Assumptions!$D$18 -> 0.65 | R5: =Assumptions!$D$18 -> 0.65 | S5: =Assumptions!$D$18 -> 0.65 | T5: =Assumptions!$D$18 -> 0.65 | U5: =Assumptions!$D$18 -> 0.65 | V5: =Assumptions!$D$18 -> 0.65 | ... AA5: =Assumptions!$D$18 -> 0.65 | AB5: =Assumptions!$E$18 -> 0.7 | AC5: =Assumptions!$E$18 -> 0.7 | AD5: =Assumptions!$E$18 -> 0.7 | AE5: =Assumptions!$E$18 -> 0.7 | AF5: =Assumptions!$E$18 -> 0.7 | AG5: =Assumptions!$E$18 -> 0.7 | AH5: =Assumptions!$E$18 -> 0.7 | AI5: =Assumptions!$E$18 -> 0.7 | ... AN5: =Assumptions!$E$18 -> 0.7 | AO5: =Assumptions!$F$18 -> 0.75 | AP5: =Assumptions!$F$18 -> 0.75 | AQ5: =Assumptions!$F$18 -> 0.75 | AR5: =Assumptions!$F$18 -> 0.75 | AS5: =Assumptions!$F$18 -> 0.75 | AT5: =Assumptions!$F$18 -> 0.75 | AU5: =Assumptions!$F$18 -> 0.75 | AV5: =Assumptions!$F$18 -> 0.75 | ... BA5: =Assumptions!$F$18 -> 0.75 | BB5: =Assumptions!$G$18 -> 0.8 | BC5: =Assumptions!$G$18 -> 0.8 | BD5: =Assumptions!$G$18 -> 0.8 | BE5: =Assumptions!$G$18 -> 0.8 | BF5: =Assumptions!$G$18 -> 0.8 | BG5: =Assumptions!$G$18 -> 0.8 | BH5: =Assumptions!$G$18 -> 0.8 | BI5: =Assumptions!$G$18 -> 0.8 | ... BN5: =Assumptions!$G$18 -> 0.8
A6: =IFERROR(VLOOKUP(Assumptions!$J$5,Assumptions!$S$5:$Z$21,3,FALSE()),"Production (units)") -> Production (units) | B6: =(Assumptions!$C$16*Assumptions!$C$18/12)*IF(SUM(Assumptions!$C$21:$N$21)=0,1,12*Assumptions!$C$21/SUM(Assumptions!$C$21:$N$21)) -> 576000 | C6: =(Assumptions!$C$16*Assumptions!$C$18/12)*IF(SUM(Assumptions!$C$21:$N$21)=0,1,12*Assumptions!$D$21/SUM(Assumptions!$C$21:$N$21)) -> 576000 | D6: =(Assumptions!$C$16*Assumptions!$C$18/12)*IF(SUM(Assumptions!$C$21:$N$21)=0,1,12*Assumptions!$E$21/SUM(Assumptions!$C$21:$N$21)) -> 576000 | E6: =(Assumptions!$C$16*Assumptions!$C$18/12)*IF(SUM(Assumptions!$C$21:$N$21)=0,1,12*Assumptions!$F$21/SUM(Assumptions!$C$21:$N$21)) -> 648000 | F6: =(Assumptions!$C$16*Assumptions!$C$18/12)*IF(SUM(Assumptions!$C$21:$N$21)=0,1,12*Assumptions!$G$21/SUM(Assumptions!$C$21:$N$21)) -> 648000 | G6: =(Assumptions!$C$16*Assumptions!$C$18/12)*IF(SUM(Assumptions!$C$21:$N$21)=0,1,12*Assumptions!$H$21/SUM(Assumptions!$C$21:$N$21)) -> 648000 | H6: =(Assumptions!$C$16*Assumptions!$C$18/12)*IF(SUM(Assumptions!$C$21:$N$21)=0,1,12*Assumptions!$I$21/SUM(Assumptions!$C$21:$N$21)) -> 576000 | I6: =(Assumptions!$C$16*Assumptions!$C$18/12)*IF(SUM(Assumptions!$C$21:$N$21)=0,1,12*Assumptions!$J$21/SUM(Assumptions!$C$21:$N$21)) -> 576000 | J6: =(Assumptions!$C$16*Assumptions!$C$18/12)*IF(SUM(Assumptions!$C$21:$N$21)=0,1,12*Assumptions!$K$21/SUM(Assumptions!$C$21:$N$21)) -> 576000 | K6: =(Assumptions!$C$16*Assumptions!$C$18/12)*IF(SUM(Assumptions!$C$21:$N$21)=0,1,12*Assumptions!$L$21/SUM(Assumptions!$C$21:$N$21)) -> 648000 | L6: =(Assumptions!$C$16*Assumptions!$C$18/12)*IF(SUM(Assumptions!$C$21:$N$21)=0,1,12*Assumptions!$M$21/SUM(Assumptions!$C$21:$N$21)) -> 648000 | M6: =(Assumptions!$C$16*Assumptions!$C$18/12)*IF(SUM(Assumptions!$C$21:$N$21)=0,1,12*Assumptions!$N$21/SUM(Assumptions!$C$21:$N$21)) -> 504000 | N6: =SUM(B6:M6) -> 7200000 | O6: =(Assumptions!$C$16*Assumptions!$D$18/12)*IF(SUM(Assumptions!$C$21:$N$21)=0,1,12*Assumptions!$C$21/SUM(Assumptions!$C$21:$N$21)) -> 624000 | P6: =(Assumptions!$C$16*Assumptions!$D$18/12)*IF(SUM(Assumptions!$C$21:$N$21)=0,1,12*Assumptions!$D$21/SUM(Assumptions!$C$21:$N$21)) -> 624000 | Q6: =(Assumptions!$C$16*Assumptions!$D$18/12)*IF(SUM(Assumptions!$C$21:$N$21)=0,1,12*Assumptions!$E$21/SUM(Assumptions!$C$21:$N$21)) -> 624000 | R6: =(Assumptions!$C$16*Assumptions!$D$18/12)*IF(SUM(Assumptions!$C$21:$N$21)=0,1,12*Assumptions!$F$21/SUM(Assumptions!$C$21:$N$21)) -> 702000 | S6: =(Assumptions!$C$16*Assumptions!$D$18/12)*IF(SUM(Assumptions!$C$21:$N$21)=0,1,12*Assumptions!$G$21/SUM(Assumptions!$C$21:$N$21)) -> 702000 | T6: =(Assumptions!$C$16*Assumptions!$D$18/12)*IF(SUM(Assumptions!$C$21:$N$21)=0,1,12*Assumptions!$H$21/SUM(Assumptions!$C$21:$N$21)) -> 702000 | U6: =(Assumptions!$C$16*Assumptions!$D$18/12)*IF(SUM(Assumptions!$C$21:$N$21)=0,1,12*Assumptions!$I$21/SUM(Assumptions!$C$21:$N$21)) -> 624000 | V6: =(Assumptions!$C$16*Assumptions!$D$18/12)*IF(SUM(Assumptions!$C$21:$N$21)=0,1,12*Assumptions!$J$21/SUM(Assumptions!$C$21:$N$21)) -> 624000 | W6: =(Assumptions!$C$16*Assumptions!$D$18/12)*IF(SUM(Assumptions!$C$21:$N$21)=0,1,12*Assumptions!$K$21/SUM(Assumptions!$C$21:$N$21)) -> 624000 | X6: =(Assumptions!$C$16*Assumptions!$D$18/12)*IF(SUM(Assumptions!$C$21:$N$21)=0,1,12*Assumptions!$L$21/SUM(Assumptions!$C$21:$N$21)) -> 702000 | Y6: =(Assumptions!$C$16*Assumptions!$D$18/12)*IF(SUM(Assumptions!$C$21:$N$21)=0,1,12*Assumptions!$M$21/SUM(Assumptions!$C$21:$N$21)) -> 702000 | Z6: =(Assumptions!$C$16*Assumptions!$D$18/12)*IF(SUM(Assumptions!$C$21:$N$21)=0,1,12*Assumptions!$N$21/SUM(Assumptions!$C$21:$N$21)) -> 546000 | AA6: =SUM(O6:Z6) -> 7800000 | AB6: =(Assumptions!$C$16*Assumptions!$E$18/12)*IF(SUM(Assumptions!$C$21:$N$21)=0,1,12*Assumptions!$C$21/SUM(Assumptions!$C$21:$N$21)) -> 672000 | AC6: =(Assumptions!$C$16*Assumptions!$E$18/12)*IF(SUM(Assumptions!$C$21:$N$21)=0,1,12*Assumptions!$D$21/SUM(Assumptions!$C$21:$N$21)) -> 672000 | AD6: =(Assumptions!$C$16*Assumptions!$E$18/12)*IF(SUM(Assumptions!$C$21:$N$21)=0,1,12*Assumptions!$E$21/SUM(Assumptions!$C$21:$N$21)) -> 672000 | AE6: =(Assumptions!$C$16*Assumptions!$E$18/12)*IF(SUM(Assumptions!$C$21:$N$21)=0,1,12*Assumptions!$F$21/SUM(Assumptions!$C$21:$N$21)) -> 756000 | AF6: =(Assumptions!$C$16*Assumptions!$E$18/12)*IF(SUM(Assumptions!$C$21:$N$21)=0,1,12*Assumptions!$G$21/SUM(Assumptions!$C$21:$N$21)) -> 756000 | AG6: =(Assumptions!$C$16*Assumptions!$E$18/12)*IF(SUM(Assumptions!$C$21:$N$21)=0,1,12*Assumptions!$H$21/SUM(Assumptions!$C$21:$N$21)) -> 756000 | AH6: =(Assumptions!$C$16*Assumptions!$E$18/12)*IF(SUM(Assumptions!$C$21:$N$21)=0,1,12*Assumptions!$I$21/SUM(Assumptions!$C$21:$N$21)) -> 672000 | AI6: =(Assumptions!$C$16*Assumptions!$E$18/12)*IF(SUM(Assumptions!$C$21:$N$21)=0,1,12*Assumptions!$J$21/SUM(Assumptions!$C$21:$N$21)) -> 672000 | AJ6: =(Assumptions!$C$16*Assumptions!$E$18/12)*IF(SUM(Assumptions!$C$21:$N$21)=0,1,12*Assumptions!$K$21/SUM(Assumptions!$C$21:$N$21)) -> 672000 | AK6: =(Assumptions!$C$16*Assumptions!$E$18/12)*IF(SUM(Assumptions!$C$21:$N$21)=0,1,12*Assumptions!$L$21/SUM(Assumptions!$C$21:$N$21)) -> 756000 | AL6: =(Assumptions!$C$16*Assumptions!$E$18/12)*IF(SUM(Assumptions!$C$21:$N$21)=0,1,12*Assumptions!$M$21/SUM(Assumptions!$C$21:$N$21)) -> 756000 | AM6: =(Assumptions!$C$16*Assumptions!$E$18/12)*IF(SUM(Assumptions!$C$21:$N$21)=0,1,12*Assumptions!$N$21/SUM(Assumptions!$C$21:$N$21)) -> 588000 | AN6: =SUM(AB6:AM6) -> 8400000 | AO6: =(Assumptions!$C$16*Assumptions!$F$18/12)*IF(SUM(Assumptions!$C$21:$N$21)=0,1,12*Assumptions!$C$21/SUM(Assumptions!$C$21:$N$21)) -> 720000 | AP6: =(Assumptions!$C$16*Assumptions!$F$18/12)*IF(SUM(Assumptions!$C$21:$N$21)=0,1,12*Assumptions!$D$21/SUM(Assumptions!$C$21:$N$21)) -> 720000 | AQ6: =(Assumptions!$C$16*Assumptions!$F$18/12)*IF(SUM(Assumptions!$C$21:$N$21)=0,1,12*Assumptions!$E$21/SUM(Assumptions!$C$21:$N$21)) -> 720000 | AR6: =(Assumptions!$C$16*Assumptions!$F$18/12)*IF(SUM(Assumptions!$C$21:$N$21)=0,1,12*Assumptions!$F$21/SUM(Assumptions!$C$21:$N$21)) -> 810000 | AS6: =(Assumptions!$C$16*Assumptions!$F$18/12)*IF(SUM(Assumptions!$C$21:$N$21)=0,1,12*Assumptions!$G$21/SUM(Assumptions!$C$21:$N$21)) -> 810000 | AT6: =(Assumptions!$C$16*Assumptions!$F$18/12)*IF(SUM(Assumptions!$C$21:$N$21)=0,1,12*Assumptions!$H$21/SUM(Assumptions!$C$21:$N$21)) -> 810000 | AU6: =(Assumptions!$C$16*Assumptions!$F$18/12)*IF(SUM(Assumptions!$C$21:$N$21)=0,1,12*Assumptions!$I$21/SUM(Assumptions!$C$21:$N$21)) -> 720000 | AV6: =(Assumptions!$C$16*Assumptions!$F$18/12)*IF(SUM(Assumptions!$C$21:$N$21)=0,1,12*Assumptions!$J$21/SUM(Assumptions!$C$21:$N$21)) -> 720000 | AW6: =(Assumptions!$C$16*Assumptions!$F$18/12)*IF(SUM(Assumptions!$C$21:$N$21)=0,1,12*Assumptions!$K$21/SUM(Assumptions!$C$21:$N$21)) -> 720000 | AX6: =(Assumptions!$C$16*Assumptions!$F$18/12)*IF(SUM(Assumptions!$C$21:$N$21)=0,1,12*Assumptions!$L$21/SUM(Assumptions!$C$21:$N$21)) -> 810000 | AY6: =(Assumptions!$C$16*Assumptions!$F$18/12)*IF(SUM(Assumptions!$C$21:$N$21)=0,1,12*Assumptions!$M$21/SUM(Assumptions!$C$21:$N$21)) -> 810000 | AZ6: =(Assumptions!$C$16*Assumptions!$F$18/12)*IF(SUM(Assumptions!$C$21:$N$21)=0,1,12*Assumptions!$N$21/SUM(Assumptions!$C$21:$N$21)) -> 630000 | BA6: =SUM(AO6:AZ6) -> 9000000 | BB6: =(Assumptions!$C$16*Assumptions!$G$18/12)*IF(SUM(Assumptions!$C$21:$N$21)=0,1,12*Assumptions!$C$21/SUM(Assumptions!$C$21:$N$21)) -> 768000 | BC6: =(Assumptions!$C$16*Assumptions!$G$18/12)*IF(SUM(Assumptions!$C$21:$N$21)=0,1,12*Assumptions!$D$21/SUM(Assumptions!$C$21:$N$21)) -> 768000 | BD6: =(Assumptions!$C$16*Assumptions!$G$18/12)*IF(SUM(Assumptions!$C$21:$N$21)=0,1,12*Assumptions!$E$21/SUM(Assumptions!$C$21:$N$21)) -> 768000 | BE6: =(Assumptions!$C$16*Assumptions!$G$18/12)*IF(SUM(Assumptions!$C$21:$N$21)=0,1,12*Assumptions!$F$21/SUM(Assumptions!$C$21:$N$21)) -> 864000 | BF6: =(Assumptions!$C$16*Assumptions!$G$18/12)*IF(SUM(Assumptions!$C$21:$N$21)=0,1,12*Assumptions!$G$21/SUM(Assumptions!$C$21:$N$21)) -> 864000 | BG6: =(Assumptions!$C$16*Assumptions!$G$18/12)*IF(SUM(Assumptions!$C$21:$N$21)=0,1,12*Assumptions!$H$21/SUM(Assumptions!$C$21:$N$21)) -> 864000 | BH6: =(Assumptions!$C$16*Assumptions!$G$18/12)*IF(SUM(Assumptions!$C$21:$N$21)=0,1,12*Assumptions!$I$21/SUM(Assumptions!$C$21:$N$21)) -> 768000 | BI6: =(Assumptions!$C$16*Assumptions!$G$18/12)*IF(SUM(Assumptions!$C$21:$N$21)=0,1,12*Assumptions!$J$21/SUM(Assumptions!$C$21:$N$21)) -> 768000 | BJ6: =(Assumptions!$C$16*Assumptions!$G$18/12)*IF(SUM(Assumptions!$C$21:$N$21)=0,1,12*Assumptions!$K$21/SUM(Assumptions!$C$21:$N$21)) -> 768000 | BK6: =(Assumptions!$C$16*Assumptions!$G$18/12)*IF(SUM(Assumptions!$C$21:$N$21)=0,1,12*Assumptions!$L$21/SUM(Assumptions!$C$21:$N$21)) -> 864000 | BL6: =(Assumptions!$C$16*Assumptions!$G$18/12)*IF(SUM(Assumptions!$C$21:$N$21)=0,1,12*Assumptions!$M$21/SUM(Assumptions!$C$21:$N$21)) -> 864000 | BM6: =(Assumptions!$C$16*Assumptions!$G$18/12)*IF(SUM(Assumptions!$C$21:$N$21)=0,1,12*Assumptions!$N$21/SUM(Assumptions!$C$21:$N$21)) -> 672000 | BN6: =SUM(BB6:BM6) -> 9600000

Sheet Sales
A1: SALES PLAN — 60-MONTH PROJECTION
A2: Sales quantity = production; revenue = quantity × escalated selling price.
B3: YEAR 1 | O3: YEAR 2 | AB3: YEAR 3 | AO3: YEAR 4 | BB3: YEAR 5
A4: Particulars | B4: M1 | C4: M2 | D4: M3 | E4: M4 | F4: M5 | G4: M6 | H4: M7 | I4: M8 | J4: M9 | K4: M10 | L4: M11 | M4: M12 | N4: Yr 1 Total | O4: M13 | P4: M14 | Q4: M15 | R4: M16 | S4: M17 | T4: M18 | U4: M19 | V4: M20 | W4: M21 | X4: M22 | Y4: M23 | Z4: M24 | AA4: Yr 2 Total | AB4: M25 | AC4: M26 | AD4: M27 | AE4: M28 | AF4: M29 | AG4: M30 | AH4: M31 | AI4: M32 | AJ4: M33 | AK4: M34 | AL4: M35 | AM4: M36 | AN4: Yr 3 Total | AO4: M37 | AP4: M38 | AQ4: M39 | AR4: M40 | AS4: M41 | AT4: M42 | AU4: M43 | AV4: M44 | AW4: M45 | AX4: M46 | AY4: M47 | AZ4: M48 | BA4: Yr 4 Total | BB4: M49 | BC4: M50 | BD4: M51 | BE4: M52 | BF4: M53 | BG4: M54 | BH4: M55 | BI4: M56 | BJ4: M57 | BK4: M58 | BL4: M59 | BM4: M60 | BN4: Yr 5 Total
A5: Sales quantity (units) | B5: =Production!B6 -> 576000 | C5: =Production!C6 -> 576000 | D5: =Production!D6 -> 576000 | E5: =Production!E6 -> 648000 | F5: =Production!F6 -> 648000 | G5: =Production!G6 -> 648000 | H5: =Production!H6 -> 576000 | I5: =Production!I6 -> 576000 | ... M5: =Production!M6 -> 504000 | N5: =SUM(B5:M5) -> 7200000 | O5: =Production!O6 -> 624000 | P5: =Production!P6 -> 624000 | Q5: =Production!Q6 -> 624000 | R5: =Production!R6 -> 702000 | S5: =Production!S6 -> 702000 | T5: =Production!T6 -> 702000 | U5: =Production!U6 -> 624000 | V5: =Production!V6 -> 624000 | ... Z5: =Production!Z6 -> 546000 | AA5: =SUM(O5:Z5) -> 7800000 | AB5: =Production!AB6 -> 672000 | AC5: =Production!AC6 -> 672000 | AD5: =Production!AD6 -> 672000 | AE5: =Production!AE6 -> 756000 | AF5: =Production!AF6 -> 756000 | AG5: =Production!AG6 -> 756000 | AH5: =Production!AH6 -> 672000 | AI5: =Production!AI6 -> 672000 | ... AM5: =Production!AM6 -> 588000 | AN5: =SUM(AB5:AM5) -> 8400000 | AO5: =Production!AO6 -> 720000 | AP5: =Production!AP6 -> 720000 | AQ5: =Production!AQ6 -> 720000 | AR5: =Production!AR6 -> 810000 | AS5: =Production!AS6 -> 810000 | AT5: =Production!AT6 -> 810000 | AU5: =Production!AU6 -> 720000 | AV5: =Production!AV6 -> 720000 | ... AZ5: =Production!AZ6 -> 630000 | BA5: =SUM(AO5:AZ5) -> 9000000 | BB5: =Production!BB6 -> 768000 | BC5: =Production!BC6 -> 768000 | BD5: =Production!BD6 -> 768000 | BE5: =Production!BE6 -> 864000 | BF5: =Production!BF6 -> 864000 | BG5: =Production!BG6 -> 864000 | BH5: =Production!BH6 -> 768000 | BI5: =Production!BI6 -> 768000 | ... BM5: =Production!BM6 -> 672000 | BN5: =SUM(BB5:BM5) -> 9600000
A6: Selling price (₹ / unit) | B6: =Assumptions!$C$23*(1+Assumptions!$C$24)^0 -> 5 | C6: =Assumptions!$C$23*(1+Assumptions!$C$24)^0 -> 5 | D6: =Assumptions!$C$23*(1+Assumptions!$C$24)^0 -> 5 | E6: =Assumptions!$C$23*(1+Assumptions!$C$24)^0 -> 5 | F6: =Assumptions!$C$23*(1+Assumptions!$C$24)^0 -> 5 | G6: =Assumptions!$C$23*(1+Assumptions!$C$24)^0 -> 5 | H6: =Assumptions!$C$23*(1+Assumptions!$C$24)^0 -> 5 | I6: =Assumptions!$C$23*(1+Assumptions!$C$24)^0 -> 5 | ... N6: =Assumptions!$C$23*(1+Assumptions!$C$24)^0 -> 5 | O6: =Assumptions!$C$23*(1+Assumptions!$C$24)^1 -> 5.2 | P6: =Assumptions!$C$23*(1+Assumptions!$C$24)^1 -> 5.2 | Q6: =Assumptions!$C$23*(1+Assumptions!$C$24)^1 -> 5.2 | R6: =Assumptions!$C$23*(1+Assumptions!$C$24)^1 -> 5.2 | S6: =Assumptions!$C$23*(1+Assumptions!$C$24)^1 -> 5.2 | T6: =Assumptions!$C$23*(1+Assumptions!$C$24)^1 -> 5.2 | U6: =Assumptions!$C$23*(1+Assumptions!$C$24)^1 -> 5.2 | V6: =Assumptions!$C$23*(1+Assumptions!$C$24)^1 -> 5.2 | ... AA6: =Assumptions!$C$23*(1+Assumptions!$C$24)^1 -> 5.2 | AB6: =Assumptions!$C$23*(1+Assumptions!$C$24)^2 -> 5.408 | AC6: =Assumptions!$C$23*(1+Assumptions!$C$24)^2 -> 5.408 | AD6: =Assumptions!$C$23*(1+Assumptions!$C$24)^2 -> 5.408 | AE6: =Assumptions!$C$23*(1+Assumptions!$C$24)^2 -> 5.408 | AF6: =Assumptions!$C$23*(1+Assumptions!$C$24)^2 -> 5.408 | AG6: =Assumptions!$C$23*(1+Assumptions!$C$24)^2 -> 5.408 | AH6: =Assumptions!$C$23*(1+Assumptions!$C$24)^2 -> 5.408 | AI6: =Assumptions!$C$23*(1+Assumptions!$C$24)^2 -> 5.408 | ... AN6: =Assumptions!$C$23*(1+Assumptions!$C$24)^2 -> 5.408 | AO6: =Assumptions!$C$23*(1+Assumptions!$C$24)^3 -> 5.62432 | AP6: =Assumptions!$C$23*(1+Assumptions!$C$24)^3 -> 5.62432 | AQ6: =Assumptions!$C$23*(1+Assumptions!$C$24)^3 -> 5.62432 | AR6: =Assumptions!$C$23*(1+Assumptions!$C$24)^3 -> 5.62432 | AS6: =Assumptions!$C$23*(1+Assumptions!$C$24)^3 -> 5.62432 | AT6: =Assumptions!$C$23*(1+Assumptions!$C$24)^3 -> 5.62432 | AU6: =Assumptions!$C$23*(1+Assumptions!$C$24)^3 -> 5.62432 | AV6: =Assumptions!$C$23*(1+Assumptions!$C$24)^3 -> 5.62432 | ... BA6: =Assumptions!$C$23*(1+Assumptions!$C$24)^3 -> 5.62432 | BB6: =Assumptions!$C$23*(1+Assumptions!$C$24)^4 -> 5.8492928 | BC6: =Assumptions!$C$23*(1+Assumptions!$C$24)^4 -> 5.8492928 | BD6: =Assumptions!$C$23*(1+Assumptions!$C$24)^4 -> 5.8492928 | BE6: =Assumptions!$C$23*(1+Assumptions!$C$24)^4 -> 5.8492928 | BF6: =Assumptions!$C$23*(1+Assumptions!$C$24)^4 -> 5.8492928 | BG6: =Assumptions!$C$23*(1+Assumptions!$C$24)^4 -> 5.8492928 | BH6: =Assumptions!$C$23*(1+Assumptions!$C$24)^4 -> 5.8492928 | BI6: =Assumptions!$C$23*(1+Assumptions!$C$24)^4 -> 5.8492928 | ... BN6: =Assumptions!$C$23*(1+Assumptions!$C$24)^4 -> 5.8492928
A7: Net Sales / Revenue (₹) | B7: =B5*B6 -> 2880000 | C7: =C5*C6 -> 2880000 | D7: =D5*D6 -> 2880000 | E7: =E5*E6 -> 3240000 | F7: =F5*F6 -> 3240000 | G7: =G5*G6 -> 3240000 | H7: =H5*H6 -> 2880000 | I7: =I5*I6 -> 2880000 | ... M7: =M5*M6 -> 2520000 | N7: =SUM(B7:M7) -> 36000000 | O7: =O5*O6 -> 3244800 | P7: =P5*P6 -> 3244800 | Q7: =Q5*Q6 -> 3244800 | R7: =R5*R6 -> 3650400 | S7: =S5*S6 -> 3650400 | T7: =T5*T6 -> 3650400 | U7: =U5*U6 -> 3244800 | V7: =V5*V6 -> 3244800 | ... Z7: =Z5*Z6 -> 2839200 | AA7: =SUM(O7:Z7) -> 40560000 | AB7: =AB5*AB6 -> 3634176 | AC7: =AC5*AC6 -> 3634176 | AD7: =AD5*AD6 -> 3634176 | AE7: =AE5*AE6 -> 4088448 | AF7: =AF5*AF6 -> 4088448 | AG7: =AG5*AG6 -> 4088448 | AH7: =AH5*AH6 -> 3634176 | AI7: =AI5*AI6 -> 3634176 | ... AM7: =AM5*AM6 -> 3179904 | AN7: =SUM(AB7:AM7) -> 45427200 | AO7: =AO5*AO6 -> 4049510.4 | AP7: =AP5*AP6 -> 4049510.4 | AQ7: =AQ5*AQ6 -> 4049510.4 | AR7: =AR5*AR6 -> 4555699.2 | AS7: =AS5*AS6 -> 4555699.2 | AT7: =AT5*AT6 -> 4555699.2 | AU7: =AU5*AU6 -> 4049510.4 | AV7: =AV5*AV6 -> 4049510.4 | ... AZ7: =AZ5*AZ6 -> 3543321.6 | BA7: =SUM(AO7:AZ7) -> 50618880 | BB7: =BB5*BB6 -> 4492256.9 | BC7: =BC5*BC6 -> 4492256.9 | BD7: =BD5*BD6 -> 4492256.9 | BE7: =BE5*BE6 -> 5053789 | BF7: =BF5*BF6 -> 5053789 | BG7: =BG5*BG6 -> 5053789 | BH7: =BH5*BH6 -> 4492256.9 | BI7: =BI5*BI6 -> 4492256.9 | ... BM7: =BM5*BM6 -> 3930724.8 | BN7: =SUM(BB7:BM7) -> 56153211

Sheet Expenses
A1: OPERATING EXPENSES — 60-MONTH PROJECTION
A2: Variable costs scale with production; period costs escalate annually; interest & depreciation linked.
B3: YEAR 1 | O3: YEAR 2 | AB3: YEAR 3 | AO3: YEAR 4 | BB3: YEAR 5
A4: Particulars | B4: M1 | C4: M2 | D4: M3 | E4: M4 | F4: M5 | G4: M6 | H4: M7 | I4: M8 | J4: M9 | K4: M10 | L4: M11 | M4: M12 | N4: Yr 1 Total | O4: M13 | P4: M14 | Q4: M15 | R4: M16 | S4: M17 | T4: M18 | U4: M19 | V4: M20 | W4: M21 | X4: M22 | Y4: M23 | Z4: M24 | AA4: Yr 2 Total | AB4: M25 | AC4: M26 | AD4: M27 | AE4: M28 | AF4: M29 | AG4: M30 | AH4: M31 | AI4: M32 | AJ4: M33 | AK4: M34 | AL4: M35 | AM4: M36 | AN4: Yr 3 Total | AO4: M37 | AP4: M38 | AQ4: M39 | AR4: M40 | AS4: M41 | AT4: M42 | AU4: M43 | AV4: M44 | AW4: M45 | AX4: M46 | AY4: M47 | AZ4: M48 | BA4: Yr 4 Total | BB4: M49 | BC4: M50 | BD4: M51 | BE4: M52 | BF4: M53 | BG4: M54 | BH4: M55 | BI4: M56 | BJ4: M57 | BK4: M58 | BL4: M59 | BM4: M60 | BN4: Yr 5 Total
A5: =IFERROR(VLOOKUP(Assumptions!$J$5,Assumptions!$S$5:$Z$21,5,FALSE()),"Raw materials") -> Raw materials | B5: =Production!B6*(Assumptions!$C$25*(1+Assumptions!$C$26)^0) -> 1440000 | C5: =Production!C6*(Assumptions!$C$25*(1+Assumptions!$C$26)^0) -> 1440000 | D5: =Production!D6*(Assumptions!$C$25*(1+Assumptions!$C$26)^0) -> 1440000 | E5: =Production!E6*(Assumptions!$C$25*(1+Assumptions!$C$26)^0) -> 1620000 | F5: =Production!F6*(Assumptions!$C$25*(1+Assumptions!$C$26)^0) -> 1620000 | G5: =Production!G6*(Assumptions!$C$25*(1+Assumptions!$C$26)^0) -> 1620000 | H5: =Production!H6*(Assumptions!$C$25*(1+Assumptions!$C$26)^0) -> 1440000 | I5: =Production!I6*(Assumptions!$C$25*(1+Assumptions!$C$26)^0) -> 1440000 | ... M5: =Production!M6*(Assumptions!$C$25*(1+Assumptions!$C$26)^0) -> 1260000 | N5: =SUM(B5:M5) -> 18000000 | O5: =Production!O6*(Assumptions!$C$25*(1+Assumptions!$C$26)^1) -> 1638000 | P5: =Production!P6*(Assumptions!$C$25*(1+Assumptions!$C$26)^1) -> 1638000 | Q5: =Production!Q6*(Assumptions!$C$25*(1+Assumptions!$C$26)^1) -> 1638000 | R5: =Production!R6*(Assumptions!$C$25*(1+Assumptions!$C$26)^1) -> 1842750 | S5: =Production!S6*(Assumptions!$C$25*(1+Assumptions!$C$26)^1) -> 1842750 | T5: =Production!T6*(Assumptions!$C$25*(1+Assumptions!$C$26)^1) -> 1842750 | U5: =Production!U6*(Assumptions!$C$25*(1+Assumptions!$C$26)^1) -> 1638000 | V5: =Production!V6*(Assumptions!$C$25*(1+Assumptions!$C$26)^1) -> 1638000 | ... Z5: =Production!Z6*(Assumptions!$C$25*(1+Assumptions!$C$26)^1) -> 1433250 | AA5: =SUM(O5:Z5) -> 20475000 | AB5: =Production!AB6*(Assumptions!$C$25*(1+Assumptions!$C$26)^2) -> 1852200 | AC5: =Production!AC6*(Assumptions!$C$25*(1+Assumptions!$C$26)^2) -> 1852200 | AD5: =Production!AD6*(Assumptions!$C$25*(1+Assumptions!$C$26)^2) -> 1852200 | AE5: =Production!AE6*(Assumptions!$C$25*(1+Assumptions!$C$26)^2) -> 2083725 | AF5: =Production!AF6*(Assumptions!$C$25*(1+Assumptions!$C$26)^2) -> 2083725 | AG5: =Production!AG6*(Assumptions!$C$25*(1+Assumptions!$C$26)^2) -> 2083725 | AH5: =Production!AH6*(Assumptions!$C$25*(1+Assumptions!$C$26)^2) -> 1852200 | AI5: =Production!AI6*(Assumptions!$C$25*(1+Assumptions!$C$26)^2) -> 1852200 | ... AM5: =Production!AM6*(Assumptions!$C$25*(1+Assumptions!$C$26)^2) -> 1620675 | AN5: =SUM(AB5:AM5) -> 23152500 | AO5: =Production!AO6*(Assumptions!$C$25*(1+Assumptions!$C$26)^3) -> 2083725 | AP5: =Production!AP6*(Assumptions!$C$25*(1+Assumptions!$C$26)^3) -> 2083725 | AQ5: =Production!AQ6*(Assumptions!$C$25*(1+Assumptions!$C$26)^3) -> 2083725 | AR5: =Production!AR6*(Assumptions!$C$25*(1+Assumptions!$C$26)^3) -> 2344190.6 | AS5: =Production!AS6*(Assumptions!$C$25*(1+Assumptions!$C$26)^3) -> 2344190.6 | AT5: =Production!AT6*(Assumptions!$C$25*(1+Assumptions!$C$26)^3) -> 2344190.6 | AU5: =Production!AU6*(Assumptions!$C$25*(1+Assumptions!$C$26)^3) -> 2083725 | AV5: =Production!AV6*(Assumptions!$C$25*(1+Assumptions!$C$26)^3) -> 2083725 | ... AZ5: =Production!AZ6*(Assumptions!$C$25*(1+Assumptions!$C$26)^3) -> 1823259.4 | BA5: =SUM(AO5:AZ5) -> 26046563 | BB5: =Production!BB6*(Assumptions!$C$25*(1+Assumptions!$C$26)^4) -> 2333772 | BC5: =Production!BC6*(Assumptions!$C$25*(1+Assumptions!$C$26)^4) -> 2333772 | BD5: =Production!BD6*(Assumptions!$C$25*(1+Assumptions!$C$26)^4) -> 2333772 | BE5: =Production!BE6*(Assumptions!$C$25*(1+Assumptions!$C$26)^4) -> 2625493.5 | BF5: =Production!BF6*(Assumptions!$C$25*(1+Assumptions!$C$26)^4) -> 2625493.5 | BG5: =Production!BG6*(Assumptions!$C$25*(1+Assumptions!$C$26)^4) -> 2625493.5 | BH5: =Production!BH6*(Assumptions!$C$25*(1+Assumptions!$C$26)^4) -> 2333772 | BI5: =Production!BI6*(Assumptions!$C$25*(1+Assumptions!$C$26)^4) -> 2333772 | ... BM5: =Production!BM6*(Assumptions!$C$25*(1+Assumptions!$C$26)^4) -> 2042050.5 | BN5: =SUM(BB5:BM5) -> 29172150
A6: =IFERROR(VLOOKUP(Assumptions!$J$5,Assumptions!$S$5:$Z$21,7,FALSE()),"Power & fuel") -> Power & fuel | B6: =Production!B6*(Assumptions!$C$27*(1+Assumptions!$C$28)^0) -> 172800 | C6: =Production!C6*(Assumptions!$C$27*(1+Assumptions!$C$28)^0) -> 172800 | D6: =Production!D6*(Assumptions!$C$27*(1+Assumptions!$C$28)^0) -> 172800 | E6: =Production!E6*(Assumptions!$C$27*(1+Assumptions!$C$28)^0) -> 194400 | F6: =Production!F6*(Assumptions!$C$27*(1+Assumptions!$C$28)^0) -> 194400 | G6: =Production!G6*(Assumptions!$C$27*(1+Assumptions!$C$28)^0) -> 194400 | H6: =Production!H6*(Assumptions!$C$27*(1+Assumptions!$C$28)^0) -> 172800 | I6: =Production!I6*(Assumptions!$C$27*(1+Assumptions!$C$28)^0) -> 172800 | ... M6: =Production!M6*(Assumptions!$C$27*(1+Assumptions!$C$28)^0) -> 151200 | N6: =SUM(B6:M6) -> 2160000 | O6: =Production!O6*(Assumptions!$C$27*(1+Assumptions!$C$28)^1) -> 198432 | P6: =Production!P6*(Assumptions!$C$27*(1+Assumptions!$C$28)^1) -> 198432 | Q6: =Production!Q6*(Assumptions!$C$27*(1+Assumptions!$C$28)^1) -> 198432 | R6: =Production!R6*(Assumptions!$C$27*(1+Assumptions!$C$28)^1) -> 223236 | S6: =Production!S6*(Assumptions!$C$27*(1+Assumptions!$C$28)^1) -> 223236 | T6: =Production!T6*(Assumptions!$C$27*(1+Assumptions!$C$28)^1) -> 223236 | U6: =Production!U6*(Assumptions!$C$27*(1+Assumptions!$C$28)^1) -> 198432 | V6: =Production!V6*(Assumptions!$C$27*(1+Assumptions!$C$28)^1) -> 198432 | ... Z6: =Production!Z6*(Assumptions!$C$27*(1+Assumptions!$C$28)^1) -> 173628 | AA6: =SUM(O6:Z6) -> 2480400 | AB6: =Production!AB6*(Assumptions!$C$27*(1+Assumptions!$C$28)^2) -> 226517.76 | AC6: =Production!AC6*(Assumptions!$C$27*(1+Assumptions!$C$28)^2) -> 226517.76 | AD6: =Production!AD6*(Assumptions!$C$27*(1+Assumptions!$C$28)^2) -> 226517.76 | AE6: =Production!AE6*(Assumptions!$C$27*(1+Assumptions!$C$28)^2) -> 254832.48 | AF6: =Production!AF6*(Assumptions!$C$27*(1+Assumptions!$C$28)^2) -> 254832.48 | AG6: =Production!AG6*(Assumptions!$C$27*(1+Assumptions!$C$28)^2) -> 254832.48 | AH6: =Production!AH6*(Assumptions!$C$27*(1+Assumptions!$C$28)^2) -> 226517.76 | AI6: =Production!AI6*(Assumptions!$C$27*(1+Assumptions!$C$28)^2) -> 226517.76 | ... AM6: =Production!AM6*(Assumptions!$C$27*(1+Assumptions!$C$28)^2) -> 198203.04 | AN6: =SUM(AB6:AM6) -> 2831472 | AO6: =Production!AO6*(Assumptions!$C$27*(1+Assumptions!$C$28)^3) -> 257259.46 | AP6: =Production!AP6*(Assumptions!$C$27*(1+Assumptions!$C$28)^3) -> 257259.46 | AQ6: =Production!AQ6*(Assumptions!$C$27*(1+Assumptions!$C$28)^3) -> 257259.46 | AR6: =Production!AR6*(Assumptions!$C$27*(1+Assumptions!$C$28)^3) -> 289416.89 | AS6: =Production!AS6*(Assumptions!$C$27*(1+Assumptions!$C$28)^3) -> 289416.89 | AT6: =Production!AT6*(Assumptions!$C$27*(1+Assumptions!$C$28)^3) -> 289416.89 | AU6: =Production!AU6*(Assumptions!$C$27*(1+Assumptions!$C$28)^3) -> 257259.46 | AV6: =Production!AV6*(Assumptions!$C$27*(1+Assumptions!$C$28)^3) -> 257259.46 | ... AZ6: =Production!AZ6*(Assumptions!$C$27*(1+Assumptions!$C$28)^3) -> 225102.02 | BA6: =SUM(AO6:AZ6) -> 3215743.2 | BB6: =Production!BB6*(Assumptions!$C$27*(1+Assumptions!$C$28)^4) -> 290874.69 | BC6: =Production!BC6*(Assumptions!$C$27*(1+Assumptions!$C$28)^4) -> 290874.69 | BD6: =Production!BD6*(Assumptions!$C$27*(1+Assumptions!$C$28)^4) -> 290874.69 | BE6: =Production!BE6*(Assumptions!$C$27*(1+Assumptions!$C$28)^4) -> 327234.03 | BF6: =Production!BF6*(Assumptions!$C$27*(1+Assumptions!$C$28)^4) -> 327234.03 | BG6: =Production!BG6*(Assumptions!$C$27*(1+Assumptions!$C$28)^4) -> 327234.03 | BH6: =Production!BH6*(Assumptions!$C$27*(1+Assumptions!$C$28)^4) -> 290874.69 | BI6: =Production!BI6*(Assumptions!$C$27*(1+Assumptions!$C$28)^4) -> 290874.69 | ... BM6: =Production!BM6*(Assumptions!$C$27*(1+Assumptions!$C$28)^4) -> 254515.36 | BN6: =SUM(BB6:BM6) -> 3635933.6
A7: Direct wages & salaries | B7: =Assumptions!$C$32*(1+Assumptions!$C$33)^0 -> 150000 | C7: =Assumptions!$C$32*(1+Assumptions!$C$33)^0 -> 150000 | D7: =Assumptions!$C$32*(1+Assumptions!$C$33)^0 -> 150000 | E7: =Assumptions!$C$32*(1+Assumptions!$C$33)^0 -> 150000 | F7: =Assumptions!$C$32*(1+Assumptions!$C$33)^0 -> 150000 | G7: =Assumptions!$C$32*(1+Assumptions!$C$33)^0 -> 150000 | H7: =Assumptions!$C$32*(1+Assumptions!$C$33)^0 -> 150000 | I7: =Assumptions!$C$32*(1+Assumptions!$C$33)^0 -> 150000 | ... M7: =Assumptions!$C$32*(1+Assumptions!$C$33)^0 -> 150000 | N7: =SUM(B7:M7) -> 1800000 | O7: =Assumptions!$C$32*(1+Assumptions!$C$33)^1 -> 157500 | P7: =Assumptions!$C$32*(1+Assumptions!$C$33)^1 -> 157500 | Q7: =Assumptions!$C$32*(1+Assumptions!$C$33)^1 -> 157500 | R7: =Assumptions!$C$32*(1+Assumptions!$C$33)^1 -> 157500 | S7: =Assumptions!$C$32*(1+Assumptions!$C$33)^1 -> 157500 | T7: =Assumptions!$C$32*(1+Assumptions!$C$33)^1 -> 157500 | U7: =Assumptions!$C$32*(1+Assumptions!$C$33)^1 -> 157500 | V7: =Assumptions!$C$32*(1+Assumptions!$C$33)^1 -> 157500 | ... Z7: =Assumptions!$C$32*(1+Assumptions!$C$33)^1 -> 157500 | AA7: =SUM(O7:Z7) -> 1890000 | AB7: =Assumptions!$C$32*(1+Assumptions!$C$33)^2 -> 165375 | AC7: =Assumptions!$C$32*(1+Assumptions!$C$33)^2 -> 165375 | AD7: =Assumptions!$C$32*(1+Assumptions!$C$33)^2 -> 165375 | AE7: =Assumptions!$C$32*(1+Assumptions!$C$33)^2 -> 165375 | AF7: =Assumptions!$C$32*(1+Assumptions!$C$33)^2 -> 165375 | AG7: =Assumptions!$C$32*(1+Assumptions!$C$33)^2 -> 165375 | AH7: =Assumptions!$C$32*(1+Assumptions!$C$33)^2 -> 165375 | AI7: =Assumptions!$C$32*(1+Assumptions!$C$33)^2 -> 165375 | ... AM7: =Assumptions!$C$32*(1+Assumptions!$C$33)^2 -> 165375 | AN7: =SUM(AB7:AM7) -> 1984500 | AO7: =Assumptions!$C$32*(1+Assumptions!$C$33)^3 -> 173643.75 | AP7: =Assumptions!$C$32*(1+Assumptions!$C$33)^3 -> 173643.75 | AQ7: =Assumptions!$C$32*(1+Assumptions!$C$33)^3 -> 173643.75 | AR7: =Assumptions!$C$32*(1+Assumptions!$C$33)^3 -> 173643.75 | AS7: =Assumptions!$C$32*(1+Assumptions!$C$33)^3 -> 173643.75 | AT7: =Assumptions!$C$32*(1+Assumptions!$C$33)^3 -> 173643.75 | AU7: =Assumptions!$C$32*(1+Assumptions!$C$33)^3 -> 173643.75 | AV7: =Assumptions!$C$32*(1+Assumptions!$C$33)^3 -> 173643.75 | ... AZ7: =Assumptions!$C$32*(1+Assumptions!$C$33)^3 -> 173643.75 | BA7: =SUM(AO7:AZ7) -> 2083725 | BB7: =Assumptions!$C$32*(1+Assumptions!$C$33)^4 -> 182325.94 | BC7: =Assumptions!$C$32*(1+Assumptions!$C$33)^4 -> 182325.94 | BD7: =Assumptions!$C$32*(1+Assumptions!$C$33)^4 -> 182325.94 | BE7: =Assumptions!$C$32*(1+Assumptions!$C$33)^4 -> 182325.94 | BF7: =Assumptions!$C$32*(1+Assumptions!$C$33)^4 -> 182325.94 | BG7: =Assumptions!$C$32*(1+Assumptions!$C$33)^4 -> 182325.94 | BH7: =Assumptions!$C$32*(1+Assumptions!$C$33)^4 -> 182325.94 | BI7: =Assumptions!$C$32*(1+Assumptions!$C$33)^4 -> 182325.94 | ... BM7: =Assumptions!$C$32*(1+Assumptions!$C$33)^4 -> 182325.94 | BN7: =SUM(BB7:BM7) -> 2187911.2
A8: Other variable cost | B8: =Production!B6*(Assumptions!$C$29*(1+Assumptions!$C$30)^0) -> 115200 | C8: =Production!C6*(Assumptions!$C$29*(1+Assumptions!$C$30)^0) -> 115200 | D8: =Production!D6*(Assumptions!$C$29*(1+Assumptions!$C$30)^0) -> 115200 | E8: =Production!E6*(Assumptions!$C$29*(1+Assumptions!$C$30)^0) -> 129600 | F8: =Production!F6*(Assumptions!$C$29*(1+Assumptions!$C$30)^0) -> 129600 | G8: =Production!G6*(Assumptions!$C$29*(1+Assumptions!$C$30)^0) -> 129600 | H8: =Production!H6*(Assumptions!$C$29*(1+Assumptions!$C$30)^0) -> 115200 | I8: =Production!I6*(Assumptions!$C$29*(1+Assumptions!$C$30)^0) -> 115200 | ... M8: =Production!M6*(Assumptions!$C$29*(1+Assumptions!$C$30)^0) -> 100800 | N8: =SUM(B8:M8) -> 1440000 | O8: =Production!O6*(Assumptions!$C$29*(1+Assumptions!$C$30)^1) -> 129792 | P8: =Production!P6*(Assumptions!$C$29*(1+Assumptions!$C$30)^1) -> 129792 | Q8: =Production!Q6*(Assumptions!$C$29*(1+Assumptions!$C$30)^1) -> 129792 | R8: =Production!R6*(Assumptions!$C$29*(1+Assumptions!$C$30)^1) -> 146016 | S8: =Production!S6*(Assumptions!$C$29*(1+Assumptions!$C$30)^1) -> 146016 | T8: =Production!T6*(Assumptions!$C$29*(1+Assumptions!$C$30)^1) -> 146016 | U8: =Production!U6*(Assumptions!$C$29*(1+Assumptions!$C$30)^1) -> 129792 | V8: =Production!V6*(Assumptions!$C$29*(1+Assumptions!$C$30)^1) -> 129792 | ... Z8: =Production!Z6*(Assumptions!$C$29*(1+Assumptions!$C$30)^1) -> 113568 | AA8: =SUM(O8:Z8) -> 1622400 | AB8: =Production!AB6*(Assumptions!$C$29*(1+Assumptions!$C$30)^2) -> 145367.04 | AC8: =Production!AC6*(Assumptions!$C$29*(1+Assumptions!$C$30)^2) -> 145367.04 | AD8: =Production!AD6*(Assumptions!$C$29*(1+Assumptions!$C$30)^2) -> 145367.04 | AE8: =Production!AE6*(Assumptions!$C$29*(1+Assumptions!$C$30)^2) -> 163537.92 | AF8: =Production!AF6*(Assumptions!$C$29*(1+Assumptions!$C$30)^2) -> 163537.92 | AG8: =Production!AG6*(Assumptions!$C$29*(1+Assumptions!$C$30)^2) -> 163537.92 | AH8: =Production!AH6*(Assumptions!$C$29*(1+Assumptions!$C$30)^2) -> 145367.04 | AI8: =Production!AI6*(Assumptions!$C$29*(1+Assumptions!$C$30)^2) -> 145367.04 | ... AM8: =Production!AM6*(Assumptions!$C$29*(1+Assumptions!$C$30)^2) -> 127196.16 | AN8: =SUM(AB8:AM8) -> 1817088 | AO8: =Production!AO6*(Assumptions!$C$29*(1+Assumptions!$C$30)^3) -> 161980.42 | AP8: =Production!AP6*(Assumptions!$C$29*(1+Assumptions!$C$30)^3) -> 161980.42 | AQ8: =Production!AQ6*(Assumptions!$C$29*(1+Assumptions!$C$30)^3) -> 161980.42 | AR8: =Production!AR6*(Assumptions!$C$29*(1+Assumptions!$C$30)^3) -> 182227.97 | AS8: =Production!AS6*(Assumptions!$C$29*(1+Assumptions!$C$30)^3) -> 182227.97 | AT8: =Production!AT6*(Assumptions!$C$29*(1+Assumptions!$C$30)^3) -> 182227.97 | AU8: =Production!AU6*(Assumptions!$C$29*(1+Assumptions!$C$30)^3) -> 161980.42 | AV8: =Production!AV6*(Assumptions!$C$29*(1+Assumptions!$C$30)^3) -> 161980.42 | ... AZ8: =Production!AZ6*(Assumptions!$C$29*(1+Assumptions!$C$30)^3) -> 141732.86 | BA8: =SUM(AO8:AZ8) -> 2024755.2 | BB8: =Production!BB6*(Assumptions!$C$29*(1+Assumptions!$C$30)^4) -> 179690.27 | BC8: =Production!BC6*(Assumptions!$C$29*(1+Assumptions!$C$30)^4) -> 179690.27 | BD8: =Production!BD6*(Assumptions!$C$29*(1+Assumptions!$C$30)^4) -> 179690.27 | BE8: =Production!BE6*(Assumptions!$C$29*(1+Assumptions!$C$30)^4) -> 202151.56 | BF8: =Production!BF6*(Assumptions!$C$29*(1+Assumptions!$C$30)^4) -> 202151.56 | BG8: =Production!BG6*(Assumptions!$C$29*(1+Assumptions!$C$30)^4) -> 202151.56 | BH8: =Production!BH6*(Assumptions!$C$29*(1+Assumptions!$C$30)^4) -> 179690.27 | BI8: =Production!BI6*(Assumptions!$C$29*(1+Assumptions!$C$30)^4) -> 179690.27 | ... BM8: =Production!BM6*(Assumptions!$C$29*(1+Assumptions!$C$30)^4) -> 157228.99 | BN8: =SUM(BB8:BM8) -> 2246128.4
A9: =IFERROR(VLOOKUP(Assumptions!$J$5,Assumptions!$S$5:$Z$21,8,FALSE()),"Factory overheads") -> Factory overheads | B9: =Assumptions!$C$34*(1+Assumptions!$C$35)^0 -> 100000 | C9: =Assumptions!$C$34*(1+Assumptions!$C$35)^0 -> 100000 | D9: =Assumptions!$C$34*(1+Assumptions!$C$35)^0 -> 100000 | E9: =Assumptions!$C$34*(1+Assumptions!$C$35)^0 -> 100000 | F9: =Assumptions!$C$34*(1+Assumptions!$C$35)^0 -> 100000 | G9: =Assumptions!$C$34*(1+Assumptions!$C$35)^0 -> 100000 | H9: =Assumptions!$C$34*(1+Assumptions!$C$35)^0 -> 100000 | I9: =Assumptions!$C$34*(1+Assumptions!$C$35)^0 -> 100000 | ... M9: =Assumptions!$C$34*(1+Assumptions!$C$35)^0 -> 100000 | N9: =SUM(B9:M9) -> 1200000 | O9: =Assumptions!$C$34*(1+Assumptions!$C$35)^1 -> 105000 | P9: =Assumptions!$C$34*(1+Assumptions!$C$35)^1 -> 105000 | Q9: =Assumptions!$C$34*(1+Assumptions!$C$35)^1 -> 105000 | R9: =Assumptions!$C$34*(1+Assumptions!$C$35)^1 -> 105000 | S9: =Assumptions!$C$34*(1+Assumptions!$C$35)^1 -> 105000 | T9: =Assumptions!$C$34*(1+Assumptions!$C$35)^1 -> 105000 | U9: =Assumptions!$C$34*(1+Assumptions!$C$35)^1 -> 105000 | V9: =Assumptions!$C$34*(1+Assumptions!$C$35)^1 -> 105000 | ... Z9: =Assumptions!$C$34*(1+Assumptions!$C$35)^1 -> 105000 | AA9: =SUM(O9:Z9) -> 1260000 | AB9: =Assumptions!$C$34*(1+Assumptions!$C$35)^2 -> 110250 | AC9: =Assumptions!$C$34*(1+Assumptions!$C$35)^2 -> 110250 | AD9: =Assumptions!$C$34*(1+Assumptions!$C$35)^2 -> 110250 | AE9: =Assumptions!$C$34*(1+Assumptions!$C$35)^2 -> 110250 | AF9: =Assumptions!$C$34*(1+Assumptions!$C$35)^2 -> 110250 | AG9: =Assumptions!$C$34*(1+Assumptions!$C$35)^2 -> 110250 | AH9: =Assumptions!$C$34*(1+Assumptions!$C$35)^2 -> 110250 | AI9: =Assumptions!$C$34*(1+Assumptions!$C$35)^2 -> 110250 | ... AM9: =Assumptions!$C$34*(1+Assumptions!$C$35)^2 -> 110250 | AN9: =SUM(AB9:AM9) -> 1323000 | AO9: =Assumptions!$C$34*(1+Assumptions!$C$35)^3 -> 115762.5 | AP9: =Assumptions!$C$34*(1+Assumptions!$C$35)^3 -> 115762.5 | AQ9: =Assumptions!$C$34*(1+Assumptions!$C$35)^3 -> 115762.5 | AR9: =Assumptions!$C$34*(1+Assumptions!$C$35)^3 -> 115762.5 | AS9: =Assumptions!$C$34*(1+Assumptions!$C$35)^3 -> 115762.5 | AT9: =Assumptions!$C$34*(1+Assumptions!$C$35)^3 -> 115762.5 | AU9: =Assumptions!$C$34*(1+Assumptions!$C$35)^3 -> 115762.5 | AV9: =Assumptions!$C$34*(1+Assumptions!$C$35)^3 -> 115762.5 | ... AZ9: =Assumptions!$C$34*(1+Assumptions!$C$35)^3 -> 115762.5 | BA9: =SUM(AO9:AZ9) -> 1389150 | BB9: =Assumptions!$C$34*(1+Assumptions!$C$35)^4 -> 121550.62 | BC9: =Assumptions!$C$34*(1+Assumptions!$C$35)^4 -> 121550.62 | BD9: =Assumptions!$C$34*(1+Assumptions!$C$35)^4 -> 121550.62 | BE9: =Assumptions!$C$34*(1+Assumptions!$C$35)^4 -> 121550.62 | BF9: =Assumptions!$C$34*(1+Assumptions!$C$35)^4 -> 121550.62 | BG9: =Assumptions!$C$34*(1+Assumptions!$C$35)^4 -> 121550.62 | BH9: =Assumptions!$C$34*(1+Assumptions!$C$35)^4 -> 121550.62 | BI9: =Assumptions!$C$34*(1+Assumptions!$C$35)^4 -> 121550.62 | ... BM9: =Assumptions!$C$34*(1+Assumptions!$C$35)^4 -> 121550.62 | BN9: =SUM(BB9:BM9) -> 1458607.5
A10: Repairs & maintenance | B10: =Assumptions!$C$36*(1+Assumptions!$C$37)^0 -> 30000 | C10: =Assumptions!$C$36*(1+Assumptions!$C$37)^0 -> 30000 | D10: =Assumptions!$C$36*(1+Assumptions!$C$37)^0 -> 30000 | E10: =Assumptions!$C$36*(1+Assumptions!$C$37)^0 -> 30000 | F10: =Assumptions!$C$36*(1+Assumptions!$C$37)^0 -> 30000 | G10: =Assumptions!$C$36*(1+Assumptions!$C$37)^0 -> 30000 | H10: =Assumptions!$C$36*(1+Assumptions!$C$37)^0 -> 30000 | I10: =Assumptions!$C$36*(1+Assumptions!$C$37)^0 -> 30000 | ... M10: =Assumptions!$C$36*(1+Assumptions!$C$37)^0 -> 30000 | N10: =SUM(B10:M10) -> 360000 | O10: =Assumptions!$C$36*(1+Assumptions!$C$37)^1 -> 31200 | P10: =Assumptions!$C$36*(1+Assumptions!$C$37)^1 -> 31200 | Q10: =Assumptions!$C$36*(1+Assumptions!$C$37)^1 -> 31200 | R10: =Assumptions!$C$36*(1+Assumptions!$C$37)^1 -> 31200 | S10: =Assumptions!$C$36*(1+Assumptions!$C$37)^1 -> 31200 | T10: =Assumptions!$C$36*(1+Assumptions!$C$37)^1 -> 31200 | U10: =Assumptions!$C$36*(1+Assumptions!$C$37)^1 -> 31200 | V10: =Assumptions!$C$36*(1+Assumptions!$C$37)^1 -> 31200 | ... Z10: =Assumptions!$C$36*(1+Assumptions!$C$37)^1 -> 31200 | AA10: =SUM(O10:Z10) -> 374400 | AB10: =Assumptions!$C$36*(1+Assumptions!$C$37)^2 -> 32448 | AC10: =Assumptions!$C$36*(1+Assumptions!$C$37)^2 -> 32448 | AD10: =Assumptions!$C$36*(1+Assumptions!$C$37)^2 -> 32448 | AE10: =Assumptions!$C$36*(1+Assumptions!$C$37)^2 -> 32448 | AF10: =Assumptions!$C$36*(1+Assumptions!$C$37)^2 -> 32448 | AG10: =Assumptions!$C$36*(1+Assumptions!$C$37)^2 -> 32448 | AH10: =Assumptions!$C$36*(1+Assumptions!$C$37)^2 -> 32448 | AI10: =Assumptions!$C$36*(1+Assumptions!$C$37)^2 -> 32448 | ... AM10: =Assumptions!$C$36*(1+Assumptions!$C$37)^2 -> 32448 | AN10: =SUM(AB10:AM10) -> 389376 | AO10: =Assumptions!$C$36*(1+Assumptions!$C$37)^3 -> 33745.92 | AP10: =Assumptions!$C$36*(1+Assumptions!$C$37)^3 -> 33745.92 | AQ10: =Assumptions!$C$36*(1+Assumptions!$C$37)^3 -> 33745.92 | AR10: =Assumptions!$C$36*(1+Assumptions!$C$37)^3 -> 33745.92 | AS10: =Assumptions!$C$36*(1+Assumptions!$C$37)^3 -> 33745.92 | AT10: =Assumptions!$C$36*(1+Assumptions!$C$37)^3 -> 33745.92 | AU10: =Assumptions!$C$36*(1+Assumptions!$C$37)^3 -> 33745.92 | AV10: =Assumptions!$C$36*(1+Assumptions!$C$37)^3 -> 33745.92 | ... AZ10: =Assumptions!$C$36*(1+Assumptions!$C$37)^3 -> 33745.92 | BA10: =SUM(AO10:AZ10) -> 404951.04 | BB10: =Assumptions!$C$36*(1+Assumptions!$C$37)^4 -> 35095.757 | BC10: =Assumptions!$C$36*(1+Assumptions!$C$37)^4 -> 35095.757 | BD10: =Assumptions!$C$36*(1+Assumptions!$C$37)^4 -> 35095.757 | BE10: =Assumptions!$C$36*(1+Assumptions!$C$37)^4 -> 35095.757 | BF10: =Assumptions!$C$36*(1+Assumptions!$C$37)^4 -> 35095.757 | BG10: =Assumptions!$C$36*(1+Assumptions!$C$37)^4 -> 35095.757 | BH10: =Assumptions!$C$36*(1+Assumptions!$C$37)^4 -> 35095.757 | BI10: =Assumptions!$C$36*(1+Assumptions!$C$37)^4 -> 35095.757 | ... BM10: =Assumptions!$C$36*(1+Assumptions!$C$37)^4 -> 35095.757 | BN10: =SUM(BB10:BM10) -> 421149.08
A11: Administrative expenses | B11: =Assumptions!$C$38*(1+Assumptions!$C$39)^0 -> 50000 | C11: =Assumptions!$C$38*(1+Assumptions!$C$39)^0 -> 50000 | D11: =Assumptions!$C$38*(1+Assumptions!$C$39)^0 -> 50000 | E11: =Assumptions!$C$38*(1+Assumptions!$C$39)^0 -> 50000 | F11: =Assumptions!$C$38*(1+Assumptions!$C$39)^0 -> 50000 | G11: =Assumptions!$C$38*(1+Assumptions!$C$39)^0 -> 50000 | H11: =Assumptions!$C$38*(1+Assumptions!$C$39)^0 -> 50000 | I11: =Assumptions!$C$38*(1+Assumptions!$C$39)^0 -> 50000 | ... M11: =Assumptions!$C$38*(1+Assumptions!$C$39)^0 -> 50000 | N11: =SUM(B11:M11) -> 600000 | O11: =Assumptions!$C$38*(1+Assumptions!$C$39)^1 -> 52000 | P11: =Assumptions!$C$38*(1+Assumptions!$C$39)^1 -> 52000 | Q11: =Assumptions!$C$38*(1+Assumptions!$C$39)^1 -> 52000 | R11: =Assumptions!$C$38*(1+Assumptions!$C$39)^1 -> 52000 | S11: =Assumptions!$C$38*(1+Assumptions!$C$39)^1 -> 52000 | T11: =Assumptions!$C$38*(1+Assumptions!$C$39)^1 -> 52000 | U11: =Assumptions!$C$38*(1+Assumptions!$C$39)^1 -> 52000 | V11: =Assumptions!$C$38*(1+Assumptions!$C$39)^1 -> 52000 | ... Z11: =Assumptions!$C$38*(1+Assumptions!$C$39)^1 -> 52000 | AA11: =SUM(O11:Z11) -> 624000 | AB11: =Assumptions!$C$38*(1+Assumptions!$C$39)^2 -> 54080 | AC11: =Assumptions!$C$38*(1+Assumptions!$C$39)^2 -> 54080 | AD11: =Assumptions!$C$38*(1+Assumptions!$C$39)^2 -> 54080 | AE11: =Assumptions!$C$38*(1+Assumptions!$C$39)^2 -> 54080 | AF11: =Assumptions!$C$38*(1+Assumptions!$C$39)^2 -> 54080 | AG11: =Assumptions!$C$38*(1+Assumptions!$C$39)^2 -> 54080 | AH11: =Assumptions!$C$38*(1+Assumptions!$C$39)^2 -> 54080 | AI11: =Assumptions!$C$38*(1+Assumptions!$C$39)^2 -> 54080 | ... AM11: =Assumptions!$C$38*(1+Assumptions!$C$39)^2 -> 54080 | AN11: =SUM(AB11:AM11) -> 648960 | AO11: =Assumptions!$C$38*(1+Assumptions!$C$39)^3 -> 56243.2 | AP11: =Assumptions!$C$38*(1+Assumptions!$C$39)^3 -> 56243.2 | AQ11: =Assumptions!$C$38*(1+Assumptions!$C$39)^3 -> 56243.2 | AR11: =Assumptions!$C$38*(1+Assumptions!$C$39)^3 -> 56243.2 | AS11: =Assumptions!$C$38*(1+Assumptions!$C$39)^3 -> 56243.2 | AT11: =Assumptions!$C$38*(1+Assumptions!$C$39)^3 -> 56243.2 | AU11: =Assumptions!$C$38*(1+Assumptions!$C$39)^3 -> 56243.2 | AV11: =Assumptions!$C$38*(1+Assumptions!$C$39)^3 -> 56243.2 | ... AZ11: =Assumptions!$C$38*(1+Assumptions!$C$39)^3 -> 56243.2 | BA11: =SUM(AO11:AZ11) -> 674918.4 | BB11: =Assumptions!$C$38*(1+Assumptions!$C$39)^4 -> 58492.928 | BC11: =Assumptions!$C$38*(1+Assumptions!$C$39)^4 -> 58492.928 | BD11: =Assumptions!$C$38*(1+Assumptions!$C$39)^4 -> 58492.928 | BE11: =Assumptions!$C$38*(1+Assumptions!$C$39)^4 -> 58492.928 | BF11: =Assumptions!$C$38*(1+Assumptions!$C$39)^4 -> 58492.928 | BG11: =Assumptions!$C$38*(1+Assumptions!$C$39)^4 -> 58492.928 | BH11: =Assumptions!$C$38*(1+Assumptions!$C$39)^4 -> 58492.928 | BI11: =Assumptions!$C$38*(1+Assumptions!$C$39)^4 -> 58492.928 | ... BM11: =Assumptions!$C$38*(1+Assumptions!$C$39)^4 -> 58492.928 | BN11: =SUM(BB11:BM11) -> 701915.14
A12: Selling & distribution | B12: =Sales!B7*Assumptions!$C$40 -> 57600 | C12: =Sales!C7*Assumptions!$C$40 -> 57600 | D12: =Sales!D7*Assumptions!$C$40 -> 57600 | E12: =Sales!E7*Assumptions!$C$40 -> 64800 | F12: =Sales!F7*Assumptions!$C$40 -> 64800 | G12: =Sales!G7*Assumptions!$C$40 -> 64800 | H12: =Sales!H7*Assumptions!$C$40 -> 57600 | I12: =Sales!I7*Assumptions!$C$40 -> 57600 | ... M12: =Sales!M7*Assumptions!$C$40 -> 50400 | N12: =SUM(B12:M12) -> 720000 | O12: =Sales!O7*Assumptions!$C$40 -> 64896 | P12: =Sales!P7*Assumptions!$C$40 -> 64896 | Q12: =Sales!Q7*Assumptions!$C$40 -> 64896 | R12: =Sales!R7*Assumptions!$C$40 -> 73008 | S12: =Sales!S7*Assumptions!$C$40 -> 73008 | T12: =Sales!T7*Assumptions!$C$40 -> 73008 | U12: =Sales!U7*Assumptions!$C$40 -> 64896 | V12: =Sales!V7*Assumptions!$C$40 -> 64896 | ... Z12: =Sales!Z7*Assumptions!$C$40 -> 56784 | AA12: =SUM(O12:Z12) -> 811200 | AB12: =Sales!AB7*Assumptions!$C$40 -> 72683.52 | AC12: =Sales!AC7*Assumptions!$C$40 -> 72683.52 | AD12: =Sales!AD7*Assumptions!$C$40 -> 72683.52 | AE12: =Sales!AE7*Assumptions!$C$40 -> 81768.96 | AF12: =Sales!AF7*Assumptions!$C$40 -> 81768.96 | AG12: =Sales!AG7*Assumptions!$C$40 -> 81768.96 | AH12: =Sales!AH7*Assumptions!$C$40 -> 72683.52 | AI12: =Sales!AI7*Assumptions!$C$40 -> 72683.52 | ... AM12: =Sales!AM7*Assumptions!$C$40 -> 63598.08 | AN12: =SUM(AB12:AM12) -> 908544 | AO12: =Sales!AO7*Assumptions!$C$40 -> 80990.208 | AP12: =Sales!AP7*Assumptions!$C$40 -> 80990.208 | AQ12: =Sales!AQ7*Assumptions!$C$40 -> 80990.208 | AR12: =Sales!AR7*Assumptions!$C$40 -> 91113.984 | AS12: =Sales!AS7*Assumptions!$C$40 -> 91113.984 | AT12: =Sales!AT7*Assumptions!$C$40 -> 91113.984 | AU12: =Sales!AU7*Assumptions!$C$40 -> 80990.208 | AV12: =Sales!AV7*Assumptions!$C$40 -> 80990.208 | ... AZ12: =Sales!AZ7*Assumptions!$C$40 -> 70866.432 | BA12: =SUM(AO12:AZ12) -> 1012377.6 | BB12: =Sales!BB7*Assumptions!$C$40 -> 89845.137 | BC12: =Sales!BC7*Assumptions!$C$40 -> 89845.137 | BD12: =Sales!BD7*Assumptions!$C$40 -> 89845.137 | BE12: =Sales!BE7*Assumptions!$C$40 -> 101075.78 | BF12: =Sales!BF7*Assumptions!$C$40 -> 101075.78 | BG12: =Sales!BG7*Assumptions!$C$40 -> 101075.78 | BH12: =Sales!BH7*Assumptions!$C$40 -> 89845.137 | BI12: =Sales!BI7*Assumptions!$C$40 -> 89845.137 | ... BM12: =Sales!BM7*Assumptions!$C$40 -> 78614.495 | BN12: =SUM(BB12:BM12) -> 1123064.2
