Workbook

Sheet Cover
B2: MANUFACTURING PLANT — 5-YEAR FINANCIAL MODEL
B3: BLANK TEMPLATE — Institutional VC Financial Model · fill the yellow cells and every sheet updates
B4: Three-statement model · cap table · DCF · exit waterfall · scenario engine · ₹ Lakh (1 Cr = 100 Lakh)
B5: ▶ HOW TO USE: enter your numbers in every YELLOW cell (Assumptions first, then Funding, Fixed Assets, Cap Table, DCF). All production, sales, expenses, profit, statements, cap table, DCF and returns recalculate automatically.
B6: =IFERROR(CONCATENATE("ACTIVE SCENARIO: ",CHOOSE('Scenario Manager'!C4,"BASE","UPSIDE","DOWNSIDE")),0) -> ACTIVE SCENARIO: BASE | F6: Change the case on the Scenario Manager tab (cell C4).
B8: Round size | D8: Post-money | F8: VC ownership (this round) | H8: FY5 revenue
B9: =Funding!C15 -> 0 | D9: ='Cap Table'!$E$19 -> 0 | F9: ='Cap Table'!$D$28 -> 0 | H9: ='Annual P&L'!G4 -> 0
B11: FY5 EBITDA % | D11: DCF enterprise value | F11: WACC | H11: VC gross IRR
B12: ='Annual P&L'!G11 -> 0 | D12: ='DCF Valuation'!$C$33 -> 0 | F12: ='DCF Valuation'!$C$13 -> 0 | H12: ='Returns & Waterfall'!F26 -> -1
B14: VC MOIC | D14: Payback (yrs) | F14: Net worth FY5 | H14: 5-yr PAT
B15: ='Returns & Waterfall'!E26 -> 0 | D15: ='Returns & Waterfall'!C40 -> 0 | F15: ='Balance Sheet'!G14 -> 0 | H15: ='Annual P&L'!G19 -> 0
B17: WORKBOOK MAP
B18: • Scenario Manager — one switch drives Base/Upside/Downside through the whole model.
B19: • Assumptions — every blue driver with a live source link.
B20: • Monthly Model — 60-month engine (production→sales→cost→profit).
B21: • Annual P&L / Balance Sheet / Cash Flow — three fully-linked, tied statements.
B22: • Working Capital · Fixed Assets · Debt · Funding — supporting schedules.
B23: • Cap Table — Seed→Series A→Series B rounds, ESOP, dilution & ownership.
B24: • DCF Valuation — WACC build, FCFF, terminal value → enterprise & equity value.
B25: • Returns & Waterfall — exit, 1× liquidation preference, MOIC/IRR, sensitivity.
B27: Illustrative model on public benchmarks (RBI, MoSPI, CBIC, Income-tax Act, CERC, CCIL). Not investment advice or an audited forecast — replace the illustrative product/capacity with your plant data and have terms reviewed before circulation.

Sheet Instructions
B2: FEASIBILITY MODEL — HOW TO USE THIS TEMPLATE
B3: A blank, fully-linked 5-year (60-month) VC feasibility model. Enter your numbers once in the yellow cells; production, sales, expenses, profit, the three financial statements, cap table, DCF and investor returns all update automatically.
B5: 1 · COLOUR LEGEND
B6: Yellow fill | C6: enter your value here (this is an input)
B7: Green text | C7: a live link — pulls from another sheet / the Scenario Manager (do not edit)
B8: Black text | C8: an automated formula (do not edit)
B9: Grey italic | C9: a note, source link or memo
B11: 2 · FILL ORDER (do these in sequence)
B12: Step 1 — Scenario Manager
B13: Set the active case in cell C4 (1=Base, 2=Upside, 3=Downside). Fill the Base column of swing drivers; Upside/Downside are optional.
B14: Step 2 — Assumptions
B15: Fill every yellow cell: timing, capacity & utilisation, pricing, raw-material & cost %, energy, manpower, other opex, financing, tax and working-capital days.
B16: Step 3 — Funding
B17: Enter the Sources & Uses amounts (capex line items, promoter & VC equity, term loan).
B18: Step 4 — Fixed Assets
B19: Enter the useful life (years) for each asset class — this drives depreciation.
B20: Step 5 — Cap Table
B21: Enter founder shares, ESOP %, and each round’s investment & pre-money (Seed, Series A, projected Series B).
B22: Step 6 — DCF Valuation
... B27: 3 · WHAT EACH SHEET DOES
B28: Cover | D28: KPI dashboard + charts (auto-populated).
B29: Scenario Manager | D29: One switch drives Base / Upside / Downside through the whole model.
B30: Assumptions | D30: All operating drivers, each with a live source link.
B31: Monthly Model | D31: The 60-month engine: production → sales → cost → profit.
B32: Annual P&L | D32: Yearly P&L, aggregated from the monthly engine.
B33: Balance Sheet | D33: Annual balance sheet (auto-ties: check row = 0).
B34: Cash Flow | D34: Indirect-method cash flow; closing cash feeds the balance sheet.
B35: Working Capital | D35: Debtor / inventory / creditor build and WC finance.
B36: Fixed Assets | D36: Depreciation schedule and net-block roll-forward.
B37: Debt Schedule | D37: Term-loan amortisation + working-capital interest.
B38: Funding | D38: Sources & uses of funds.
B39: Cap Table | D39: Rounds, ESOP, price/share, dilution and ownership.
... B41: Returns & Waterfall | D41: Exit, 1× liquidation preference, MOIC / IRR and sensitivity.
B43: 4 · CONVENTIONS & NOTES
B44: • Monetary figures are in ₹ Lakh (1 Crore = 100 Lakh). Per-unit rates (₹/unit, ₹/kWh, ₹/month) are in actual ₹.
B45: • The financial year runs April–March (Indian FY). Month 1 = the first month after funding close.
B46: • Empty inputs deliberately show 0 (not errors); values appear as you fill the yellow cells.
B47: • The product names, location and sheet labels are placeholders — rename them to your plant and products.
B48: • Source links point to issuing authorities (RBI, MoSPI, CBIC, Income-tax, CERC, CCIL); values are as-of their dates and refreshed manually.
B49: • Illustrative model — not investment advice or an audited forecast. Have terms and figures reviewed before circulating to investors.

Sheet Scenario Manager
A1: SCENARIO MANAGER
A2: Set the active case in the yellow cell. Base / Upside / Downside flow through the entire model via CHOOSE().
A4: Active scenario (1=Base, 2=Upside, 3=Downside) | C4: 1 | E4: =IFERROR(CHOOSE(C4,"◀ BASE","◀ UPSIDE","◀ DOWNSIDE"),0) -> ◀ BASE
A6: Swing driver | C6: Base | D6: Upside | E6: Downside | G6: ACTIVE
A7: Utilisation – steady ceiling | G7: =IFERROR(CHOOSE($C$4,C7,D7,E7),0) -> 0
A8: Utilisation – monthly step-up | G8: =IFERROR(CHOOSE($C$4,C8,D8,E8),0) -> 0
A9: Annual price escalation | G9: =IFERROR(CHOOSE($C$4,C9,D9,E9),0) -> 0
A10: RM – Product A (% rev) | G10: =IFERROR(CHOOSE($C$4,C10,D10,E10),0) -> 0
A11: RM – Product B (% rev) | G11: =IFERROR(CHOOSE($C$4,C11,D11,E11),0) -> 0
A12: Exit EV/EBITDA multiple | G12: =IFERROR(CHOOSE($C$4,C12,D12,E12),0) -> 0
A14: Downside also implicitly stresses volume (lower ceiling & slower ramp) and margins (higher RM).

Sheet Assumptions
A1: ASSUMPTIONS — Manufacturing Plant (5-Year Model)
A2: BLANK TEMPLATE — enter values only in the YELLOW cells below. Green cells are linked to the Scenario Manager; black cells are formulas. Monetary flows in ₹ Lakh (1 Cr = 100 Lakh); rates in actual ₹.
A3: Assumption | C3: Value | D3: Unit | E3: Basis / live source
A4: 1. TIMING & CALENDAR
A5: Model start (FY begins Apr) | D5: date | E5: Indian FY Apr–Mar
A6: Commercial production starts in month | D6: month # | E6: Greenfield gestation ≈ 3 months
A7: Projection horizon | D7: months | E7: 5 years × 12
A8: 2. CAPACITY & UTILISATION
A9: Product A – installed capacity | D9: units/mo | E9: Primary product line
A10: Product B – installed capacity | D10: units/mo | E10: Secondary product line
A11: Utilisation – opening (month 4) | D11: % cap | E11: Greenfield ramp start
A12: Utilisation – monthly step-up | C12: ='Scenario Manager'!$G$8 -> 0 | D12: ppt/mo | E12: ← Scenario Manager
A13: Utilisation – steady ceiling | C13: ='Scenario Manager'!$G$7 -> 0 | D13: % cap | E13: ← Scenario Manager
A14: 3. PRICING (net of GST)
A15: Product A – realisation | D15: ₹/unit | E15: Net selling price ex-GST
A16: Product B – realisation | D16: ₹/unit | E16: Net selling price ex-GST
A17: Annual price escalation | C17: ='Scenario Manager'!$G$9 -> 0 | D17: %/yr | E17: ← Scenario Manager
A18: GST on output (info) | D18: % | E18: CBIC – GST rate schedule
A19: 4. RAW MATERIAL & DIRECT COST
A20: RM – Product A (% of A rev) | C20: ='Scenario Manager'!$G$10 -> 0 | D20: % rev | E20: ← Scenario Manager
A21: RM – Product B (% of B rev) | C21: ='Scenario Manager'!$G$11 -> 0 | D21: % rev | E21: ← Scenario Manager
A22: RM efficiency gain | D22: /yr | E22: Scale procurement + yield
A23: Consumables & tooling | D23: % rev | E23: Inserts, coolant, perishables
A24: Energy intensity – Product A | D24: kWh/unit | E24: Machining energy/part
A25: Energy intensity – Product B | D25: kWh/unit | E25: Larger part / more ops
A26: Power tariff (HT industrial) | D26: ₹/kWh | E26: Electricity regulator (SERC/CERC) tariff order
A27: Power tariff escalation | D27: %/yr | E27: Fuel-surcharge linked
A28: 5. MANPOWER
A29: Direct labour – FY1 | D29: persons | E29: Ramp-linked
A30: Direct labour – FY2 | D30: persons
A31: Direct labour – FY3 | D31: persons
A32: Direct labour – FY4 | D32: persons
A33: Direct labour – FY5 | D33: persons
A34: Average direct wage | D34: ₹/mo | E34: Above statutory minimum wage (skilled) – CLC
A35: Indirect + admin – FY1 | D35: persons | E35: Supervisors, QA, admin
A36: Indirect + admin – FY2 | D36: persons
A37: Indirect + admin – FY3 | D37: persons
A38: Indirect + admin – FY4 | D38: persons
A39: Indirect + admin – FY5 | D39: persons
A40: Average indirect salary | D40: ₹/mo
...

Sheet Monthly Model
A1: MONTHLY OPERATING MODEL — 60 Months (₹ figures in ₹ Lakh)
A2: Production → Sales → Cost → Profit. Every cell is a live formula linked to Assumptions & Scenario Manager.
A3: Fiscal Year | B3: =IFERROR(ROUNDUP(B4/12,0),0) -> 1 | C3: =IFERROR(ROUNDUP(C4/12,0),0) -> 1 | D3: =IFERROR(ROUNDUP(D4/12,0),0) -> 1 | E3: =IFERROR(ROUNDUP(E4/12,0),0) -> 1 | F3: =IFERROR(ROUNDUP(F4/12,0),0) -> 1 | G3: =IFERROR(ROUNDUP(G4/12,0),0) -> 1 | H3: =IFERROR(ROUNDUP(H4/12,0),0) -> 1 | I3: =IFERROR(ROUNDUP(I4/12,0),0) -> 1 | ... BI3: =IFERROR(ROUNDUP(BI4/12,0),0) -> 5
A4: Month # | B4: 1 | C4: 2 | D4: 3 | E4: 4 | F4: 5 | G4: 6 | H4: 7 | I4: 8 | J4: 9 | K4: 10 | L4: 11 | M4: 12 | N4: 13 | O4: 14 | P4: 15 | Q4: 16 | R4: 17 | S4: 18 | T4: 19 | U4: 20 | V4: 21 | W4: 22 | X4: 23 | Y4: 24 | Z4: 25 | AA4: 26 | AB4: 27 | AC4: 28 | AD4: 29 | AE4: 30 | AF4: 31 | AG4: 32 | AH4: 33 | AI4: 34 | AJ4: 35 | AK4: 36 | AL4: 37 | AM4: 38 | AN4: 39 | AO4: 40 | AP4: 41 | AQ4: 42 | AR4: 43 | AS4: 44 | AT4: 45 | AU4: 46 | AV4: 47 | AW4: 48 | AX4: 49 | AY4: 50 | AZ4: 51 | BA4: 52 | BB4: 53 | BC4: 54 | BD4: 55 | BE4: 56 | BF4: 57 | BG4: 58 | BH4: 59 | BI4: 60
A5: Month | B5: =IF(Assumptions!$C$5="","",EDATE(Assumptions!$C$5,B4-1)) | C5: =IF(Assumptions!$C$5="","",EDATE(Assumptions!$C$5,C4-1)) | D5: =IF(Assumptions!$C$5="","",EDATE(Assumptions!$C$5,D4-1)) | E5: =IF(Assumptions!$C$5="","",EDATE(Assumptions!$C$5,E4-1)) | F5: =IF(Assumptions!$C$5="","",EDATE(Assumptions!$C$5,F4-1)) | G5: =IF(Assumptions!$C$5="","",EDATE(Assumptions!$C$5,G4-1)) | H5: =IF(Assumptions!$C$5="","",EDATE(Assumptions!$C$5,H4-1)) | I5: =IF(Assumptions!$C$5="","",EDATE(Assumptions!$C$5,I4-1)) | ... BI5: =IF(Assumptions!$C$5="","",EDATE(Assumptions!$C$5,BI4-1))
A7: PRODUCTION
A8: Capacity utilisation (%) | B8: =IF(B4<Assumptions!$C$6,0,MIN(Assumptions!$C$13,Assumptions!$C$11+(B4-Assumptions!$C$6)*Assumptions!$C$12)) -> 0 | C8: =IF(C4<Assumptions!$C$6,0,MIN(Assumptions!$C$13,Assumptions!$C$11+(C4-Assumptions!$C$6)*Assumptions!$C$12)) -> 0 | D8: =IF(D4<Assumptions!$C$6,0,MIN(Assumptions!$C$13,Assumptions!$C$11+(D4-Assumptions!$C$6)*Assumptions!$C$12)) -> 0 | E8: =IF(E4<Assumptions!$C$6,0,MIN(Assumptions!$C$13,Assumptions!$C$11+(E4-Assumptions!$C$6)*Assumptions!$C$12)) -> 0 | F8: =IF(F4<Assumptions!$C$6,0,MIN(Assumptions!$C$13,Assumptions!$C$11+(F4-Assumptions!$C$6)*Assumptions!$C$12)) -> 0 | G8: =IF(G4<Assumptions!$C$6,0,MIN(Assumptions!$C$13,Assumptions!$C$11+(G4-Assumptions!$C$6)*Assumptions!$C$12)) -> 0 | H8: =IF(H4<Assumptions!$C$6,0,MIN(Assumptions!$C$13,Assumptions!$C$11+(H4-Assumptions!$C$6)*Assumptions!$C$12)) -> 0 | I8: =IF(I4<Assumptions!$C$6,0,MIN(Assumptions!$C$13,Assumptions!$C$11+(I4-Assumptions!$C$6)*Assumptions!$C$12)) -> 0 | ... BI8: =IF(BI4<Assumptions!$C$6,0,MIN(Assumptions!$C$13,Assumptions!$C$11+(BI4-Assumptions!$C$6)*Assumptions!$C$12)) -> 0
A9: Product A – production (units) | B9: =Assumptions!$C$9*B8 -> 0 | C9: =Assumptions!$C$9*C8 -> 0 | D9: =Assumptions!$C$9*D8 -> 0 | E9: =Assumptions!$C$9*E8 -> 0 | F9: =Assumptions!$C$9*F8 -> 0 | G9: =Assumptions!$C$9*G8 -> 0 | H9: =Assumptions!$C$9*H8 -> 0 | I9: =Assumptions!$C$9*I8 -> 0 | ... BI9: =Assumptions!$C$9*BI8 -> 0
A10: Product B – production (units) | B10: =Assumptions!$C$10*B8 -> 0 | C10: =Assumptions!$C$10*C8 -> 0 | D10: =Assumptions!$C$10*D8 -> 0 | E10: =Assumptions!$C$10*E8 -> 0 | F10: =Assumptions!$C$10*F8 -> 0 | G10: =Assumptions!$C$10*G8 -> 0 | H10: =Assumptions!$C$10*H8 -> 0 | I10: =Assumptions!$C$10*I8 -> 0 | ... BI10: =Assumptions!$C$10*BI8 -> 0
A11: Total production (units) | B11: =B9+B10 -> 0 | C11: =C9+C10 -> 0 | D11: =D9+D10 -> 0 | E11: =E9+E10 -> 0 | F11: =F9+F10 -> 0 | G11: =G9+G10 -> 0 | H11: =H9+H10 -> 0 | I11: =I9+I10 -> 0 | ... BI11: =BI9+BI10 -> 0
A13: SALES & REVENUE
A14: Product A – units sold | B14: =B9 -> 0 | C14: =C9 -> 0 | D14: =D9 -> 0 | E14: =E9 -> 0 | F14: =F9 -> 0 | G14: =G9 -> 0 | H14: =H9 -> 0 | I14: =I9 -> 0 | ... BI14: =BI9 -> 0
A15: Product B – units sold | B15: =B10 -> 0 | C15: =C10 -> 0 | D15: =D10 -> 0 | E15: =E10 -> 0 | F15: =F10 -> 0 | G15: =G10 -> 0 | H15: =H10 -> 0 | I15: =I10 -> 0 | ... BI15: =BI10 -> 0
A16: Product A – realisation (₹/unit) | B16: =IFERROR(Assumptions!$C$15*(1+Assumptions!$C$17)^(B3-1),0) -> 0 | C16: =IFERROR(Assumptions!$C$15*(1+Assumptions!$C$17)^(C3-1),0) -> 0 | D16: =IFERROR(Assumptions!$C$15*(1+Assumptions!$C$17)^(D3-1),0) -> 0 | E16: =IFERROR(Assumptions!$C$15*(1+Assumptions!$C$17)^(E3-1),0) -> 0 | F16: =IFERROR(Assumptions!$C$15*(1+Assumptions!$C$17)^(F3-1),0) -> 0 | G16: =IFERROR(Assumptions!$C$15*(1+Assumptions!$C$17)^(G3-1),0) -> 0 | H16: =IFERROR(Assumptions!$C$15*(1+Assumptions!$C$17)^(H3-1),0) -> 0 | I16: =IFERROR(Assumptions!$C$15*(1+Assumptions!$C$17)^(I3-1),0) -> 0 | ... BI16: =IFERROR(Assumptions!$C$15*(1+Assumptions!$C$17)^(BI3-1),0) -> 0
A17: Product B – realisation (₹/unit) | B17: =IFERROR(Assumptions!$C$16*(1+Assumptions!$C$17)^(B3-1),0) -> 0 | C17: =IFERROR(Assumptions!$C$16*(1+Assumptions!$C$17)^(C3-1),0) -> 0 | D17: =IFERROR(Assumptions!$C$16*(1+Assumptions!$C$17)^(D3-1),0) -> 0 | E17: =IFERROR(Assumptions!$C$16*(1+Assumptions!$C$17)^(E3-1),0) -> 0 | F17: =IFERROR(Assumptions!$C$16*(1+Assumptions!$C$17)^(F3-1),0) -> 0 | G17: =IFERROR(Assumptions!$C$16*(1+Assumptions!$C$17)^(G3-1),0) -> 0 | H17: =IFERROR(Assumptions!$C$16*(1+Assumptions!$C$17)^(H3-1),0) -> 0 | I17: =IFERROR(Assumptions!$C$16*(1+Assumptions!$C$17)^(I3-1),0) -> 0 | ... BI17: =IFERROR(Assumptions!$C$16*(1+Assumptions!$C$17)^(BI3-1),0) -> 0
A18: Product A – revenue | B18: =IFERROR(B14*B16/100000,0) -> 0 | C18: =IFERROR(C14*C16/100000,0) -> 0 | D18: =IFERROR(D14*D16/100000,0) -> 0 | E18: =IFERROR(E14*E16/100000,0) -> 0 | F18: =IFERROR(F14*F16/100000,0) -> 0 | G18: =IFERROR(G14*G16/100000,0) -> 0 | H18: =IFERROR(H14*H16/100000,0) -> 0 | I18: =IFERROR(I14*I16/100000,0) -> 0 | ... BI18: =IFERROR(BI14*BI16/100000,0) -> 0
A19: Product B – revenue | B19: =IFERROR(B15*B17/100000,0) -> 0 | C19: =IFERROR(C15*C17/100000,0) -> 0 | D19: =IFERROR(D15*D17/100000,0) -> 0 | E19: =IFERROR(E15*E17/100000,0) -> 0 | F19: =IFERROR(F15*F17/100000,0) -> 0 | G19: =IFERROR(G15*G17/100000,0) -> 0 | H19: =IFERROR(H15*H17/100000,0) -> 0 | I19: =IFERROR(I15*I17/100000,0) -> 0 | ... BI19: =IFERROR(BI15*BI17/100000,0) -> 0
A20: Net revenue | B20: =B18+B19 -> 0 | C20: =C18+C19 -> 0 | D20: =D18+D19 -> 0 | E20: =E18+E19 -> 0 | F20: =F18+F19 -> 0 | G20: =G18+G19 -> 0 | H20: =H18+H19 -> 0 | I20: =I18+I19 -> 0 | ... BI20: =BI18+BI19 -> 0
A22: DIRECT / VARIABLE COST
A23: Raw material – Product A | B23: =B18*Assumptions!$C$20*(1-Assumptions!$C$22*(B3-1)) -> 0 | C23: =C18*Assumptions!$C$20*(1-Assumptions!$C$22*(C3-1)) -> 0 | D23: =D18*Assumptions!$C$20*(1-Assumptions!$C$22*(D3-1)) -> 0 | E23: =E18*Assumptions!$C$20*(1-Assumptions!$C$22*(E3-1)) -> 0 | F23: =F18*Assumptions!$C$20*(1-Assumptions!$C$22*(F3-1)) -> 0 | G23: =G18*Assumptions!$C$20*(1-Assumptions!$C$22*(G3-1)) -> 0 | H23: =H18*Assumptions!$C$20*(1-Assumptions!$C$22*(H3-1)) -> 0 | I23: =I18*Assumptions!$C$20*(1-Assumptions!$C$22*(I3-1)) -> 0 | ... BI23: =BI18*Assumptions!$C$20*(1-Assumptions!$C$22*(BI3-1)) -> 0
A24: Raw material – Product B | B24: =B19*Assumptions!$C$21*(1-Assumptions!$C$22*(B3-1)) -> 0 | C24: =C19*Assumptions!$C$21*(1-Assumptions!$C$22*(C3-1)) -> 0 | D24: =D19*Assumptions!$C$21*(1-Assumptions!$C$22*(D3-1)) -> 0 | E24: =E19*Assumptions!$C$21*(1-Assumptions!$C$22*(E3-1)) -> 0 | F24: =F19*Assumptions!$C$21*(1-Assumptions!$C$22*(F3-1)) -> 0 | G24: =G19*Assumptions!$C$21*(1-Assumptions!$C$22*(G3-1)) -> 0 | H24: =H19*Assumptions!$C$21*(1-Assumptions!$C$22*(H3-1)) -> 0 | I24: =I19*Assumptions!$C$21*(1-Assumptions!$C$22*(I3-1)) -> 0 | ... BI24: =BI19*Assumptions!$C$21*(1-Assumptions!$C$22*(BI3-1)) -> 0
A25: Consumables & tooling | B25: =B20*Assumptions!$C$23 -> 0 | C25: =C20*Assumptions!$C$23 -> 0 | D25: =D20*Assumptions!$C$23 -> 0 | E25: =E20*Assumptions!$C$23 -> 0 | F25: =F20*Assumptions!$C$23 -> 0 | G25: =G20*Assumptions!$C$23 -> 0 | H25: =H20*Assumptions!$C$23 -> 0 | I25: =I20*Assumptions!$C$23 -> 0 | ... BI25: =BI20*Assumptions!$C$23 -> 0
A26: Power & fuel | B26: =IFERROR((B9*Assumptions!$C$24+B10*Assumptions!$C$25)*Assumptions!$C$26*(1+Assumptions!$C$27)^(B3-1)/100000,0) -> 0 | C26: =IFERROR((C9*Assumptions!$C$24+C10*Assumptions!$C$25)*Assumptions!$C$26*(1+Assumptions!$C$27)^(C3-1)/100000,0) -> 0 | D26: =IFERROR((D9*Assumptions!$C$24+D10*Assumptions!$C$25)*Assumptions!$C$26*(1+Assumptions!$C$27)^(D3-1)/100000,0) -> 0 | E26: =IFERROR((E9*Assumptions!$C$24+E10*Assumptions!$C$25)*Assumptions!$C$26*(1+Assumptions!$C$27)^(E3-1)/100000,0) -> 0 | F26: =IFERROR((F9*Assumptions!$C$24+F10*Assumptions!$C$25)*Assumptions!$C$26*(1+Assumptions!$C$27)^(F3-1)/100000,0) -> 0 | G26: =IFERROR((G9*Assumptions!$C$24+G10*Assumptions!$C$25)*Assumptions!$C$26*(1+Assumptions!$C$27)^(G3-1)/100000,0) -> 0 | H26: =IFERROR((H9*Assumptions!$C$24+H10*Assumptions!$C$25)*Assumptions!$C$26*(1+Assumptions!$C$27)^(H3-1)/100000,0) -> 0 | I26: =IFERROR((I9*Assumptions!$C$24+I10*Assumptions!$C$25)*Assumptions!$C$26*(1+Assumptions!$C$27)^(I3-1)/100000,0) -> 0 | ... BI26: =IFERROR((BI9*Assumptions!$C$24+BI10*Assumptions!$C$25)*Assumptions!$C$26*(1+Assumptions!$C$27)^(BI3-1)/100000,0) -> 0
A27: Direct labour | B27: =IFERROR(IF(B4<Assumptions!$C$6,0,CHOOSE(B3,Assumptions!$C$29,Assumptions!$C$30,Assumptions!$C$31,Assumptions!$C$32,Assumptions!$C$33)*Assumptions!$C$34*(1+Assumptions!$C$41)^(B3-1)/100000),0) -> 0 | C27: =IFERROR(IF(C4<Assumptions!$C$6,0,CHOOSE(C3,Assumptions!$C$29,Assumptions!$C$30,Assumptions!$C$31,Assumptions!$C$32,Assumptions!$C$33)*Assumptions!$C$34*(1+Assumptions!$C$41)^(C3-1)/100000),0) -> 0 | D27: =IFERROR(IF(D4<Assumptions!$C$6,0,CHOOSE(D3,Assumptions!$C$29,Assumptions!$C$30,Assumptions!$C$31,Assumptions!$C$32,Assumptions!$C$33)*Assumptions!$C$34*(1+Assumptions!$C$41)^(D3-1)/100000),0) -> 0 | E27: =IFERROR(IF(E4<Assumptions!$C$6,0,CHOOSE(E3,Assumptions!$C$29,Assumptions!$C$30,Assumptions!$C$31,Assumptions!$C$32,Assumptions!$C$33)*Assumptions!$C$34*(1+Assumptions!$C$41)^(E3-1)/100000),0) -> 0 | F27: =IFERROR(IF(F4<Assumptions!$C$6,0,CHOOSE(F3,Assumptions!$C$29,Assumptions!$C$30,Assumptions!$C$31,Assumptions!$C$32,Assumptions!$C$33)*Assumptions!$C$34*(1+Assumptions!$C$41)^(F3-1)/100000),0) -> 0 | G27: =IFERROR(IF(G4<Assumptions!$C$6,0,CHOOSE(G3,Assumptions!$C$29,Assumptions!$C$30,Assumptions!$C$31,Assumptions!$C$32,Assumptions!$C$33)*Assumptions!$C$34*(1+Assumptions!$C$41)^(G3-1)/100000),0) -> 0 | H27: =IFERROR(IF(H4<Assumptions!$C$6,0,CHOOSE(H3,Assumptions!$C$29,Assumptions!$C$30,Assumptions!$C$31,Assumptions!$C$32,Assumptions!$C$33)*Assumptions!$C$34*(1+Assumptions!$C$41)^(H3-1)/100000),0) -> 0 | I27: =IFERROR(IF(I4<Assumptions!$C$6,0,CHOOSE(I3,Assumptions!$C$29,Assumptions!$C$30,Assumptions!$C$31,Assumptions!$C$32,Assumptions!$C$33)*Assumptions!$C$34*(1+Assumptions!$C$41)^(I3-1)/100000),0) -> 0 | ... BI27: =IFERROR(IF(BI4<Assumptions!$C$6,0,CHOOSE(BI3,Assumptions!$C$29,Assumptions!$C$30,Assumptions!$C$31,Assumptions!$C$32,Assumptions!$C$33)*Assumptions!$C$34*(1+Assumptions!$C$41)^(BI3-1)/100000),0) -> 0
A28: Total direct cost | B28: =SUM(B23:B27) -> 0 | C28: =SUM(C23:C27) -> 0 | D28: =SUM(D23:D27) -> 0 | E28: =SUM(E23:E27) -> 0 | F28: =SUM(F23:F27) -> 0 | G28: =SUM(G23:G27) -> 0 | H28: =SUM(H23:H27) -> 0 | I28: =SUM(I23:I27) -> 0 | ... BI28: =SUM(BI23:BI27) -> 0
A29: Gross profit | B29: =B20-B28 -> 0 | C29: =C20-C28 -> 0 | D29: =D20-D28 -> 0 | E29: =E20-E28 -> 0 | F29: =F20-F28 -> 0 | G29: =G20-G28 -> 0 | H29: =H20-H28 -> 0 | I29: =I20-I28 -> 0 | ... BI29: =BI20-BI28 -> 0
A30: Gross margin (%) | B30: =IFERROR(IF(B20=0,0,B29/B20),0) -> 0 | C30: =IFERROR(IF(C20=0,0,C29/C20),0) -> 0 | D30: =IFERROR(IF(D20=0,0,D29/D20),0) -> 0 | E30: =IFERROR(IF(E20=0,0,E29/E20),0) -> 0 | F30: =IFERROR(IF(F20=0,0,F29/F20),0) -> 0 | G30: =IFERROR(IF(G20=0,0,G29/G20),0) -> 0 | H30: =IFERROR(IF(H20=0,0,H29/H20),0) -> 0 | I30: =IFERROR(IF(I20=0,0,I29/I20),0) -> 0 | ... BI30: =IFERROR(IF(BI20=0,0,BI29/BI20),0) -> 0
A32: OPERATING EXPENSES
A33: Employee cost (indirect & admin) | B33: =IFERROR(CHOOSE(B3,Assumptions!$C$35,Assumptions!$C$36,Assumptions!$C$37,Assumptions!$C$38,Assumptions!$C$39)*Assumptions!$C$40*(1+Assumptions!$C$41)^(B3-1)/100000,0) -> 0 | C33: =IFERROR(CHOOSE(C3,Assumptions!$C$35,Assumptions!$C$36,Assumptions!$C$37,Assumptions!$C$38,Assumptions!$C$39)*Assumptions!$C$40*(1+Assumptions!$C$41)^(C3-1)/100000,0) -> 0 | D33: =IFERROR(CHOOSE(D3,Assumptions!$C$35,Assumptions!$C$36,Assumptions!$C$37,Assumptions!$C$38,Assumptions!$C$39)*Assumptions!$C$40*(1+Assumptions!$C$41)^(D3-1)/100000,0) -> 0 | E33: =IFERROR(CHOOSE(E3,Assumptions!$C$35,Assumptions!$C$36,Assumptions!$C$37,Assumptions!$C$38,Assumptions!$C$39)*Assumptions!$C$40*(1+Assumptions!$C$41)^(E3-1)/100000,0) -> 0 | F33: =IFERROR(CHOOSE(F3,Assumptions!$C$35,Assumptions!$C$36,Assumptions!$C$37,Assumptions!$C$38,Assumptions!$C$39)*Assumptions!$C$40*(1+Assumptions!$C$41)^(F3-1)/100000,0) -> 0 | G33: =IFERROR(CHOOSE(G3,Assumptions!$C$35,Assumptions!$C$36,Assumptions!$C$37,Assumptions!$C$38,Assumptions!$C$39)*Assumptions!$C$40*(1+Assumptions!$C$41)^(G3-1)/100000,0) -> 0 | H33: =IFERROR(CHOOSE(H3,Assumptions!$C$35,Assumptions!$C$36,Assumptions!$C$37,Assumptions!$C$38,Assumptions!$C$39)*Assumptions!$C$40*(1+Assumptions!$C$41)^(H3-1)/100000,0) -> 0 | I33: =IFERROR(CHOOSE(I3,Assumptions!$C$35,Assumptions!$C$36,Assumptions!$C$37,Assumptions!$C$38,Assumptions!$C$39)*Assumptions!$C$40*(1+Assumptions!$C$41)^(I3-1)/100000,0) -> 0 | ... BI33: =IFERROR(CHOOSE(BI3,Assumptions!$C$35,Assumptions!$C$36,Assumptions!$C$37,Assumptions!$C$38,Assumptions!$C$39)*Assumptions!$C$40*(1+Assumptions!$C$41)^(BI3-1)/100000,0) -> 0
A34: Factory rent & lease | B34: =IFERROR(Assumptions!$C$43*(1+Assumptions!$C$44)^(B3-1),0) -> 0 | C34: =IFERROR(Assumptions!$C$43*(1+Assumptions!$C$44)^(C3-1),0) -> 0 | D34: =IFERROR(Assumptions!$C$43*(1+Assumptions!$C$44)^(D3-1),0) -> 0 | E34: =IFERROR(Assumptions!$C$43*(1+Assumptions!$C$44)^(E3-1),0) -> 0 | F34: =IFERROR(Assumptions!$C$43*(1+Assumptions!$C$44)^(F3-1),0) -> 0 | G34: =IFERROR(Assumptions!$C$43*(1+Assumptions!$C$44)^(G3-1),0) -> 0 | H34: =IFERROR(Assumptions!$C$43*(1+Assumptions!$C$44)^(H3-1),0) -> 0 | I34: =IFERROR(Assumptions!$C$43*(1+Assumptions!$C$44)^(I3-1),0) -> 0 | ... BI34: =IFERROR(Assumptions!$C$43*(1+Assumptions!$C$44)^(BI3-1),0) -> 0
A35: Repairs & maintenance | B35: =IFERROR(IF(B4<Assumptions!$C$6,0,Funding!$C$20*Assumptions!$C$45/12),0) -> 0 | C35: =IFERROR(IF(C4<Assumptions!$C$6,0,Funding!$C$20*Assumptions!$C$45/12),0) -> 0 | D35: =IFERROR(IF(D4<Assumptions!$C$6,0,Funding!$C$20*Assumptions!$C$45/12),0) -> 0 | E35: =IFERROR(IF(E4<Assumptions!$C$6,0,Funding!$C$20*Assumptions!$C$45/12),0) -> 0 | F35: =IFERROR(IF(F4<Assumptions!$C$6,0,Funding!$C$20*Assumptions!$C$45/12),0) -> 0 | G35: =IFERROR(IF(G4<Assumptions!$C$6,0,Funding!$C$20*Assumptions!$C$45/12),0) -> 0 | H35: =IFERROR(IF(H4<Assumptions!$C$6,0,Funding!$C$20*Assumptions!$C$45/12),0) -> 0 | I35: =IFERROR(IF(I4<Assumptions!$C$6,0,Funding!$C$20*Assumptions!$C$45/12),0) -> 0 | ... BI35: =IFERROR(IF(BI4<Assumptions!$C$6,0,Funding!$C$20*Assumptions!$C$45/12),0) -> 0
A36: Selling & distribution | B36: =B20*Assumptions!$C$46 -> 0 | C36: =C20*Assumptions!$C$46 -> 0 | D36: =D20*Assumptions!$C$46 -> 0 | E36: =E20*Assumptions!$C$46 -> 0 | F36: =F20*Assumptions!$C$46 -> 0 | G36: =G20*Assumptions!$C$46 -> 0 | H36: =H20*Assumptions!$C$46 -> 0 | I36: =I20*Assumptions!$C$46 -> 0 | ... BI36: =BI20*Assumptions!$C$46 -> 0
A37: Administrative & other | B37: =IFERROR(Assumptions!$C$47*(1+Assumptions!$C$48)^(B3-1),0) -> 0 | C37: =IFERROR(Assumptions!$C$47*(1+Assumptions!$C$48)^(C3-1),0) -> 0 | D37: =IFERROR(Assumptions!$C$47*(1+Assumptions!$C$48)^(D3-1),0) -> 0 | E37: =IFERROR(Assumptions!$C$47*(1+Assumptions!$C$48)^(E3-1),0) -> 0 | F37: =IFERROR(Assumptions!$C$47*(1+Assumptions!$C$48)^(F3-1),0) -> 0 | G37: =IFERROR(Assumptions!$C$47*(1+Assumptions!$C$48)^(G3-1),0) -> 0 | H37: =IFERROR(Assumptions!$C$47*(1+Assumptions!$C$48)^(H3-1),0) -> 0 | I37: =IFERROR(Assumptions!$C$47*(1+Assumptions!$C$48)^(I3-1),0) -> 0 | ... BI37: =IFERROR(Assumptions!$C$47*(1+Assumptions!$C$48)^(BI3-1),0) -> 0
A38: Total operating expenses | B38: =SUM(B33:B37) -> 0 | C38: =SUM(C33:C37) -> 0 | D38: =SUM(D33:D37) -> 0 | E38: =SUM(E33:E37) -> 0 | F38: =SUM(F33:F37) -> 0 | G38: =SUM(G33:G37) -> 0 | H38: =SUM(H33:H37) -> 0 | I38: =SUM(I33:I37) -> 0 | ... BI38: =SUM(BI33:BI37) -> 0
A40: EBITDA | B40: =B29-B38 -> 0 | C40: =C29-C38 -> 0 | D40: =D29-D38 -> 0 | E40: =E29-E38 -> 0 | F40: =F29-F38 -> 0 | G40: =G29-G38 -> 0 | H40: =H29-H38 -> 0 | I40: =I29-I38 -> 0 | ... BI40: =BI29-BI38 -> 0
A41: EBITDA margin (%) | B41: =IFERROR(IF(B20=0,0,B40/B20),0) -> 0 | C41: =IFERROR(IF(C20=0,0,C40/C20),0) -> 0 | D41: =IFERROR(IF(D20=0,0,D40/D20),0) -> 0 | E41: =IFERROR(IF(E20=0,0,E40/E20),0) -> 0 | F41: =IFERROR(IF(F20=0,0,F40/F20),0) -> 0 | G41: =IFERROR(IF(G20=0,0,G40/G20),0) -> 0 | H41: =IFERROR(IF(H20=0,0,H40/H20),0) -> 0 | I41: =IFERROR(IF(I20=0,0,I40/I20),0) -> 0 | ... BI41: =IFERROR(IF(BI20=0,0,BI40/BI20),0) -> 0
A42: Depreciation & amortisation | B42: =IF(B4<Assumptions!$C$6,0,'Fixed Assets'!$C$11) -> 0 | C42: =IF(C4<Assumptions!$C$6,0,'Fixed Assets'!$C$11) -> 0 | D42: =IF(D4<Assumptions!$C$6,0,'Fixed Assets'!$C$11) -> 0 | E42: =IF(E4<Assumptions!$C$6,0,'Fixed Assets'!$C$11) -> 0 | F42: =IF(F4<Assumptions!$C$6,0,'Fixed Assets'!$C$11) -> 0 | G42: =IF(G4<Assumptions!$C$6,0,'Fixed Assets'!$C$11) -> 0 | H42: =IF(H4<Assumptions!$C$6,0,'Fixed Assets'!$C$11) -> 0 | I42: =IF(I4<Assumptions!$C$6,0,'Fixed Assets'!$C$11) -> 0 | ... BI42: =IF(BI4<Assumptions!$C$6,0,'Fixed Assets'!$C$11) -> 0
A43: EBIT | B43: =B40-B42 -> 0 | C43: =C40-C42 -> 0 | D43: =D40-D42 -> 0 | E43: =E40-E42 -> 0 | F43: =F40-F42 -> 0 | G43: =G40-G42 -> 0 | H43: =H40-H42 -> 0 | I43: =I40-I42 -> 0 | ... BI43: =BI40-BI42 -> 0
A44: Finance cost – term loan | B44: =IFERROR(CHOOSE(B3,'Debt Schedule'!$D$5,'Debt Schedule'!$D$6,'Debt Schedule'!$D$7,'Debt Schedule'!$D$8,'Debt Schedule'!$D$9)/12,0) -> 0 | C44: =IFERROR(CHOOSE(C3,'Debt Schedule'!$D$5,'Debt Schedule'!$D$6,'Debt Schedule'!$D$7,'Debt Schedule'!$D$8,'Debt Schedule'!$D$9)/12,0) -> 0 | D44: =IFERROR(CHOOSE(D3,'Debt Schedule'!$D$5,'Debt Schedule'!$D$6,'Debt Schedule'!$D$7,'Debt Schedule'!$D$8,'Debt Schedule'!$D$9)/12,0) -> 0 | E44: =IFERROR(CHOOSE(E3,'Debt Schedule'!$D$5,'Debt Schedule'!$D$6,'Debt Schedule'!$D$7,'Debt Schedule'!$D$8,'Debt Schedule'!$D$9)/12,0) -> 0 | F44: =IFERROR(CHOOSE(F3,'Debt Schedule'!$D$5,'Debt Schedule'!$D$6,'Debt Schedule'!$D$7,'Debt Schedule'!$D$8,'Debt Schedule'!$D$9)/12,0) -> 0 | G44: =IFERROR(CHOOSE(G3,'Debt Schedule'!$D$5,'Debt Schedule'!$D$6,'Debt Schedule'!$D$7,'Debt Schedule'!$D$8,'Debt Schedule'!$D$9)/12,0) -> 0 | H44: =IFERROR(CHOOSE(H3,'Debt Schedule'!$D$5,'Debt Schedule'!$D$6,'Debt Schedule'!$D$7,'Debt Schedule'!$D$8,'Debt Schedule'!$D$9)/12,0) -> 0 | I44: =IFERROR(CHOOSE(I3,'Debt Schedule'!$D$5,'Debt Schedule'!$D$6,'Debt Schedule'!$D$7,'Debt Schedule'!$D$8,'Debt Schedule'!$D$9)/12,0) -> 0 | ... BI44: =IFERROR(CHOOSE(BI3,'Debt Schedule'!$D$5,'Debt Schedule'!$D$6,'Debt Schedule'!$D$7,'Debt Schedule'!$D$8,'Debt Schedule'!$D$9)/12,0) -> 0
A45: Finance cost – working capital | B45: =IFERROR(CHOOSE(B3,'Debt Schedule'!$C$18,'Debt Schedule'!$D$18,'Debt Schedule'!$E$18,'Debt Schedule'!$F$18,'Debt Schedule'!$G$18)/12,0) -> 0 | C45: =IFERROR(CHOOSE(C3,'Debt Schedule'!$C$18,'Debt Schedule'!$D$18,'Debt Schedule'!$E$18,'Debt Schedule'!$F$18,'Debt Schedule'!$G$18)/12,0) -> 0 | D45: =IFERROR(CHOOSE(D3,'Debt Schedule'!$C$18,'Debt Schedule'!$D$18,'Debt Schedule'!$E$18,'Debt Schedule'!$F$18,'Debt Schedule'!$G$18)/12,0) -> 0 | E45: =IFERROR(CHOOSE(E3,'Debt Schedule'!$C$18,'Debt Schedule'!$D$18,'Debt Schedule'!$E$18,'Debt Schedule'!$F$18,'Debt Schedule'!$G$18)/12,0) -> 0 | F45: =IFERROR(CHOOSE(F3,'Debt Schedule'!$C$18,'Debt Schedule'!$D$18,'Debt Schedule'!$E$18,'Debt Schedule'!$F$18,'Debt Schedule'!$G$18)/12,0) -> 0 | G45: =IFERROR(CHOOSE(G3,'Debt Schedule'!$C$18,'Debt Schedule'!$D$18,'Debt Schedule'!$E$18,'Debt Schedule'!$F$18,'Debt Schedule'!$G$18)/12,0) -> 0 | H45: =IFERROR(CHOOSE(H3,'Debt Schedule'!$C$18,'Debt Schedule'!$D$18,'Debt Schedule'!$E$18,'Debt Schedule'!$F$18,'Debt Schedule'!$G$18)/12,0) -> 0 | I45: =IFERROR(CHOOSE(I3,'Debt Schedule'!$C$18,'Debt Schedule'!$D$18,'Debt Schedule'!$E$18,'Debt Schedule'!$F$18,'Debt Schedule'!$G$18)/12,0) -> 0 | ... BI45: =IFERROR(CHOOSE(BI3,'Debt Schedule'!$C$18,'Debt Schedule'!$D$18,'Debt Schedule'!$E$18,'Debt Schedule'!$F$18,'Debt Schedule'!$G$18)/12,0) -> 0
...

Sheet Annual P&L
A1: ANNUAL PROFIT & LOSS (₹ Lakh)
A2: Auto-aggregated from the 60-month engine. FY0 = funding/commissioning; FY1 is a partial ramp year.
A3: ₹ Lakh | B3: FY0 | C3: FY1 | D3: FY2 | E3: FY3 | F3: FY4 | G3: FY5 | H3: 5-yr total
A4: Net revenue | B4: 0 | C4: =SUM('Monthly Model'!B20:M20) -> 0 | D4: =SUM('Monthly Model'!N20:Y20) -> 0 | E4: =SUM('Monthly Model'!Z20:AK20) -> 0 | F4: =SUM('Monthly Model'!AL20:AW20) -> 0 | G4: =SUM('Monthly Model'!AX20:BI20) -> 0 | H4: =SUM(C4:G4) -> 0
A5: Revenue growth % | C5: - | D5: =IFERROR(IF(C4=0,0,D4/C4-1),0) -> 0 | E5: =IFERROR(IF(D4=0,0,E4/D4-1),0) -> 0 | F5: =IFERROR(IF(E4=0,0,F4/E4-1),0) -> 0 | G5: =IFERROR(IF(F4=0,0,G4/F4-1),0) -> 0
A6: Direct / variable cost | B6: 0 | C6: =SUM('Monthly Model'!B28:M28) -> 0 | D6: =SUM('Monthly Model'!N28:Y28) -> 0 | E6: =SUM('Monthly Model'!Z28:AK28) -> 0 | F6: =SUM('Monthly Model'!AL28:AW28) -> 0 | G6: =SUM('Monthly Model'!AX28:BI28) -> 0 | H6: =SUM(C6:G6) -> 0
A7: Gross profit | B7: 0 | C7: =SUM('Monthly Model'!B29:M29) -> 0 | D7: =SUM('Monthly Model'!N29:Y29) -> 0 | E7: =SUM('Monthly Model'!Z29:AK29) -> 0 | F7: =SUM('Monthly Model'!AL29:AW29) -> 0 | G7: =SUM('Monthly Model'!AX29:BI29) -> 0 | H7: =SUM(C7:G7) -> 0
A8: Gross margin % | B8: =IFERROR(IF(B4=0,0,B7/B4),0) -> 0 | C8: =IFERROR(IF(C4=0,0,C7/C4),0) -> 0 | D8: =IFERROR(IF(D4=0,0,D7/D4),0) -> 0 | E8: =IFERROR(IF(E4=0,0,E7/E4),0) -> 0 | F8: =IFERROR(IF(F4=0,0,F7/F4),0) -> 0 | G8: =IFERROR(IF(G4=0,0,G7/G4),0) -> 0
A9: Operating expenses | B9: 0 | C9: =SUM('Monthly Model'!B38:M38) -> 0 | D9: =SUM('Monthly Model'!N38:Y38) -> 0 | E9: =SUM('Monthly Model'!Z38:AK38) -> 0 | F9: =SUM('Monthly Model'!AL38:AW38) -> 0 | G9: =SUM('Monthly Model'!AX38:BI38) -> 0 | H9: =SUM(C9:G9) -> 0
A10: EBITDA | B10: 0 | C10: =SUM('Monthly Model'!B40:M40) -> 0 | D10: =SUM('Monthly Model'!N40:Y40) -> 0 | E10: =SUM('Monthly Model'!Z40:AK40) -> 0 | F10: =SUM('Monthly Model'!AL40:AW40) -> 0 | G10: =SUM('Monthly Model'!AX40:BI40) -> 0 | H10: =SUM(C10:G10) -> 0
A11: EBITDA margin % | B11: =IFERROR(IF(B4=0,0,B10/B4),0) -> 0 | C11: =IFERROR(IF(C4=0,0,C10/C4),0) -> 0 | D11: =IFERROR(IF(D4=0,0,D10/D4),0) -> 0 | E11: =IFERROR(IF(E4=0,0,E10/E4),0) -> 0 | F11: =IFERROR(IF(F4=0,0,F10/F4),0) -> 0 | G11: =IFERROR(IF(G4=0,0,G10/G4),0) -> 0
A12: Depreciation & amortisation | B12: 0 | C12: =SUM('Monthly Model'!B42:M42) -> 0 | D12: =SUM('Monthly Model'!N42:Y42) -> 0 | E12: =SUM('Monthly Model'!Z42:AK42) -> 0 | F12: =SUM('Monthly Model'!AL42:AW42) -> 0 | G12: =SUM('Monthly Model'!AX42:BI42) -> 0 | H12: =SUM(C12:G12) -> 0
A13: EBIT | B13: 0 | C13: =SUM('Monthly Model'!B43:M43) -> 0 | D13: =SUM('Monthly Model'!N43:Y43) -> 0 | E13: =SUM('Monthly Model'!Z43:AK43) -> 0 | F13: =SUM('Monthly Model'!AL43:AW43) -> 0 | G13: =SUM('Monthly Model'!AX43:BI43) -> 0 | H13: =SUM(C13:G13) -> 0
A14: Finance cost | B14: 0 | C14: =SUM('Monthly Model'!B46:M46) -> 0 | D14: =SUM('Monthly Model'!N46:Y46) -> 0 | E14: =SUM('Monthly Model'!Z46:AK46) -> 0 | F14: =SUM('Monthly Model'!AL46:AW46) -> 0 | G14: =SUM('Monthly Model'!AX46:BI46) -> 0 | H14: =SUM(C14:G14) -> 0
A15: Profit before tax | B15: 0 | C15: =SUM('Monthly Model'!B47:M47) -> 0 | D15: =SUM('Monthly Model'!N47:Y47) -> 0 | E15: =SUM('Monthly Model'!Z47:AK47) -> 0 | F15: =SUM('Monthly Model'!AL47:AW47) -> 0 | G15: =SUM('Monthly Model'!AX47:BI47) -> 0 | H15: =SUM(C15:G15) -> 0
A16: Tax expense | B16: 0 | C16: =SUM('Monthly Model'!B48:M48) -> 0 | D16: =SUM('Monthly Model'!N48:Y48) -> 0 | E16: =SUM('Monthly Model'!Z48:AK48) -> 0 | F16: =SUM('Monthly Model'!AL48:AW48) -> 0 | G16: =SUM('Monthly Model'!AX48:BI48) -> 0 | H16: =SUM(C16:G16) -> 0
A17: Profit after tax (PAT) | B17: 0 | C17: =SUM('Monthly Model'!B49:M49) -> 0 | D17: =SUM('Monthly Model'!N49:Y49) -> 0 | E17: =SUM('Monthly Model'!Z49:AK49) -> 0 | F17: =SUM('Monthly Model'!AL49:AW49) -> 0 | G17: =SUM('Monthly Model'!AX49:BI49) -> 0 | H17: =SUM(C17:G17) -> 0
A18: PAT margin % | B18: =IFERROR(IF(B4=0,0,B17/B4),0) -> 0 | C18: =IFERROR(IF(C4=0,0,C17/C4),0) -> 0 | D18: =IFERROR(IF(D4=0,0,D17/D4),0) -> 0 | E18: =IFERROR(IF(E4=0,0,E17/E4),0) -> 0 | F18: =IFERROR(IF(F4=0,0,F17/F4),0) -> 0 | G18: =IFERROR(IF(G4=0,0,G17/G4),0) -> 0
A19: Cumulative PAT | B19: 0 | C19: =B19+C17 -> 0 | D19: =C19+D17 -> 0 | E19: =D19+E17 -> 0 | F19: =E19+F17 -> 0 | G19: =F19+G17 -> 0

Sheet Balance Sheet
A1: BALANCE SHEET (₹ Lakh)
A3: As at year-end | B3: FY0 | C3: FY1 | D3: FY2 | E3: FY3 | F3: FY4 | G3: FY5
A4: ASSETS
A5: Net fixed assets | B5: ='Fixed Assets'!B20 -> 0 | C5: ='Fixed Assets'!C20 -> 0 | D5: ='Fixed Assets'!D20 -> 0 | E5: ='Fixed Assets'!E20 -> 0 | F5: ='Fixed Assets'!F20 -> 0 | G5: ='Fixed Assets'!G20 -> 0
A6: Inventory | B6: ='Working Capital'!B7 -> 0 | C6: ='Working Capital'!C7 -> 0 | D6: ='Working Capital'!D7 -> 0 | E6: ='Working Capital'!E7 -> 0 | F6: ='Working Capital'!F7 -> 0 | G6: ='Working Capital'!G7 -> 0
A7: Trade debtors | B7: ='Working Capital'!B6 -> 0 | C7: ='Working Capital'!C6 -> 0 | D7: ='Working Capital'!D6 -> 0 | E7: ='Working Capital'!E6 -> 0 | F7: ='Working Capital'!F6 -> 0 | G7: ='Working Capital'!G6 -> 0
A8: Cash & bank | B8: ='Cash Flow'!B24 -> 0 | C8: ='Cash Flow'!C24 -> 0 | D8: ='Cash Flow'!D24 -> 0 | E8: ='Cash Flow'!E24 -> 0 | F8: ='Cash Flow'!F24 -> 0 | G8: ='Cash Flow'!G24 -> 0
A9: Total assets | B9: =SUM(B5:B8) -> 0 | C9: =SUM(C5:C8) -> 0 | D9: =SUM(D5:D8) -> 0 | E9: =SUM(E5:E8) -> 0 | F9: =SUM(F5:F8) -> 0 | G9: =SUM(G5:G8) -> 0
A11: EQUITY & LIABILITIES
A12: Equity share capital & premium | B12: =Funding!C14+Funding!C15 -> 0 | C12: =Funding!C14+Funding!C15 -> 0 | D12: =Funding!C14+Funding!C15 -> 0 | E12: =Funding!C14+Funding!C15 -> 0 | F12: =Funding!C14+Funding!C15 -> 0 | G12: =Funding!C14+Funding!C15 -> 0
A13: Reserves & surplus (retained earnings) | B13: ='Annual P&L'!B19 -> 0 | C13: ='Annual P&L'!C19 -> 0 | D13: ='Annual P&L'!D19 -> 0 | E13: ='Annual P&L'!E19 -> 0 | F13: ='Annual P&L'!F19 -> 0 | G13: ='Annual P&L'!G19 -> 0
A14: Net worth | B14: =B12+B13 -> 0 | C14: =C12+C13 -> 0 | D14: =D12+D13 -> 0 | E14: =E12+E13 -> 0 | F14: =F12+F13 -> 0 | G14: =G12+G13 -> 0
A15: Term loan | B15: =Funding!C16 -> 0 | C15: ='Debt Schedule'!F5 -> 0 | D15: ='Debt Schedule'!F6 -> 0 | E15: ='Debt Schedule'!F7 -> 0 | F15: ='Debt Schedule'!F8 -> 0 | G15: ='Debt Schedule'!F9 -> 0
A16: Working-capital loan | B16: 0 | C16: ='Working Capital'!C12 -> 0 | D16: ='Working Capital'!D12 -> 0 | E16: ='Working Capital'!E12 -> 0 | F16: ='Working Capital'!F12 -> 0 | G16: ='Working Capital'!G12 -> 0
A17: Trade creditors | B17: ='Working Capital'!B8 -> 0 | C17: ='Working Capital'!C8 -> 0 | D17: ='Working Capital'!D8 -> 0 | E17: ='Working Capital'!E8 -> 0 | F17: ='Working Capital'!F8 -> 0 | G17: ='Working Capital'!G8 -> 0
A18: Total equity & liabilities | B18: =B14+B15+B16+B17 -> 0 | C18: =C14+C15+C16+C17 -> 0 | D18: =D14+D15+D16+D17 -> 0 | E18: =E14+E15+E16+E17 -> 0 | F18: =F14+F15+F16+F17 -> 0 | G18: =G14+G15+G16+G17 -> 0
A19: Balance check (assets − E&L) | B19: =B9-B18 -> 0 | C19: =C9-C18 -> 0 | D19: =D9-D18 -> 0 | E19: =E9-E18 -> 0 | F19: =F9-F18 -> 0 | G19: =G9-G18 -> 0
A20: Cash is drawn from the Cash-Flow statement; the check row confirms the three statements tie (≈ 0).

Sheet Cash Flow
A1: CASH-FLOW STATEMENT (indirect method, ₹ Lakh)
B3: FY0 | C3: FY1 | D3: FY2 | E3: FY3 | F3: FY4 | G3: FY5
A4: OPERATING ACTIVITIES
A5: Profit after tax | B5: 0 | C5: ='Annual P&L'!C17 -> 0 | D5: ='Annual P&L'!D17 -> 0 | E5: ='Annual P&L'!E17 -> 0 | F5: ='Annual P&L'!F17 -> 0 | G5: ='Annual P&L'!G17 -> 0
A6: Add: depreciation & amortisation | B6: 0 | C6: ='Annual P&L'!C12 -> 0 | D6: ='Annual P&L'!D12 -> 0 | E6: ='Annual P&L'!E12 -> 0 | F6: ='Annual P&L'!F12 -> 0 | G6: ='Annual P&L'!G12 -> 0
A7: (Increase)/decrease in debtors | B7: 0 | C7: =-('Working Capital'!C6-'Working Capital'!B6) -> 0 | D7: =-('Working Capital'!D6-'Working Capital'!C6) -> 0 | E7: =-('Working Capital'!E6-'Working Capital'!D6) -> 0 | F7: =-('Working Capital'!F6-'Working Capital'!E6) -> 0 | G7: =-('Working Capital'!G6-'Working Capital'!F6) -> 0
A8: (Increase)/decrease in inventory | B8: 0 | C8: =-('Working Capital'!C7-'Working Capital'!B7) -> 0 | D8: =-('Working Capital'!D7-'Working Capital'!C7) -> 0 | E8: =-('Working Capital'!E7-'Working Capital'!D7) -> 0 | F8: =-('Working Capital'!F7-'Working Capital'!E7) -> 0 | G8: =-('Working Capital'!G7-'Working Capital'!F7) -> 0
A9: Increase/(decrease) in creditors | B9: 0 | C9: =('Working Capital'!C8-'Working Capital'!B8) -> 0 | D9: =('Working Capital'!D8-'Working Capital'!C8) -> 0 | E9: =('Working Capital'!E8-'Working Capital'!D8) -> 0 | F9: =('Working Capital'!F8-'Working Capital'!E8) -> 0 | G9: =('Working Capital'!G8-'Working Capital'!F8) -> 0
A10: Net cash from operations | B10: =SUM(B5:B9) -> 0 | C10: =SUM(C5:C9) -> 0 | D10: =SUM(D5:D9) -> 0 | E10: =SUM(E5:E9) -> 0 | F10: =SUM(F5:F9) -> 0 | G10: =SUM(G5:G9) -> 0
A12: INVESTING ACTIVITIES
A13: Capital expenditure | B13: =-Funding!C20 -> 0 | C13: 0 | D13: 0 | E13: 0 | F13: 0 | G13: 0
A14: Net cash from investing | B14: =B13 -> 0 | C14: =C13 -> 0 | D14: =D13 -> 0 | E14: =E13 -> 0 | F14: =F13 -> 0 | G14: =G13 -> 0
A16: FINANCING ACTIVITIES
A17: Equity raised | B17: =Funding!C14+Funding!C15 -> 0 | C17: 0 | D17: 0 | E17: 0 | F17: 0 | G17: 0
A18: Term loan drawn | B18: =Funding!C16 -> 0 | C18: 0 | D18: 0 | E18: 0 | F18: 0 | G18: 0
A19: Term loan principal repaid | B19: 0 | C19: =-'Debt Schedule'!E5 -> 0 | D19: =-'Debt Schedule'!E6 -> 0 | E19: =-'Debt Schedule'!E7 -> 0 | F19: =-'Debt Schedule'!E8 -> 0 | G19: =-'Debt Schedule'!E9 -> 0
A20: Increase/(decrease) in WC loan | B20: 0 | C20: =('Working Capital'!C12-'Working Capital'!B12) -> 0 | D20: =('Working Capital'!D12-'Working Capital'!C12) -> 0 | E20: =('Working Capital'!E12-'Working Capital'!D12) -> 0 | F20: =('Working Capital'!F12-'Working Capital'!E12) -> 0 | G20: =('Working Capital'!G12-'Working Capital'!F12) -> 0
A21: Net cash from financing | B21: =SUM(B17:B20) -> 0 | C21: =SUM(C17:C20) -> 0 | D21: =SUM(D17:D20) -> 0 | E21: =SUM(E17:E20) -> 0 | F21: =SUM(F17:F20) -> 0 | G21: =SUM(G17:G20) -> 0
A22: Net change in cash | B22: =B10+B14+B21 -> 0 | C22: =C10+C14+C21 -> 0 | D22: =D10+D14+D21 -> 0 | E22: =E10+E14+E21 -> 0 | F22: =F10+F14+F21 -> 0 | G22: =G10+G14+G21 -> 0
A23: Opening cash | B23: 0 | C23: =B24 -> 0 | D23: =C24 -> 0 | E23: =D24 -> 0 | F23: =E24 -> 0 | G23: =F24 -> 0
A24: Closing cash | B24: =B23+B22 -> 0 | C24: =C23+C22 -> 0 | D24: =D23+D22 -> 0 | E24: =E23+E22 -> 0 | F24: =F23+F22 -> 0 | G24: =G23+G22 -> 0

Sheet Working Capital
A1: WORKING CAPITAL SCHEDULE (₹ Lakh)
A3: Particulars | B3: FY0 | C3: FY1 | D3: FY2 | E3: FY3 | F3: FY4 | G3: FY5
A4: Net revenue | B4: 0 | C4: ='Annual P&L'!C4 -> 0 | D4: ='Annual P&L'!D4 -> 0 | E4: ='Annual P&L'!E4 -> 0 | F4: ='Annual P&L'!F4 -> 0 | G4: ='Annual P&L'!G4 -> 0
A5: Direct cost | B5: 0 | C5: ='Annual P&L'!C6 -> 0 | D5: ='Annual P&L'!D6 -> 0 | E5: ='Annual P&L'!E6 -> 0 | F5: ='Annual P&L'!F6 -> 0 | G5: ='Annual P&L'!G6 -> 0
A6: Debtors | B6: =IFERROR(B4*Assumptions!$C$55/365,0) -> 0 | C6: =IFERROR(C4*Assumptions!$C$55/365,0) -> 0 | D6: =IFERROR(D4*Assumptions!$C$55/365,0) -> 0 | E6: =IFERROR(E4*Assumptions!$C$55/365,0) -> 0 | F6: =IFERROR(F4*Assumptions!$C$55/365,0) -> 0 | G6: =IFERROR(G4*Assumptions!$C$55/365,0) -> 0
A7: Inventory | B7: =IFERROR(B5*Assumptions!$C$56/365,0) -> 0 | C7: =IFERROR(C5*Assumptions!$C$56/365,0) -> 0 | D7: =IFERROR(D5*Assumptions!$C$56/365,0) -> 0 | E7: =IFERROR(E5*Assumptions!$C$56/365,0) -> 0 | F7: =IFERROR(F5*Assumptions!$C$56/365,0) -> 0 | G7: =IFERROR(G5*Assumptions!$C$56/365,0) -> 0
A8: Creditors | B8: =IFERROR(B5*Assumptions!$C$57/365,0) -> 0 | C8: =IFERROR(C5*Assumptions!$C$57/365,0) -> 0 | D8: =IFERROR(D5*Assumptions!$C$57/365,0) -> 0 | E8: =IFERROR(E5*Assumptions!$C$57/365,0) -> 0 | F8: =IFERROR(F5*Assumptions!$C$57/365,0) -> 0 | G8: =IFERROR(G5*Assumptions!$C$57/365,0) -> 0
A9: Net working capital (operating) | B9: =B6+B7-B8 -> 0 | C9: =C6+C7-C8 -> 0 | D9: =D6+D7-D8 -> 0 | E9: =E6+E7-E8 -> 0 | F9: =F6+F7-F8 -> 0 | G9: =G6+G7-G8 -> 0
A10: Change in net working capital | B10: 0 | C10: =C9-B9 -> 0 | D10: =D9-C9 -> 0 | E10: =E9-D9 -> 0 | F10: =F9-E9 -> 0 | G10: =G9-F9 -> 0
A11: WC gap funded by bank + margin | B11: =B9 -> 0 | C11: =C9 -> 0 | D11: =D9 -> 0 | E11: =E9 -> 0 | F11: =F9 -> 0 | G11: =G9 -> 0
A12: Bank WC loan (drawn) | B12: =B11*Assumptions!$C$52 -> 0 | C12: =C11*Assumptions!$C$52 -> 0 | D12: =D11*Assumptions!$C$52 -> 0 | E12: =E11*Assumptions!$C$52 -> 0 | F12: =F11*Assumptions!$C$52 -> 0 | G12: =G11*Assumptions!$C$52 -> 0
A13: WC interest | B13: =B12*Assumptions!$C$51 -> 0 | C13: =C12*Assumptions!$C$51 -> 0 | D13: =D12*Assumptions!$C$51 -> 0 | E13: =E12*Assumptions!$C$51 -> 0 | F13: =F12*Assumptions!$C$51 -> 0 | G13: =G12*Assumptions!$C$51 -> 0
A15: Bank funds 75% of the operating WC gap; the 25% margin is met from equity (margin-money line in Funding).

Sheet Fixed Assets
A1: FIXED ASSETS & DEPRECIATION (₹ Lakh)
A3: DEPRECIATION RATE SCHEDULE (straight-line, Companies Act Sch. II basis)
A4: Asset | C4: Cost | D4: Life (yrs) | E4: Annual dep.
A5: Plant & machinery (incl. contingency) | C5: =Funding!C4+Funding!C9 -> 0 | E5: =IFERROR(C5/D5,0) -> 0
A6: Utilities & electricals | C6: =Funding!C5 -> 0 | E6: =IFERROR(C6/D6,0) -> 0
A7: Tools, dies & fixtures | C7: =Funding!C6 -> 0 | E7: =IFERROR(C7/D7,0) -> 0
A8: Office, IT & ERP | C8: =Funding!C7 -> 0 | E8: =IFERROR(C8/D8,0) -> 0
A9: Preliminary & pre-operative (amortised) | C9: =Funding!C8 -> 0 | E9: =IFERROR(C9/D9,0) -> 0
A10: Total | C10: =SUM(C5:C9) -> 0 | E10: =SUM(E5:E9) -> 0
A11: Monthly depreciation (→ Monthly Model) | C11: =IFERROR(E10/12,0) -> 0
A13: NET BLOCK ROLL-FORWARD (₹ Lakh)
B14: FY0 | C14: FY1 | D14: FY2 | E14: FY3 | F14: FY4 | G14: FY5
A15: Gross block — opening | B15: 0 | C15: =B17 -> 0 | D15: =C17 -> 0 | E15: =D17 -> 0 | F15: =E17 -> 0 | G15: =F17 -> 0
A16: Add: capex additions | B16: =Funding!C20 -> 0 | C16: 0 | D16: 0 | E16: 0 | F16: 0 | G16: 0
A17: Gross block — closing | B17: =B15+B16 -> 0 | C17: =C15+C16 -> 0 | D17: =D15+D16 -> 0 | E17: =E15+E16 -> 0 | F17: =F15+F16 -> 0 | G17: =G15+G16 -> 0
A18: Depreciation for the year | B18: 0 | C18: ='Annual P&L'!C12 -> 0 | D18: ='Annual P&L'!D12 -> 0 | E18: ='Annual P&L'!E12 -> 0 | F18: ='Annual P&L'!F12 -> 0 | G18: ='Annual P&L'!G12 -> 0
A19: Accumulated depreciation | B19: =B18 -> 0 | C19: =B19+C18 -> 0 | D19: =C19+D18 -> 0 | E19: =D19+E18 -> 0 | F19: =E19+F18 -> 0 | G19: =F19+G18 -> 0
A20: Net block — closing | B20: =B17-B19 -> 0 | C20: =C17-C19 -> 0 | D20: =D17-D19 -> 0 | E20: =E17-E19 -> 0 | F20: =F17-F19 -> 0 | G20: =G17-G19 -> 0

Sheet Debt Schedule
A1: DEBT SCHEDULE (₹ Lakh)
A3: TERM-LOAN AMORTISATION (7-yr tenor, 12-month principal moratorium)
A4: Year | C4: Opening | D4: Interest | E4: Principal | F4: Closing
A5: Year 1 | C5: =Funding!C16 -> 0 | D5: =IFERROR((C5-E5/2)*Assumptions!$C$50,0) -> 0 | E5: 0 | F5: =C5-E5 -> 0
A6: Year 2 | C6: =F5 -> 0 | D6: =IFERROR((C6-E6/2)*Assumptions!$C$50,0) -> 0 | E6: =IFERROR(Funding!C16/6,0) -> 0 | F6: =C6-E6 -> 0
A7: Year 3 | C7: =F6 -> 0 | D7: =IFERROR((C7-E7/2)*Assumptions!$C$50,0) -> 0 | E7: =IFERROR(Funding!C16/6,0) -> 0 | F7: =C7-E7 -> 0
A8: Year 4 | C8: =F7 -> 0 | D8: =IFERROR((C8-E8/2)*Assumptions!$C$50,0) -> 0 | E8: =IFERROR(Funding!C16/6,0) -> 0 | F8: =C8-E8 -> 0
A9: Year 5 | C9: =F8 -> 0 | D9: =IFERROR((C9-E9/2)*Assumptions!$C$50,0) -> 0 | E9: =IFERROR(Funding!C16/6,0) -> 0 | F9: =C9-E9 -> 0
A10: Year 6 | C10: =F9 -> 0 | D10: =IFERROR((C10-E10/2)*Assumptions!$C$50,0) -> 0 | E10: =IFERROR(Funding!C16/6,0) -> 0 | F10: =C10-E10 -> 0
A11: Year 7 | C11: =F10 -> 0 | D11: =IFERROR((C11-E11/2)*Assumptions!$C$50,0) -> 0 | E11: =IFERROR(Funding!C16/6,0) -> 0 | F11: =C11-E11 -> 0
A12: FY1–FY5 interest (D5:D9) feeds the Monthly Model (÷12).
A14: WORKING-CAPITAL FINANCE (₹ Lakh)
C15: FY1 | D15: FY2 | E15: FY3 | F15: FY4 | G15: FY5
A16: WC gap | C16: ='Working Capital'!C11 -> 0 | D16: ='Working Capital'!D11 -> 0 | E16: ='Working Capital'!E11 -> 0 | F16: ='Working Capital'!F11 -> 0 | G16: ='Working Capital'!G11 -> 0
A17: Bank WC loan | C17: ='Working Capital'!C12 -> 0 | D17: ='Working Capital'!D12 -> 0 | E17: ='Working Capital'!E12 -> 0 | F17: ='Working Capital'!F12 -> 0 | G17: ='Working Capital'!G12 -> 0
A18: WC interest | C18: ='Working Capital'!C13 -> 0 | D18: ='Working Capital'!D13 -> 0 | E18: ='Working Capital'!E13 -> 0 | F18: ='Working Capital'!F13 -> 0 | G18: ='Working Capital'!G13 -> 0

Sheet Funding
A1: FUNDING — SOURCES & USES (₹ Lakh)
A3: USES OF FUNDS
A4: Plant & machinery
A5: Utilities & electricals
A6: Tools, dies & fixtures
A7: Office, IT & ERP
A8: Preliminary & pre-operative
A9: Contingency
A10: Margin money for working capital
A11: Total project cost | C11: =SUM(C4:C10) -> 0
A13: SOURCES OF FUNDS
A14: Promoter equity
A15: VC equity — Series A (this round)
A16: Term loan
A17: Total sources | C17: =SUM(C14:C16) -> 0
A18: Balance check (sources − uses) | C18: =C17-C11 -> 0
A20: Total capitalised capex (dep & maintenance base) | C20: =SUM(C4:C9) -> 0
A22: Debt : equity at inception = term loan ÷ (promoter + VC).
A23: =IFERROR(CONCATENATE("D:E = ",TEXT(C16/(C14+C15),"0.00"),"x"),0) -> 0

Sheet Cap Table
A1: CAP TABLE, ROUNDS & DILUTION
A3: CAP-TABLE INPUTS
A4: Founder shares (nos.)
A5: ESOP pool (% of post-Series A FD)
A6: Seed investment (₹ Lakh)
A7: Seed pre-money (₹ Lakh)
A8: Series A investment (₹ Lakh) | C8: =Funding!C15 -> 0
A9: Series A pre-money (₹ Lakh)
A10: Series B investment — projected (₹ Lakh)
A11: Series B pre-money — projected (₹ Lakh)
A12: Series B round timing (FY)
A14: ROUND-BY-ROUND SHARE LEDGER
A15: Round | C15: Investment | D15: Pre-money | E15: Post-money | F15: Price/share (₹) | G15: New shares | H15: Shares o/s
A16: Founders | C16: - | D16: - | E16: - | F16: - | G16: =C4 -> 0 | H16: =G16 -> 0
A17: Seed | C17: =C6 -> 0 | D17: =C7 -> 0 | E17: =C17+D17 -> 0 | F17: =IFERROR(D17*100000/H16,0) -> 0 | G17: =IFERROR(C17*100000/F17,0) -> 0 | H17: =H16+G17 -> 0
A18: ESOP pool | C18: 0 | D18: - | E18: - | F18: - | G18: =IFERROR(H17*C5/(1-C5),0) -> 0 | H18: =H17+G18 -> 0
A19: Series A (VC) | C19: =C8 -> 0 | D19: =C9 -> 0 | E19: =C19+D19 -> 0 | F19: =IFERROR(D19*100000/H18,0) -> 0 | G19: =IFERROR(C19*100000/F19,0) -> 0 | H19: =H18+G19 -> 0
A20: Series B (projected) | C20: =C10 -> 0 | D20: =C11 -> 0 | E20: =C20+D20 -> 0 | F20: =IFERROR(D20*100000/H19,0) -> 0 | G20: =IFERROR(C20*100000/F20,0) -> 0 | H20: =H19+G20 -> 0
A21: Fully diluted total | G21: =SUM(G16:G20) -> 0 | H21: =H20 -> 0
A23: OWNERSHIP
A24: Holder | C24: Shares | D24: Own % (post-A) | E24: Own % (FD post-B) | F24: Invested (₹L)
A25: Founders | C25: =G16 -> 0 | D25: =IFERROR(C25/$H$19,0) -> 0 | E25: =IFERROR(C25/$H$21,0) -> 0 | F25: =Funding!C14 -> 0
A26: Seed | C26: =G17 -> 0 | D26: =IFERROR(C26/$H$19,0) -> 0 | E26: =IFERROR(C26/$H$21,0) -> 0 | F26: =C6 -> 0
A27: ESOP pool | C27: =G18 -> 0 | D27: =IFERROR(C27/$H$19,0) -> 0 | E27: =IFERROR(C27/$H$21,0) -> 0 | F27: 0
A28: Series A (VC) | C28: =G19 -> 0 | D28: =IFERROR(C28/$H$19,0) -> 0 | E28: =IFERROR(C28/$H$21,0) -> 0 | F28: =C8 -> 0
A29: Series B (projected) | C29: =G20 -> 0 | D29: - | E29: =IFERROR(C29/$H$21,0) -> 0 | F29: =C10 -> 0
A30: Total | C30: =SUM(C25:C29) -> 0 | E30: =SUM(E25:E29) -> 0 | F30: =SUM(F25:F29) -> 0
A32: Series B is an illustrative future round shown for dilution; the 3-statement model runs on committed capital (promoter + Series A + term loan).

Sheet DCF Valuation
A1: DCF VALUATION (FCFF, ₹ Lakh)
A3: WACC BUILD-UP
A4: Risk-free rate (India 10Y G-sec) | E4: CCIL / RBI
A5: Equity risk premium | E5: India ERP
A6: Levered beta (sector) | E6: Sector comparables (your sector)
A7: Cost of equity (Ke = Rf + β·ERP) | C7: =C4+C6*C5 -> 0 | E7: CAPM
A8: Pre-tax cost of debt | C8: =Assumptions!$C$50 -> 0 | E8: Term-loan rate
A9: Tax rate | C9: =Assumptions!$C$53 -> 0 | E9: 115BAA
A10: After-tax cost of debt | C10: =C8*(1-C9) -> 0 | E10: Kd·(1−t)
A11: Target equity weight | E11: Long-run structure
A12: Target debt weight | C12: =1-C11 -> 1
A13: WACC | C13: =C11*C7+C12*C10 -> 0 | E13: We·Ke + Wd·Kd
A15: FREE CASH FLOW TO FIRM & DISCOUNTING
A16: ₹ Lakh | C16: FY1 | D16: FY2 | E16: FY3 | F16: FY4 | G16: FY5
A17: Period (t) | C17: 1 | D17: 2 | E17: 3 | F17: 4 | G17: 5
A18: EBIT | C18: ='Annual P&L'!C13 -> 0 | D18: ='Annual P&L'!D13 -> 0 | E18: ='Annual P&L'!E13 -> 0 | F18: ='Annual P&L'!F13 -> 0 | G18: ='Annual P&L'!G13 -> 0
A19: Less: tax on EBIT | C19: =-C18*Assumptions!$C$53 -> 0 | D19: =-D18*Assumptions!$C$53 -> 0 | E19: =-E18*Assumptions!$C$53 -> 0 | F19: =-F18*Assumptions!$C$53 -> 0 | G19: =-G18*Assumptions!$C$53 -> 0
A20: NOPAT | C20: =C18+C19 -> 0 | D20: =D18+D19 -> 0 | E20: =E18+E19 -> 0 | F20: =F18+F19 -> 0 | G20: =G18+G19 -> 0
A21: Add: depreciation | C21: ='Annual P&L'!C12 -> 0 | D21: ='Annual P&L'!D12 -> 0 | E21: ='Annual P&L'!E12 -> 0 | F21: ='Annual P&L'!F12 -> 0 | G21: ='Annual P&L'!G12 -> 0
A22: Less: capex | C22: =-'Cash Flow'!C13*0 -> 0 | D22: =-'Cash Flow'!D13*0 -> 0 | E22: =-'Cash Flow'!E13*0 -> 0 | F22: =-'Cash Flow'!F13*0 -> 0 | G22: =-'Cash Flow'!G13*0 -> 0
A23: Less: change in NWC | C23: =-'Working Capital'!C10 -> 0 | D23: =-'Working Capital'!D10 -> 0 | E23: =-'Working Capital'!E10 -> 0 | F23: =-'Working Capital'!F10 -> 0 | G23: =-'Working Capital'!G10 -> 0
A24: Free cash flow to firm (FCFF) | C24: =C20+C21+C22+C23 -> 0 | D24: =D20+D21+D22+D23 -> 0 | E24: =E20+E21+E22+E23 -> 0 | F24: =F20+F21+F22+F23 -> 0 | G24: =G20+G21+G22+G23 -> 0
A25: Discount factor @ WACC | C25: =IFERROR(1/(1+'DCF Valuation'!$C$13)^C17,0) -> 1 | D25: =IFERROR(1/(1+'DCF Valuation'!$C$13)^D17,0) -> 1 | E25: =IFERROR(1/(1+'DCF Valuation'!$C$13)^E17,0) -> 1 | F25: =IFERROR(1/(1+'DCF Valuation'!$C$13)^F17,0) -> 1 | G25: =IFERROR(1/(1+'DCF Valuation'!$C$13)^G17,0) -> 1
A26: PV of FCFF | C26: =C24*C25 -> 0 | D26: =D24*D25 -> 0 | E26: =E24*E25 -> 0 | F26: =F24*F25 -> 0 | G26: =G24*G25 -> 0
A28: ENTERPRISE & EQUITY VALUE (₹ Lakh)
A29: Sum of PV of FCFF (FY1–FY5) | C29: =SUM(C26:G26) -> 0
A30: Terminal growth (g)
A31: Terminal value (Gordon) = FCFF₅·(1+g)/(WACC−g) | C31: =IFERROR(G24*(1+C30)/('DCF Valuation'!$C$13-C30),0) -> 0
A32: PV of terminal value | C32: =IFERROR(C31/(1+'DCF Valuation'!$C$13)^5,0) -> 0
A33: Enterprise value (DCF) | C33: =C29+C32 -> 0
A34: Memo: EV via exit multiple (FY5 EBITDA × mult) | C34: ='Annual P&L'!G10*'Scenario Manager'!$G$12 -> 0
A35: Less: net debt today (loan − opening cash) | C35: =-(Funding!C16-'Cash Flow'!B24) -> 0
A36: Equity value (DCF) | C36: =C33+C35 -> 0
A37: Series A post-money (cap table) | C37: ='Cap Table'!$E$19 -> 0
A38: DCF equity value vs Series A post-money | C38: =IFERROR(C36/C37-1,0) -> 0
A40: Base DCF uses the Gordon terminal value; the exit-multiple EV (row 34) is shown as a cross-check. WACC & g are editable.

Sheet Returns & Waterfall
A1: INVESTOR RETURNS & EXIT WATERFALL (₹ Lakh)
A3: 1. EXIT ECONOMICS (Year 5)
A4: FY5 EBITDA | C4: ='Annual P&L'!G10 -> 0
A5: Exit EV/EBITDA multiple | C5: ='Scenario Manager'!$G$12 -> 0
A6: Enterprise value at exit | C6: =C4*C5 -> 0
A7: Less: term loan outstanding (FY5) | C7: =-'Debt Schedule'!F9 -> 0
A8: Less: WC loan (FY5) | C8: =-'Working Capital'!G12 -> 0
A9: Add: cash & bank (FY5) | C9: ='Cash Flow'!G24 -> 0
A10: Equity value at exit | C10: =C6+C7+C8+C9 -> 0
A12: 2. LIQUIDATION WATERFALL (non-participating, 1× preferred)
A13: Preference multiple — Series A / Series B
A15: Holder | C15: Shares | D15: Invested | E15: 1× pref | F15: As-converted | G15: Converts? | H15: Proceeds
A16: Founders | C16: ='Cap Table'!$C$25 -> 0 | D16: =Funding!C14 -> 0 | E16: 0 | F16: =IFERROR(C16/'Cap Table'!$H$21*$C$10,0) -> 0 | G16: 1 | H16: =C16*$E$21 -> 0
A17: Seed | C17: ='Cap Table'!$C$26 -> 0 | D17: ='Cap Table'!$F$26 -> 0 | E17: 0 | F17: =IFERROR(C17/'Cap Table'!$H$21*$C$10,0) -> 0 | G17: 1 | H17: =C17*$E$21 -> 0
A18: ESOP pool | C18: ='Cap Table'!$C$27 -> 0 | D18: 0 | E18: 0 | F18: =IFERROR(C18/'Cap Table'!$H$21*$C$10,0) -> 0 | G18: 1 | H18: =C18*$E$21 -> 0
A19: Series A (VC) | C19: ='Cap Table'!$C$28 -> 0 | D19: ='Cap Table'!$F$28 -> 0 | E19: =$C$13*D19 -> 0 | F19: =IFERROR(C19/'Cap Table'!$H$21*$C$10,0) -> 0 | G19: =IF(F19>E19,1,0) -> 0 | H19: =IF(G19=1,C19*$E$21,E19) -> 0
A20: Series B (projected) | C20: ='Cap Table'!$C$29 -> 0 | D20: ='Cap Table'!$F$29 -> 0 | E20: =$D$13*D20 -> 0 | F20: =IFERROR(C20/'Cap Table'!$H$21*$C$10,0) -> 0 | G20: =IF(F20>E20,1,0) -> 0 | H20: =IF(G20=1,C20*$E$21,E20) -> 0
A21: Residual pool / base / per-share (₹L) | C21: =$C$10-((1-G19)*E19+(1-G20)*E20) -> 0 | D21: =('Cap Table'!$C$25+'Cap Table'!$C$26+'Cap Table'!$C$27)+G19*'Cap Table'!$C$28+G20*'Cap Table'!$C$29 -> 0 | E21: =IFERROR(MAX(0,C21)/D21,0) -> 0
A22: Check: Σ proceeds = equity value | C22: ='Cap Table'!$C$25+'Cap Table'!$C$26+'Cap Table'!$C$27 -> 0 | H22: =SUM(H16:H20)-C10 -> 0
C23: 'Cap Table'!$C$28
A24: 3. RETURN BY INVESTOR | C24: 'Cap Table'!$C$29
A25: Investor | C25: Invested | D25: Proceeds | E25: MOIC | F25: Gross IRR
A26: Series A (VC) | C26: =D19 -> 0 | D26: =H19 -> 0 | E26: =IFERROR(IF(C26=0,0,D26/C26),0) -> 0 | F26: =IFERROR((D26/C26)^(1/(5))-1,-1) -> -1
A27: Series B (projected) | C27: =D20 -> 0 | D27: =H20 -> 0 | E27: =IFERROR(IF(C27=0,0,D27/C27),0) -> 0 | F27: =IFERROR((D27/C27)^(1/((5-'Cap Table'!$C$12+1)))-1,-1) -> -1
A28: Seed | C28: =D17 -> 0 | D28: =H17 -> 0 | E28: =IFERROR(IF(C28=0,0,D28/C28),0) -> 0 | F28: =IFERROR((D28/C28)^(1/(6))-1,-1) -> -1
A30: 4. SERIES A SENSITIVITY — Gross IRR
A31: FY5 EBITDA ▼ / Exit multiple ►
C32: Downside −15% | D32: =IFERROR((('Cap Table'!$E$28*(('Annual P&L'!G10*0.85)*5-('Debt Schedule'!F9+'Working Capital'!G12-'Cash Flow'!G24)))/'Cap Table'!$F$28)^(1/5)-1,-1) -> -1 | E32: =IFERROR((('Cap Table'!$E$28*(('Annual P&L'!G10*0.85)*6-('Debt Schedule'!F9+'Working Capital'!G12-'Cash Flow'!G24)))/'Cap Table'!$F$28)^(1/5)-1,-1) -> -1 | F32: =IFERROR((('Cap Table'!$E$28*(('Annual P&L'!G10*0.85)*7-('Debt Schedule'!F9+'Working Capital'!G12-'Cash Flow'!G24)))/'Cap Table'!$F$28)^(1/5)-1,-1) -> -1 | G32: =IFERROR((('Cap Table'!$E$28*(('Annual P&L'!G10*0.85)*8-('Debt Schedule'!F9+'Working Capital'!G12-'Cash Flow'!G24)))/'Cap Table'!$F$28)^(1/5)-1,-1) -> -1
C33: Base | D33: =IFERROR((('Cap Table'!$E$28*(('Annual P&L'!G10*1)*5-('Debt Schedule'!F9+'Working Capital'!G12-'Cash Flow'!G24)))/'Cap Table'!$F$28)^(1/5)-1,-1) -> -1 | E33: =IFERROR((('Cap Table'!$E$28*(('Annual P&L'!G10*1)*6-('Debt Schedule'!F9+'Working Capital'!G12-'Cash Flow'!G24)))/'Cap Table'!$F$28)^(1/5)-1,-1) -> -1 | F33: =IFERROR((('Cap Table'!$E$28*(('Annual P&L'!G10*1)*7-('Debt Schedule'!F9+'Working Capital'!G12-'Cash Flow'!G24)))/'Cap Table'!$F$28)^(1/5)-1,-1) -> -1 | G33: =IFERROR((('Cap Table'!$E$28*(('Annual P&L'!G10*1)*8-('Debt Schedule'!F9+'Working Capital'!G12-'Cash Flow'!G24)))/'Cap Table'!$F$28)^(1/5)-1,-1) -> -1
C34: Upside +15% | D34: =IFERROR((('Cap Table'!$E$28*(('Annual P&L'!G10*1.15)*5-('Debt Schedule'!F9+'Working Capital'!G12-'Cash Flow'!G24)))/'Cap Table'!$F$28)^(1/5)-1,-1) -> -1 | E34: =IFERROR((('Cap Table'!$E$28*(('Annual P&L'!G10*1.15)*6-('Debt Schedule'!F9+'Working Capital'!G12-'Cash Flow'!G24)))/'Cap Table'!$F$28)^(1/5)-1,-1) -> -1 | F34: =IFERROR((('Cap Table'!$E$28*(('Annual P&L'!G10*1.15)*7-('Debt Schedule'!F9+'Working Capital'!G12-'Cash Flow'!G24)))/'Cap Table'!$F$28)^(1/5)-1,-1) -> -1 | G34: =IFERROR((('Cap Table'!$E$28*(('Annual P&L'!G10*1.15)*8-('Debt Schedule'!F9+'Working Capital'!G12-'Cash Flow'!G24)))/'Cap Table'!$F$28)^(1/5)-1,-1) -> -1
A37: 5. PROJECT RETURN METRICS
A38: FY5 Return on Equity (on net worth) | C38: =IFERROR('Annual P&L'!G17/'Balance Sheet'!G14,0) -> 0
A39: FY5 Return on Capital Employed | C39: =IFERROR('Annual P&L'!G13/('Balance Sheet'!G14+'Balance Sheet'!G15+'Balance Sheet'!G16),0) -> 0
A40: Payback on equity (yrs) | C40: =IFERROR((Funding!C14+Funding!C15)/(('Annual P&L'!F17+'Annual P&L'!F12+'Annual P&L'!G17+'Annual P&L'!G12)/2),0) -> 0
A41: 5-yr revenue CAGR (FY1→FY5) | C41: =IFERROR(('Annual P&L'!G4/'Annual P&L'!C4)^(1/4)-1,0) -> 0
A43: Waterfall is first-order (convert decision uses as-converted at full equity value); adequate where equity value ≫ total preference. Series B illustrative.
